Workbook

Sheet Summary Data
A1: Redoubt Lake sockeye salmon information:
A2: Yellow cells = brood years not fertilized.
G3: Directed | Q3: Full | R3: Fertilized
B4: Weir | C4: Escapement | D4: Subsistence | E4: Sportfish | F4: Commercial | G4: Commercial | H4: Total | I4: Total | J4: Harvest | K4: OEG (2003) | M4: Fry Stocking Activity | O4: Fertilizer Activity | Q4: Limnology | R4: Brood | W4: Stock-recruit data from Geiger (2003):
A5: Year | B5: Count | C5: Estimate | D5: Harvest | E5: Harvest | F5: Harvest | G5: Fishery | H5: Harvest | I5: Run | J5: Rate | K5: Lower | L5: Upper | M5: Species | N5: Number | O5: Fert (tons) | P5: Total P (kg) | Q5: Survey | R5: Years | S5: Other | W5: Year | X5: Escapement | Y5: Return | Z5: R/S | AA5: Ln R/S | AB5: S | AC5: R
A6: 1982 | B6: 430 | C6: 455.84087 | D6: =Harvest!D5 -> 97 | E6: ND | F6: ND | H6: =SUM(D6:F6) -> 97 | I6: =SUM(C6,H6) -> 552.84087 | J6: =H6/I6 -> 0.17545736 | Q6: Yes | W6: 1982 | X6: 456 | Y6: 6870 | Z6: =Y6/X6 -> 15.065789 | AA6: =LN(Z6) -> 2.7124266 | AB6: =X6/1000 -> 0.456 | AC6: =Y6/1000 -> 6.87
A7: 1983 | B7: 2525 | C7: 2539.7855 | D7: 36 | E7: ND | F7: ND | H7: =SUM(D7:F7) -> 36 | I7: =SUM(C7,H7) -> 2575.7855 | J7: =H7/I7 -> 0.013976319 | Q7: Yes | W7: 1983 | X7: 2540 | Y7: 12928 | Z7: =Y7/X7 -> 5.0897638 | AA7: =LN(Z7) -> 1.6272314 | AB7: =X7/1000 -> 2.54 | AC7: =Y7/1000 -> 12.928
A8: 1984 | B8: 11545 | C8: 11579.407 | D8: 175 | E8: ND | F8: ND | H8: =SUM(D8:F8) -> 175 | I8: =SUM(C8,H8) -> 11754.407 | J8: =H8/I8 -> 0.014888033 | O8: 61 | P8: 1682 | Q8: Yes | R8: 1982-1983 | W8: 1984 | X8: 11579 | Y8: 50507 | Z8: =Y8/X8 -> 4.3619484 | AA8: =LN(Z8) -> 1.4729188 | AB8: =X8/1000 -> 11.579 | AC8: =Y8/1000 -> 50.507
A9: 1985 | B9: 10669 | C9: 10991.361 | D9: =Harvest!D5 -> 97 | E9: ND | F9: =Harvest!G5 -> 141 | H9: =SUM(D9:F9) -> 238 | I9: =SUM(C9,H9) -> 11229.361 | J9: =H9/I9 -> 0.021194438 | O9: 65 | P9: 1763 | Q9: Yes | R9: 1983-1984 | W9: 1985 | X9: 10991 | Y9: 96544 | Z9: =Y9/X9 -> 8.7839141 | AA9: =LN(Z9) -> 2.1729221 | AB9: =X9/1000 -> 10.991 | AC9: =Y9/1000 -> 96.544
A10: 1986 | B10: 9414 | C10: 9798.1704 | D10: =Harvest!D6 -> 86 | E10: ND | F10: =Harvest!G6 -> 12 | H10: =SUM(D10:F10) -> 98 | I10: =SUM(C10,H10) -> 9896.1704 | J10: =H10/I10 -> 0.0099028206 | M10: Sockeye | N10: 28220 | O10: 78 | P10: 2163 | Q10: Yes | R10: 1984-1985 | S10: 900,000 Chinook salmon stocked in lake | W10: 1986 | X10: 9798 | Y10: 10935 | Z10: =Y10/X10 -> 1.1160441 | AA10: =LN(Z10) -> 0.10979037 | AB10: =X10/1000 -> 9.798 | AC10: =Y10/1000 -> 10.935
A11: 1987 | B11: 12990 | C11: 14251.358 | D11: =Harvest!D7 -> 199 | E11: ND | F11: =Harvest!G7 -> 86 | H11: =SUM(D11:F11) -> 285 | I11: =SUM(C11,H11) -> 14536.358 | J11: =H11/I11 -> 0.019606011 | M11: Sockeye | N11: 28711 | O11: 75 | P11: 3045 | Q11: Yes | R11: 1985-1986 | W11: 1987 | X11: 14251 | Y11: 14167 | Z11: =Y11/X11 -> 0.99410568 | AA11: =LN(Z11) -> -0.0059117633 | AB11: =X11/1000 -> 14.251 | AC11: =Y11/1000 -> 14.167
A12: 1988 | B12: 1889 | C12: 3252.0307 | D12: =Harvest!D8 -> 334 | E12: ND | F12: =Harvest!G8 -> 6 | H12: =SUM(D12:F12) -> 340 | I12: =SUM(C12,H12) -> 3592.0307 | J12: =H12/I12 -> 0.09465398 | Q12: Yes | W12: 1988 | X12: 3252 | Y12: 31862 | Z12: =Y12/X12 -> 9.797663 | AA12: =LN(Z12) -> 2.2821439 | AB12: =X12/1000 -> 3.252 | AC12: =Y12/1000 -> 31.862
A13: 1989 | B13: 28669 | C13: 31570.475 | D13: =Harvest!D9 -> 2685 | E13: ND | F13: =Harvest!G9 -> 1 | H13: =SUM(D13:F13) -> 2686 | I13: =SUM(C13,H13) -> 34256.475 | J13: =H13/I13 -> 0.078408535 | M13: Sockeye | N13: 38800 | Q13: No | W13: 1989 | X13: 31570 | Y13: 26851 | Z13: =Y13/X13 -> 0.85052265 | AA13: =LN(Z13) -> -0.16190424 | AB13: =X13/1000 -> 31.57 | AC13: =Y13/1000 -> 26.851
A14: 1990 | B14: 72517 | C14: 73180.572 | D14: =Harvest!D10 -> 5326 | E14: 703 | F14: =Harvest!G10 -> 0 | H14: =SUM(D14:F14) -> 6029 | I14: =SUM(C14,H14) -> 79209.572 | J14: =H14/I14 -> 0.076114539 | M14: Sockeye | N14: 59520 | O14: 107 | P14: 3045 | Q14: Yes | R14: 1988-1989 | W14: 1990 | X14: 73181 | Y14: 42987 | Z14: =Y14/X14 -> 0.58740657 | AA14: =LN(Z14) -> -0.53203808 | AB14: =X14/1000 -> 73.181 | AC14: =Y14/1000 -> 42.987
A15: 1991 | B15: 45039 | C15: 45509.809 | D15: =Harvest!D11 -> 3105 | E15: ND | F15: =Harvest!G11 -> 1 | H15: =SUM(D15:F15) -> 3106 | I15: =SUM(C15,H15) -> 48615.809 | J15: =H15/I15 -> 0.063888683 | M15: Sockeye | N15: 236436 | O15: 97 | P15: 2844 | Q15: Yes | R15: 1989-1990 | W15: 1991 | X15: 45510 | Y15: 33250 | Z15: =Y15/X15 -> 0.73060866 | AA15: =LN(Z15) -> -0.31387731 | AB15: =X15/1000 -> 45.51 | AC15: =Y15/1000 -> 33.25
A16: 1992 | B16: 10231 | C16: 10325.817 | D16: =Harvest!D12 -> 96 | E16: ND | F16: =Harvest!G12 -> 5 | H16: =SUM(D16:F16) -> 101 | I16: =SUM(C16,H16) -> 10426.817 | J16: =H16/I16 -> 0.0096865615 | O16: 95 | P16: 2003 | Q16: Yes | R16: 1990-1991 | W16: 1992 | X16: 10326 | Y16: 38798 | Z16: =Y16/X16 -> 3.7573116 | AA16: =LN(Z16) -> 1.3237037 | AB16: =X16/1000 -> 10.326 | AC16: =Y16/1000 -> 38.798
A17: 1993 | B17: 24707 | C17: 25018.473 | D17: =Harvest!D13 -> 2326 | E17: 130 | F17: =Harvest!G13 -> 686 | H17: =SUM(D17:F17) -> 3142 | I17: =SUM(C17,H17) -> 28160.473 | J17: =H17/I17 -> 0.11157483 | O17: 109 | P17: 3205 | Q17: Yes | R17: 1991-1992 | W17: 1993 | X17: 25018 | Y17: 46784 | Z17: =Y17/X17 -> 1.8700136 | AA17: =LN(Z17) -> 0.6259457 | AB17: =X17/1000 -> 25.018 | AC17: =Y17/1000 -> 46.784
A18: 1994 | B18: 39216 | C18: 39710.383 | D18: =Harvest!D14 -> 4120 | E18: 721 | F18: =Harvest!G14 -> 1327 | H18: =SUM(D18:F18) -> 6168 | I18: =SUM(C18,H18) -> 45878.383 | J18: =H18/I18 -> 0.1344424 | O18: 80 | P18: 1682 | Q18: Yes | R18: 1992-1993 | W18: 1994 | X18: 39710 | Y18: 67592 | Z18: =Y18/X18 -> 1.7021405 | AA18: =LN(Z18) -> 0.53188659 | AB18: =X18/1000 -> 39.71 | AC18: =Y18/1000 -> 67.592
A19: 1995 | B19: 34216 | C19: 34797.618 | D19: =Harvest!D15 -> 2968 | E19: 646 | F19: =Harvest!G15 -> 1888 | H19: =SUM(D19:F19) -> 5502 | I19: =SUM(C19,H19) -> 40299.618 | J19: =H19/I19 -> 0.13652735 | O19: 94 | P19: 2740 | Q19: Yes | R19: 1993-1994 | W19: 1995 | X19: 34798 | Y19: 4242 | Z19: =Y19/X19 -> 0.12190356 | AA19: =LN(Z19) -> -2.1045251 | AB19: =X19/1000 -> 34.798 | AC19: =Y19/1000 -> 4.242
A20: 1996 | B20: 18725 | C20: 19209.335 | D20: =Harvest!D16 -> 3337 | E20: 1078 | F20: =Harvest!G16 -> 1268 | H20: =SUM(D20:F20) -> 5683 | I20: =SUM(C20,H20) -> 24892.335 | J20: =H20/I20 -> 0.22830321 | Q20: Yes | W20: 1996 | X20: 19209 | Y20: 4362 | Z20: =Y20/X20 -> 0.22708106 | AA20: =LN(Z20) -> -1.4824483 | AB20: =X20/1000 -> 19.209 | AC20: =Y20/1000 -> 4.362
A21: 1997 | B21: 28127 | C21: 28898.406 | D21: =Harvest!D17 -> 2253 | E21: 1569 | F21: =Harvest!G17 -> 5434 | H21: =SUM(D21:F21) -> 9256 | I21: =SUM(C21,H21) -> 38154.406 | J21: =H21/I21 -> 0.24259321 | Q21: No | W21: alpha^ | X21: 4.496
A22: 1998 | D22: =Harvest!D18 -> 4296 | E22: 1732 | F22: =Harvest!G18 -> 2906 | H22: =SUM(D22:F22) -> 8934 | Q22: No | W22: lnalpha^ | X22: =LN(X21) -> 1.5031881
A23: 1999 | B23: 57469 | C23: 57753.571 | D23: =Harvest!D19 -> 6761 | E23: 3192 | F23: =Harvest!G19 -> 2741 | H23: =SUM(D23:F23) -> 12694 | I23: =SUM(C23,H23) -> 70447.571 | J23: =H23/I23 -> 0.18019074 | O23: 9 | Q23: Yes | R23: 1997-1998 | W23: beta^ | X23: 4.3e-05
A24: 2000 | B24: 2948 | C24: 3032.1983 | D24: =Harvest!D20 -> 35 | E24: 95 | F24: =Harvest!G20 -> 679 | H24: =SUM(D24:F24) -> 809 | I24: =SUM(C24,H24) -> 3841.1983 | J24: =H24/I24 -> 0.21061136 | O24: 10 | Q24: Yes | R24: 1998-1999 | W24: sigma^ | X24: 1.293
A25: 2001 | B25: 3661 | C25: 3666.9945 | D25: =Harvest!D21 -> 16 | E25: 50 | F25: =Harvest!G21 -> 1388 | H25: =SUM(D25:F25) -> 1454 | I25: =SUM(C25,H25) -> 5120.9945 | J25: =H25/I25 -> 0.28392922 | O25: 10 | Q25: Yes | R25: 1999-2000 | W25: lnalpha' | X25: =X22+X24^2/2 -> 2.3391126
A26: 2002 | B26: 23918.447 | C26: 23987.72 | D26: =Harvest!D22 -> 1255 | E26: 820 | F26: =Harvest!G22 -> 611 | H26: =SUM(D26:F26) -> 2686 | I26: =SUM(C26,H26) -> 26673.72 | J26: =H26/I26 -> 0.10069836 | O26: 6.5 | Q26: Yes | R26: 2000-2001 | W26: Smax^ | X26: =1/X23 -> 23255.814
A27: 2003 | B27: 69859 | C27: 69892.77 | D27: =Harvest!D23 -> 10591 | E27: 126 | F27: =Harvest!G23 -> 1321 | G27: Yes | H27: =SUM(D27:F27) -> 12038 | I27: =SUM(C27,H27) -> 81930.77 | J27: =H27/I27 -> 0.14692893 | K27: 7000 | L27: 25000 | O27: 10 | Q27: Yes | R27: 2001-2002 | W27: Seq^ | X27: =X25/X23 -> 54397.968
A28: 2004 | B28: 77049 | C28: 77262.734 | D28: =Harvest!D24 -> 9338 | E28: 295 | F28: =Harvest!G24 -> 3305 | G28: Yes | H28: =SUM(D28:F28) -> 12938 | I28: =SUM(C28,H28) -> 90200.734 | J28: =H28/I28 -> 0.14343564 | K28: 7000 | L28: 25000 | O28: 9.98 | Q28: Yes | R28: 2002-2003 | W28: Smsy^ | X28: 17400
A29: 2005 | B29: 65546 | C29: 65653.383 | D29: =Harvest!D25 -> 5299 | E29: 0 | F29: =Harvest!G25 -> 1996 | H29: =SUM(D29:F29) -> 7295 | I29: =SUM(C29,H29) -> 72948.383 | J29: =H29/I29 -> 0.10000222 | K29: 7000 | L29: 25000 | O29: 9.82 | Q29: Yes | R29: 2003-2004 | W29: Umsy^ | X29: =X25*(0.5-0.07*X25) -> 0.78655496
A30: 2006 | B30: 101067 | C30: 103952.86 | D30: =Harvest!D26 -> 13683 | E30: 43 | F30: =Harvest!G26 -> 11507 | G30: Yes | H30: =SUM(D30:F30) -> 25233 | I30: =SUM(C30,H30) -> 129185.86 | J30: =H30/I30 -> 0.19532324 | K30: 7000 | L30: 25000 | O30: 8.55 | Q30: Yes | R30: 2004-2005 | W30: MSY^ | X30: =X28*EXP(X25-X23*X28)-X28 -> 68003.136
A31: 2007 | B31: 66708 | C31: 66938.383 | D31: =Harvest!D27 -> 8711 | E31: 337 | F31: =Harvest!G27 -> 6689 | G31: Yes | H31: =SUM(D31:F31) -> 15737 | I31: =SUM(C31,H31) -> 82675.383 | J31: =H31/I31 -> 0.19034686 | K31: 7000 | L31: 25000 | O31: 10 | Q31: Yes | R31: 2005-2006 | W31: 90% Smsy | X31: 11040 | Y31: 25200
A32: 2008 | B32: 10019.018 | C32: 10063.983 | D32: =Harvest!D28 -> 679 | E32: 43 | F32: =Harvest!G28 -> 739 | H32: =SUM(D32:F32) -> 1461 | I32: =SUM(C32,H32) -> 11524.983 | J32: =H32/I32 -> 0.12676808 | K32: 7000 | L32: 25000 | O32: 10 | Q32: Yes | R32: 2006-2007 | W32: Contrast | X32: =MAX(X6:X20)/MIN(X6:X20) -> 160.48465
A33: 2009 | B33: 12503 | C33: 12568.761 | D33: =Harvest!D29 -> 1149 | E33: 0 | F33: =Harvest!G29 -> 891 | H33: =SUM(D33:F33) -> 2040 | I33: =SUM(C33,H33) -> 14608.761 | J33: =H33/I33 -> 0.13964224 | K33: 7000 | L33: 25000 | O33: 10 | Q33: Yes | R33: 2007-2008
A34: 2010 | B34: 17030 | C34: 17156.231 | D34: =Harvest!D30 -> 1656 | E34: 220 | F34: =Harvest!G30 -> 1152 | H34: =SUM(D34:F34) -> 3028 | I34: =SUM(C34,H34) -> 20184.231 | J34: =H34/I34 -> 0.1500181 | K34: 7000 | L34: 25000 | O34: 10 | Q34: Yes | R34: 2008-2009
A35: 2011 | B35: 21645 | C35: 22719.733 | D35: =Harvest!D31 -> 1402 | E35: 77 | F35: =Harvest!G31 -> 1177 | H35: =SUM(D35:F35) -> 2656 | I35: =SUM(C35,H35) -> 25375.733 | J35: =H35/I35 -> 0.10466693 | K35: 7000 | L35: 25000 | O35: 10 | Q35: Yes | R35: 2009-2010
A36: 2012 | B36: 40272 | C36: 40943.877 | D36: =Harvest!D32 -> 4975 | E36: 253 | F36: =Harvest!G32 -> 1157 | H36: =SUM(D36:F36) -> 6385 | I36: =SUM(C36,H36) -> 47328.877 | J36: =H36/I36 -> 0.13490707 | K36: 7000 | L36: 25000 | O36: 10 | Q36: Yes | R36: 2010-2011
A37: 2013 | B37: 48355 | C37: 49124.281 | D37: =Harvest!D33 -> 4352 | E37: 150 | F37: =Harvest!G33 -> 4364 | G37: Yes | H37: =SUM(D37:F37) -> 8866 | I37: =SUM(C37,H37) -> 57990.281 | J37: =H37/I37 -> 0.15288769 | K37: 7000 | L37: 25000 | O37: 10 | Q37: Yes | R37: 2011-2012 | S37: Massive landslide
A38: 2014 | B38: 18694 | C38: 19936.125 | D38: =Harvest!D34 -> 1892 | E38: 0 | F38: =Harvest!G34 -> 3824 | H38: =SUM(D38:F38) -> 5716 | I38: =SUM(C38,H38) -> 25652.125 | J38: =H38/I38 -> 0.22282754 | K38: 7000 | L38: 25000 | O38: 7.4385 | Q38: Yes | R38: 2012-2013 | S38: Cyanobacteria bloom
A39: 2015 | B39: 12540 | C39: 13982.744 | D39: =Harvest!D35 -> 599 | E39: 0 | F39: =Harvest!G35 -> 3939 | H39: =SUM(D39:F39) -> 4538 | I39: =SUM(C39,H39) -> 18520.744 | J39: =H39/I39 -> 0.24502255 | K39: 7000 | L39: 25000 | O39: 8.1 | Q39: Yes | R39: 2013-2014 | S39: Cyanobacteria bloom
A40: 2016 | B40: 22553 | C40: 22774 | D40: =Harvest!D36 -> 2489 | E40: 0 | F40: =Harvest!G36 -> 1592 | H40: =SUM(D40:F40) -> 4081 | I40: =SUM(C40,H40) -> 26855 | J40: =H40/I40 -> 0.15196425 | K40: 7000 | L40: 25000 | O40: 9.6 | Q40: Yes | R40: 2014-2015
...

Sheet S-R Summary
A1: Stock-Recruit Summary:
C3: Run Recon. 1 | E3: Run Recon. 2 | F3: Run Recon. 3 | H3: Run Recon. 4
B4: Geiger (2003) | C4: SLR | D4: AR1 | E4: SLR | F4: SLR | G4: AR1 | H4: SLR
A5: lnalpha^ | B5: ='Run Reconstruction 1'!AC32 -> 0 | C5: ='Run Reconstruction 1'!AA32 -> 1.6827988 | D5: ='Run Reconstruction 1'!AB32 -> 1.5528306 | E5: ='Run Reconstruction 2'!AA32 -> 1.6845423 | F5: ='Run Reconstruction 3'!AA32 -> 1.6997209 | G5: ='Run Reconstruction 3'!AB32 -> 1.5651301 | H5: ='Run Reconstruction 4'!AA32 -> 2.0777105
A6: beta^ | B6: ='Run Reconstruction 1'!AC33 -> 0 | C6: ='Run Reconstruction 1'!AA33 -> 4.0698178e-05 | D6: ='Run Reconstruction 1'!AB33 -> 3.7985844e-05 | E6: ='Run Reconstruction 2'!AA33 -> 4.0804639e-05 | F6: ='Run Reconstruction 3'!AA33 -> 4.0699613e-05 | G6: ='Run Reconstruction 3'!AB33 -> 3.7902439e-05 | H6: ='Run Reconstruction 4'!AA33 -> 4.5026494e-05
A7: sigma^ | B7: ='Run Reconstruction 1'!AC34 -> 0 | C7: ='Run Reconstruction 1'!AA34 -> 0.98895758 | D7: ='Run Reconstruction 1'!AB34 -> 0.96204303 | E7: ='Run Reconstruction 2'!AA34 -> 0.99050509 | F7: ='Run Reconstruction 3'!AA34 -> 0.96636458 | G7: ='Run Reconstruction 3'!AB34 -> 0.9350733 | H7: ='Run Reconstruction 4'!AA34 -> 0.93609124
A8: lnalpha' | B8: ='Run Reconstruction 1'!AC35 -> 0 | C8: ='Run Reconstruction 1'!AA35 -> 2.1718174 | D8: ='Run Reconstruction 1'!AB35 -> 2.0531963 | E8: ='Run Reconstruction 2'!AA35 -> 2.1750925 | F8: ='Run Reconstruction 3'!AA35 -> 2.1666511 | G8: ='Run Reconstruction 3'!AB35 -> 2.0424131 | H8: ='Run Reconstruction 4'!AA35 -> 2.5158439
A9: Smax^ | B9: ='Run Reconstruction 1'!AC36 -> 0 | C9: ='Run Reconstruction 1'!AA36 -> 24571.125 | D9: ='Run Reconstruction 1'!AB36 -> 26325.596 | E9: ='Run Reconstruction 2'!AA36 -> 24507.018 | F9: ='Run Reconstruction 3'!AA36 -> 24570.258 | G9: ='Run Reconstruction 3'!AB36 -> 26383.526 | H9: ='Run Reconstruction 4'!AA36 -> 22209.147
A10: Seq^ | B10: ='Run Reconstruction 1'!AC37 -> 0 | C10: ='Run Reconstruction 1'!AA37 -> 53363.996 | D10: ='Run Reconstruction 1'!AB37 -> 54051.616 | E10: ='Run Reconstruction 2'!AA37 -> 53305.03 | F10: ='Run Reconstruction 3'!AA37 -> 53235.178 | G10: ='Run Reconstruction 3'!AB37 -> 53886.059 | H10: ='Run Reconstruction 4'!AA37 -> 55874.746
A11: Smsy^ | B11: ='Run Reconstruction 1'!AC38 -> 0 | C11: ='Run Reconstruction 1'!AA38 -> 18569.218 | D11: ='Run Reconstruction 1'!AB38 -> 19257.308 | E11: ='Run Reconstruction 2'!AA38 -> 18536.479 | F11: ='Run Reconstruction 3'!AA38 -> 18543.645 | G11: ='Run Reconstruction 3'!AB38 -> 19238.998 | H11: ='Run Reconstruction 4'!AA38 -> 18097.323
A12: Umsy^ | B12: ='Run Reconstruction 1'!AC39 -> 0 | C12: ='Run Reconstruction 1'!AA39 -> 0.75573334 | D12: ='Run Reconstruction 1'!AB39 -> 0.73150509 | E12: ='Run Reconstruction 2'!AA39 -> 0.75637433 | F12: ='Run Reconstruction 3'!AA39 -> 0.75471916 | G12: ='Run Reconstruction 3'!AB39 -> 0.72920496 | H12: ='Run Reconstruction 4'!AA39 -> 0.81485901
A13: MSY^ | B13: ='Run Reconstruction 1'!AC40 -> 0 | C13: ='Run Reconstruction 1'!AA40 -> 57953.627 | D13: ='Run Reconstruction 1'!AB40 -> 52952.927 | E13: ='Run Reconstruction 2'!AA40 -> 58052.928 | F13: ='Run Reconstruction 3'!AA40 -> 57557.179 | G13: ='Run Reconstruction 3'!AB40 -> 52293.188 | H13: ='Run Reconstruction 4'!AA40 -> 81064.085
A14: S Contrast | B14: ='Run Reconstruction 1'!AC41 -> 0 | C14: ='Run Reconstruction 1'!AA41 -> 169.49497 | D14: 169 | E14: ='Run Reconstruction 2'!AA41 -> 169.49497 | F14: ='Run Reconstruction 3'!AA41 -> 169.49497 | G14: 169 | H14: ='Run Reconstruction 4'!AA41 -> 34.283
A15: 90% Smsy lower | B15: ='Run Reconstruction 1'!AC42 -> 0 | C15: ='Run Reconstruction 1'!AA42 -> 11749.218 | D15: ='Run Reconstruction 1'!AB42 -> 12228.332 | E15: ='Run Reconstruction 2'!AA42 -> 11727.764 | F15: ='Run Reconstruction 3'!AA42 -> 11734.642 | G15: ='Run Reconstruction 3'!AB42 -> 12220.747 | H15: ='Run Reconstruction 4'!AA42 -> 11364.949
A16: 90% Smsy Upper | B16: ='Run Reconstruction 1'!AC43 -> 0 | C16: ='Run Reconstruction 1'!AA43 -> 26836.837 | D16: ='Run Reconstruction 1'!AB43 -> 27711.26 | E16: ='Run Reconstruction 2'!AA43 -> 26792.241 | F16: ='Run Reconstruction 3'!AA43 -> 26794.968 | G16: ='Run Reconstruction 3'!AB43 -> 27674.374 | H16: ='Run Reconstruction 4'!AA43 -> 26502.945
A18: Run Reconstruction 1: | B18: Brood years 1982-2013; missing 1998 escapement imputed as average return for each age class, all brood years.
A19: Run Reconstruction 2: | B19: Brood years 1982-2013; missing 1998 escapement imputed as average return for each age class brood years 1982-1990.
A20: Run Reconstruction 3: | B20: Brood years 1982-2013; missing 1998 escapement estimated by regression of escapement on subsistence harvest; age based on average age at return, BY1982-1990 and 1996-2013.
A21: Run Reconstruction 4: | B21: Brood years 1999-2013.

Sheet Run Reconstruction 1
A1: Redoubt Lake sockeye salmon brood table:
A2: RED data imputed for missing escapement in 1998 - based on average age at return, BY1982-1990 and 1996-2013.
H4: Estimated Return by Year:
A5: Year | B5: Escapement | C5: Harvest | D5: Run | E5: Return | F5: R/S | G5: Ln R/S | H5: Year | I5: age 3 | K5: age 4 | M5: age 5 | O5: age 6 | Q5: age 7 | S5: age 8 | U5: S | V5: R
A6: 1982 | B6: ='Summary Data'!C6 -> 455.84087 | C6: ='Summary Data'!H6 -> 97 | D6: =SUM(B6:C6) -> 552.84087 | E6: =SUM(I6,K6,M6,O6,Q6,S6) -> 6855.6678 | F6: =E6/B6 -> 15.039608 | G6: =LN(F6) -> 2.7106872 | H6: 1985 | I6: =B9*SUM('Escapement Age'!S9:T9)+C9*'Escapement Age'!S9 -> 75.45557 | J6: 1986 | K6: =B10*SUM('Escapement Age'!U10:W10)+C10*SUM('Escapement Age'!U10:V10) -> 1807.8226 | L6: 1987 | M6: =B11*SUM('Escapement Age'!X11:Z11)+C11*SUM('Escapement Age'!X11:Y11) -> 4612.1024 | N6: 1988 | O6: =B12*SUM('Escapement Age'!AA12:AC12)+'Run Reconstruction 1'!C12*SUM('Escapement Age'!AA12:AC12) -> 339.78668 | P6: 1989 | Q6: =B13*SUM('Escapement Age'!AD13:AF13)+C13*SUM('Escapement Age'!AD13:AF13) -> 20.500583 | R6: 1990 | S6: =B14*SUM('Escapement Age'!AG14)+C14*SUM('Escapement Age'!AG14) -> 0 | U6: =B6/1000 -> 0.45584087 | V6: =E6/1000 -> 6.8556678
A7: 1983 | B7: ='Summary Data'!C7 -> 2539.7855 | C7: ='Summary Data'!H7 -> 36 | D7: =SUM(B7:C7) -> 2575.7855 | E7: =SUM(I7,K7,M7,O7,Q7,S7) -> 12843.288 | F7: =E7/B7 -> 5.0568398 | G7: =LN(F7) -> 1.6207417 | H7: 1986 | I7: =B10*SUM('Escapement Age'!S10:T10)+C10*'Escapement Age'!S10 -> 68.625318 | J7: 1987 | K7: =B11*SUM('Escapement Age'!U11:W11)+C11*SUM('Escapement Age'!U11:V11) -> 5948.6908 | L7: 1988 | M7: =B12*SUM('Escapement Age'!X12:Z12)+C12*SUM('Escapement Age'!X12:Y12) -> 2786.2508 | N7: 1989 | O7: =B13*SUM('Escapement Age'!AA13:AC13)+'Run Reconstruction 1'!C13*SUM('Escapement Age'!AA13:AC13) -> 4018.1143 | P7: 1990 | Q7: =B14*SUM('Escapement Age'!AD14:AF14)+C14*SUM('Escapement Age'!AD14:AF14) -> 0 | R7: 1991 | S7: =B15*SUM('Escapement Age'!AG15)+C15*SUM('Escapement Age'!AG15) -> 21.607026 | U7: =B7/1000 -> 2.5397855 | V7: =E7/1000 -> 12.843288
A8: 1984 | B8: ='Summary Data'!C8 -> 11579.407 | C8: ='Summary Data'!H8 -> 175 | D8: =SUM(B8:C8) -> 11754.407 | E8: =SUM(I8,K8,M8,O8,Q8,S8) -> 50074.938 | F8: =E8/B8 -> 4.3244821 | G8: =LN(F8) -> 1.4642924 | H8: 1987 | I8: =B11*SUM('Escapement Age'!S11:T11)+C11*'Escapement Age'!S11 -> 94.201613 | J8: 1988 | K8: =B12*SUM('Escapement Age'!U12:W12)+C12*SUM('Escapement Age'!U12:V12) -> 465.99317 | L8: 1989 | M8: =B13*SUM('Escapement Age'!X13:Z13)+C13*SUM('Escapement Age'!X13:Y13) -> 27202.667 | N8: 1990 | O8: =B14*SUM('Escapement Age'!AA14:AC14)+'Run Reconstruction 1'!C14*SUM('Escapement Age'!AA14:AC14) -> 21080.476 | P8: 1991 | Q8: =B15*SUM('Escapement Age'!AD15:AF15)+C15*SUM('Escapement Age'!AD15:AF15) -> 1231.6005 | R8: 1992 | S8: =B16*SUM('Escapement Age'!AG16)+C16*SUM('Escapement Age'!AG16) -> 0 | U8: =B8/1000 -> 11.579407 | V8: =E8/1000 -> 50.074938
A9: 1985 | B9: ='Summary Data'!C9 -> 10991.361 | C9: ='Summary Data'!H9 -> 238 | D9: =SUM(B9:C9) -> 11229.361 | E9: =SUM(I9,K9,M9,O9,Q9,S9) -> 96153.771 | F9: =E9/B9 -> 8.7481221 | G9: =LN(F9) -> 2.1688391 | H9: 1988 | I9: =B12*SUM('Escapement Age'!S12:T12)+C12*'Escapement Age'!S12 -> 0 | J9: 1989 | K9: =B13*SUM('Escapement Age'!U13:W13)+C13*SUM('Escapement Age'!U13:V13) -> 2775.6397 | L9: 1990 | M9: =B14*SUM('Escapement Age'!X14:Z14)+C14*SUM('Escapement Age'!X14:Y14) -> 53395.456 | N9: 1991 | O9: =B15*SUM('Escapement Age'!AA15:AC15)+'Run Reconstruction 1'!C15*SUM('Escapement Age'!AA15:AC15) -> 39778.535 | P9: 1992 | Q9: =B16*SUM('Escapement Age'!AD16:AF16)+C16*SUM('Escapement Age'!AD16:AF16) -> 204.13948 | R9: 1993 | S9: =B17*SUM('Escapement Age'!AG17)+C17*SUM('Escapement Age'!AG17) -> 0 | U9: =B9/1000 -> 10.991361 | V9: =E9/1000 -> 96.153771
A10: 1986 | B10: ='Summary Data'!C10 -> 9798.1704 | C10: ='Summary Data'!H10 -> 98 | D10: =SUM(B10:C10) -> 9896.1704 | E10: =SUM(I10,K10,M10,O10,Q10,S10) -> 10915.724 | F10: =E10/B10 -> 1.1140574 | G10: =LN(F10) -> 0.10800863 | H10: 1989 | I10: =B13*SUM('Escapement Age'!S13:T13)+C13*'Escapement Age'!S13 -> 151.1453 | J10: 1990 | K10: =B14*SUM('Escapement Age'!U14:W14)+C14*SUM('Escapement Age'!U14:V14) -> 4221.5122 | L10: 1991 | M10: =B15*SUM('Escapement Age'!X15:Z15)+C15*SUM('Escapement Age'!X15:Y15) -> 3238.2931 | N10: 1992 | O10: =B16*SUM('Escapement Age'!AA16:AC16)+'Run Reconstruction 1'!C16*SUM('Escapement Age'!AA16:AC16) -> 3038.5377 | P10: 1993 | Q10: =B17*SUM('Escapement Age'!AD17:AF17)+C17*SUM('Escapement Age'!AD17:AF17) -> 266.23567 | R10: 1994 | S10: =B18*SUM('Escapement Age'!AG18)+C18*SUM('Escapement Age'!AG18) -> 0 | U10: =B10/1000 -> 9.7981704 | V10: =E10/1000 -> 10.915724
A11: 1987 | B11: ='Summary Data'!C11 -> 14251.358 | C11: ='Summary Data'!H11 -> 285 | D11: =SUM(B11:C11) -> 14536.358 | E11: =SUM(I11,K11,M11,O11,Q11,S11) -> 14253.971 | F11: =E11/B11 -> 1.0001834 | G11: =LN(F11) -> 0.00018333767 | H11: 1990 | I11: =B14*SUM('Escapement Age'!S14:T14)+C14*'Escapement Age'!S14 -> 466.4897 | J11: 1991 | K11: =B15*SUM('Escapement Age'!U15:W15)+C15*SUM('Escapement Age'!U15:V15) -> 4196.3247 | L11: 1992 | M11: =B16*SUM('Escapement Age'!X16:Z16)+C16*SUM('Escapement Age'!X16:Y16) -> 4694.5996 | N11: 1993 | O11: =B17*SUM('Escapement Age'!AA17:AC17)+'Run Reconstruction 1'!C17*SUM('Escapement Age'!AA17:AC17) -> 4150.8561 | P11: 1994 | Q11: =B18*SUM('Escapement Age'!AD18:AF18)+C18*SUM('Escapement Age'!AD18:AF18) -> 745.70127 | R11: 1995 | S11: =B19*SUM('Escapement Age'!AG19)+C19*SUM('Escapement Age'!AG19) -> 0 | U11: =B11/1000 -> 14.251358 | V11: =E11/1000 -> 14.253971
A12: 1988 | B12: ='Summary Data'!C12 -> 3252.0307 | C12: ='Summary Data'!H12 -> 340 | D12: =SUM(B12:C12) -> 3592.0307 | E12: =SUM(I12,K12,M12,O12,Q12,S12) -> 32610.622 | F12: =E12/B12 -> 10.027772 | G12: =LN(F12) -> 2.3053584 | H12: 1991 | I12: =B15*SUM('Escapement Age'!S15:T15)+C15*'Escapement Age'!S15 -> 101.13291 | J12: 1992 | K12: =B16*SUM('Escapement Age'!U16:W16)+C16*SUM('Escapement Age'!U16:V16) -> 1736.5725 | L12: 1993 | M12: =B17*SUM('Escapement Age'!X17:Z17)+C17*SUM('Escapement Age'!X17:Y17) -> 14049.982 | N12: 1994 | O12: =B18*SUM('Escapement Age'!AA18:AC18)+'Run Reconstruction 1'!C18*SUM('Escapement Age'!AA18:AC18) -> 16618.485 | P12: 1995 | Q12: =B19*SUM('Escapement Age'!AD19:AF19)+C19*SUM('Escapement Age'!AD19:AF19) -> 104.44825 | R12: 1996 | S12: =B20*SUM('Escapement Age'!AG20)+C20*SUM('Escapement Age'!AG20) -> 0 | U12: =B12/1000 -> 3.2520307 | V12: =E12/1000 -> 32.610622
A13: 1989 | B13: ='Summary Data'!C13 -> 31570.475 | C13: ='Summary Data'!H13 -> 2686 | D13: =SUM(B13:C13) -> 34256.475 | E13: =SUM(I13,K13,M13,O13,Q13,S13) -> 27573.431 | F13: =E13/B13 -> 0.87339299 | G13: =LN(F13) -> -0.13536966 | H13: 1992 | I13: =B16*SUM('Escapement Age'!S16:T16)+C16*'Escapement Age'!S16 -> 738.6691 | J13: 1993 | K13: =B17*SUM('Escapement Age'!U17:W17)+C17*SUM('Escapement Age'!U17:V17) -> 9320.6459 | L13: 1994 | M13: =B18*SUM('Escapement Age'!X18:Z18)+C18*SUM('Escapement Age'!X18:Y18) -> 15444.282 | N13: 1995 | O13: =B19*SUM('Escapement Age'!AA19:AC19)+'Run Reconstruction 1'!C19*SUM('Escapement Age'!AA19:AC19) -> 2054.149 | P13: 1996 | Q13: =B20*SUM('Escapement Age'!AD20:AF20)+C20*SUM('Escapement Age'!AD20:AF20) -> 15.685151 | R13: 1997 | S13: =B21*SUM('Escapement Age'!AG21)+C21*SUM('Escapement Age'!AG21) -> 0 | U13: =B13/1000 -> 31.570475 | V13: =E13/1000 -> 27.573431
A14: 1990 | B14: ='Summary Data'!C14 -> 73180.572 | C14: ='Summary Data'!H14 -> 6029 | D14: =SUM(B14:C14) -> 79209.572 | E14: =SUM(I14,K14,M14,O14,Q14,S14) -> 44788.023 | F14: =E14/B14 -> 0.61202067 | G14: =LN(F14) -> -0.49098921 | H14: 1993 | I14: =B17*SUM('Escapement Age'!S17:T17)+C17*'Escapement Age'!S17 -> 268.78462 | J14: 1994 | K14: =B18*SUM('Escapement Age'!U18:W18)+C18*SUM('Escapement Age'!U18:V18) -> 12580.691 | L14: 1995 | M14: =B19*SUM('Escapement Age'!X19:Z19)+C19*SUM('Escapement Age'!X19:Y19) -> 28879.942 | N14: 1996 | O14: =B20*SUM('Escapement Age'!AA20:AC20)+'Run Reconstruction 1'!C20*SUM('Escapement Age'!AA20:AC20) -> 3058.6045 | P14: 1997 | Q14: =B21*SUM('Escapement Age'!AD21:AF21)+C21*SUM('Escapement Age'!AD21:AF21) -> 0 | R14: 1998 | S14: 0 | U14: =B14/1000 -> 73.180572 | V14: =E14/1000 -> 44.788023
A15: 1991 | B15: ='Summary Data'!C15 -> 45509.809 | C15: ='Summary Data'!H15 -> 3106 | D15: =SUM(B15:C15) -> 48615.809 | E15: =SUM(I15,K15,M15,O15,Q15,S15) -> 35903.724 | F15: =E15/B15 -> 0.78892276 | G15: =LN(F15) -> -0.23708686 | H15: 1994 | I15: =B18*SUM('Escapement Age'!S18:T18)+C18*'Escapement Age'!S18 -> 384.19488 | J15: 1995 | K15: =B19*SUM('Escapement Age'!U19:W19)+C19*SUM('Escapement Age'!U19:V19) -> 5419.2378 | L15: 1996 | M15: =B20*SUM('Escapement Age'!X20:Z20)+C20*SUM('Escapement Age'!X20:Y20) -> 14775.412 | N15: 1997 | O15: =B21*SUM('Escapement Age'!AA21:AC21)+'Run Reconstruction 1'!C21*SUM('Escapement Age'!AA21:AC21) -> 15148.317 | P15: 1998 | Q15: =Q55 -> 176.56229 | R15: 1999 | S15: =B23*SUM('Escapement Age'!AG23)+C23*SUM('Escapement Age'!AG23) -> 0 | U15: =B15/1000 -> 45.509809 | V15: =E15/1000 -> 35.903724
A16: 1992 | B16: ='Summary Data'!C16 -> 10325.817 | C16: ='Summary Data'!H16 -> 101 | D16: =SUM(B16:C16) -> 10426.817 | E16: =SUM(I16,K16,M16,O16,Q16,S16) -> 33072.008 | F16: =E16/B16 -> 3.2028467 | G16: =LN(F16) -> 1.16404 | H16: 1995 | I16: =B19*SUM('Escapement Age'!S19:T19)+C19*'Escapement Age'!S19 -> 3173.9954 | J16: 1996 | K16: =B20*SUM('Escapement Age'!U20:W20)+C20*SUM('Escapement Age'!U20:V20) -> 6196.6404 | L16: 1997 | M16: =B21*SUM('Escapement Age'!X21:Z21)+C21*SUM('Escapement Age'!X21:Y21) -> 17217.03 | N16: 1998 | O16: =O56 -> 6484.3422 | P16: 1999 | Q16: =B23*SUM('Escapement Age'!AD23:AF23)+C23*SUM('Escapement Age'!AD23:AF23) -> 0 | R16: 2000 | S16: =B24*SUM('Escapement Age'!AG24)+C24*SUM('Escapement Age'!AG24) -> 0 | U16: =B16/1000 -> 10.325817 | V16: =E16/1000 -> 33.072008
A17: 1993 | B17: ='Summary Data'!C17 -> 25018.473 | C17: ='Summary Data'!H17 -> 3142 | D17: =SUM(B17:C17) -> 28160.473 | E17: =SUM(I17,K17,M17,O17,Q17,S17) -> 33128.504 | F17: =E17/B17 -> 1.3241617 | G17: =LN(F17) -> 0.2807796 | H17: 1996 | I17: =B20*SUM('Escapement Age'!S20:T20)+C20*'Escapement Age'!S20 -> 584.58164 | J17: 1997 | K17: =B21*SUM('Escapement Age'!U21:W21)+C21*SUM('Escapement Age'!U21:V21) -> 4583.2368 | L17: 1998 | M17: =M57 -> 17376.264 | N17: 1999 | O17: =B23*SUM('Escapement Age'!AA23:AC23)+'Run Reconstruction 1'!C23*SUM('Escapement Age'!AA23:AC23) -> 10584.422 | P17: 2000 | Q17: =B24*SUM('Escapement Age'!AD24:AF24)+C24*SUM('Escapement Age'!AD24:AF24) -> 0 | R17: 2001 | S17: =B25*SUM('Escapement Age'!AG25)+C25*SUM('Escapement Age'!AG25) -> 0 | U17: =B17/1000 -> 25.018473 | V17: =E17/1000 -> 33.128504
A18: 1994 | B18: ='Summary Data'!C18 -> 39710.383 | C18: ='Summary Data'!H18 -> 6168 | D18: =SUM(B18:C18) -> 45878.383 | E18: =SUM(I18,K18,M18,O18,Q18,S18) -> 79775.016 | F18: =E18/B18 -> 2.0089208 | G18: =LN(F18) -> 0.69759768 | H18: 1997 | I18: =B21*SUM('Escapement Age'!S21:T21)+C21*'Escapement Age'!S21 -> 821.33642 | J18: 1998 | K18: =K58 -> 20079.022 | L18: 1999 | M18: =B23*SUM('Escapement Age'!X23:Z23)+C23*SUM('Escapement Age'!X23:Y23) -> 58639.824 | N18: 2000 | O18: =B24*SUM('Escapement Age'!AA24:AC24)+'Run Reconstruction 1'!C24*SUM('Escapement Age'!AA24:AC24) -> 234.83308 | P18: 2001 | Q18: =B25*SUM('Escapement Age'!AD25:AF25)+C25*SUM('Escapement Age'!AD25:AF25) -> 0 | R18: 2002 | S18: =B26*SUM('Escapement Age'!AG26)+C26*SUM('Escapement Age'!AG26) -> 0 | U18: =B18/1000 -> 39.710383 | V18: =E18/1000 -> 79.775016
A19: 1995 | B19: ='Summary Data'!C19 -> 34797.618 | C19: ='Summary Data'!H19 -> 5502 | D19: =SUM(B19:C19) -> 40299.618 | E19: =SUM(I19,K19,M19,O19,Q19,S19) -> 3751.9711 | F19: =E19/B19 -> 0.10782264 | G19: =LN(F19) -> -2.2272676 | H19: 1998 | I19: =I59 -> 85.333521 | J19: 1999 | K19: =B23*SUM('Escapement Age'!U23:W23)+C23*SUM('Escapement Age'!U23:V23) -> 1063.761 | L19: 2000 | M19: =B24*SUM('Escapement Age'!X24:Z24)+C24*SUM('Escapement Age'!X24:Y24) -> 2465.7474 | N19: 2001 | O19: =B25*SUM('Escapement Age'!AA25:AC25)+'Run Reconstruction 1'!C25*SUM('Escapement Age'!AA25:AC25) -> 99.840673 | P19: 2002 | Q19: =B26*SUM('Escapement Age'!AD26:AF26)+C26*SUM('Escapement Age'!AD26:AF26) -> 37.288518 | R19: 2003 | S19: =B27*SUM('Escapement Age'!AG27)+C27*SUM('Escapement Age'!AG27) -> 0 | U19: =B19/1000 -> 34.797618 | V19: =E19/1000 -> 3.7519711
A20: 1996 | B20: ='Summary Data'!C20 -> 19209.335 | C20: ='Summary Data'!H20 -> 5683 | D20: =SUM(B20:C20) -> 24892.335 | E20: =SUM(I20,K20,M20,O20,Q20,S20) -> 7433.8899 | F20: =E20/B20 -> 0.38699361 | G20: =LN(F20) -> -0.94934709 | H20: 1999 | I20: =B23*SUM('Escapement Age'!S23:T23)+C23*'Escapement Age'!S23 -> 130.81217 | J20: 2000 | K20: =B24*SUM('Escapement Age'!U24:W24)+C24*SUM('Escapement Age'!U24:V24) -> 1038.7975 | L20: 2001 | M20: =B25*SUM('Escapement Age'!X25:Z25)+C25*SUM('Escapement Age'!X25:Y25) -> 3509.8825 | N20: 2002 | O20: =B26*SUM('Escapement Age'!AA26:AC26)+'Run Reconstruction 1'!C26*SUM('Escapement Age'!AA26:AC26) -> 2672.3438 | P20: 2003 | Q20: =B27*SUM('Escapement Age'!AD27:AF27)+C27*SUM('Escapement Age'!AD27:AF27) -> 82.053851 | R20: 2004 | S20: =B28*SUM('Escapement Age'!AG28)+C28*SUM('Escapement Age'!AG28) -> 0 | U20: =B20/1000 -> 19.209335 | V20: =E20/1000 -> 7.4338899
A21: 1997 | B21: ='Summary Data'!C21 -> 28898.406 | C21: ='Summary Data'!H21 -> 9256 | D21: =SUM(B21:C21) -> 38154.406 | E21: =SUM(I21,K21,M21,O21,Q21,S21) -> 27191.067 | F21: =E21/B21 -> 0.94091926 | G21: =LN(F21) -> -0.06089795 | H21: 2000 | I21: =B24*SUM('Escapement Age'!S24:T24)+C24*'Escapement Age'!S24 -> 80.035035 | J21: 2001 | K21: =B25*SUM('Escapement Age'!U25:W25)+C25*SUM('Escapement Age'!U25:V25) -> 1283.2943 | L21: 2002 | M21: =B26*SUM('Escapement Age'!X26:Z26)+C26*SUM('Escapement Age'!X26:Y26) -> 13150.418 | N21: 2003 | O21: =B27*SUM('Escapement Age'!AA27:AC27)+'Run Reconstruction 1'!C27*SUM('Escapement Age'!AA27:AC27) -> 12677.32 | P21: 2004 | Q21: =B28*SUM('Escapement Age'!AD28:AF28)+C28*SUM('Escapement Age'!AD28:AF28) -> 0 | R21: 2005 | S21: =B29*SUM('Escapement Age'!AG29)+C29*SUM('Escapement Age'!AG29) -> 0 | U21: =B21/1000 -> 28.898406 | V21: =E21/1000 -> 27.191067
A22: 1998 | B22: =D22-C22 -> 35267.524 | C22: ='Summary Data'!H22 -> 8934 | D22: =SUM(I19,K18,M17,O16,Q15,S14) -> 44201.524 | E22: =SUM(I22,K22,M22,O22,Q22,S22) -> 81474.629 | F22: =E22/B22 -> 2.3101885 | G22: =LN(F22) -> 0.83732913 | H22: 2001 | I22: =B25*SUM('Escapement Age'!S25:T25)+C25*'Escapement Age'!S25 -> 137.02823 | J22: 2002 | K22: =B26*SUM('Escapement Age'!U26:W26)+C26*SUM('Escapement Age'!U26:V26) -> 10737.668 | L22: 2003 | M22: =B27*SUM('Escapement Age'!X27:Z27)+C27*SUM('Escapement Age'!X27:Y27) -> 64699.461 | N22: 2004 | O22: =B28*SUM('Escapement Age'!AA28:AC28)+'Run Reconstruction 1'!C28*SUM('Escapement Age'!AA28:AC28) -> 5838.8078 | P22: 2005 | Q22: =B29*SUM('Escapement Age'!AD29:AF29)+C29*SUM('Escapement Age'!AD29:AF29) -> 61.663891 | R22: 2006 | S22: =B30*SUM('Escapement Age'!AG30)+C30*SUM('Escapement Age'!AG30) -> 0 | U22: =B22/1000 -> 35.267524 | V22: =E22/1000 -> 81.474629
A23: 1999 | B23: ='Summary Data'!C23 -> 57753.571 | C23: ='Summary Data'!H23 -> 12694 | D23: =SUM(B23:C23) -> 70447.571 | E23: =SUM(I23,K23,M23,O23,Q23,S23) -> 62003.178 | F23: =E23/B23 -> 1.0735817 | G23: =LN(F23) -> 0.071000461 | H23: 2002 | I23: =B26*SUM('Escapement Age'!S26:T26)+C26*'Escapement Age'!S26 -> 44.711501 | J23: 2003 | K23: =B27*SUM('Escapement Age'!U27:W27)+C27*SUM('Escapement Age'!U27:V27) -> 4370.6275 | L23: 2004 | M23: =B28*SUM('Escapement Age'!X28:Z28)+C28*SUM('Escapement Age'!X28:Y28) -> 51452.282 | N23: 2005 | O23: =B29*SUM('Escapement Age'!AA29:AC29)+'Run Reconstruction 1'!C29*SUM('Escapement Age'!AA29:AC29) -> 6135.5571 | P23: 2006 | Q23: =B30*SUM('Escapement Age'!AD30:AF30)+C30*SUM('Escapement Age'!AD30:AF30) -> 0 | R23: 2007 | S23: =B31*SUM('Escapement Age'!AG31)+C31*SUM('Escapement Age'!AG31) -> 0 | U23: =B23/1000 -> 57.753571 | V23: =E23/1000 -> 62.003178
A24: 2000 | B24: ='Summary Data'!C24 -> 3032.1983 | C24: ='Summary Data'!H24 -> 809 | D24: =SUM(B24:C24) -> 3841.1983 | E24: =SUM(I24,K24,M24,O24,Q24,S24) -> 90543.469 | F24: =E24/B24 -> 29.860669 | G24: =LN(F24) -> 3.3965422 | H24: 2003 | I24: =B27*SUM('Escapement Age'!S27:T27)+C27*'Escapement Age'!S27 -> 34.998883 | J24: 2004 | K24: =B28*SUM('Escapement Age'!U28:W28)+C28*SUM('Escapement Age'!U28:V28) -> 31827.453 | L24: 2005 | M24: =B29*SUM('Escapement Age'!X29:Z29)+C29*SUM('Escapement Age'!X29:Y29) -> 46124.59 | N24: 2006 | O24: =B30*SUM('Escapement Age'!AA30:AC30)+'Run Reconstruction 1'!C30*SUM('Escapement Age'!AA30:AC30) -> 12377.088 | P24: 2007 | Q24: =B31*SUM('Escapement Age'!AD31:AF31)+C31*SUM('Escapement Age'!AD31:AF31) -> 179.33923 | R24: 2008 | S24: =B32*SUM('Escapement Age'!AG32)+C32*SUM('Escapement Age'!AG32) -> 0 | U24: =B24/1000 -> 3.0321983 | V24: =E24/1000 -> 90.543469 | AA24: function LINEST
A25: 2001 | B25: ='Summary Data'!C25 -> 3666.9945 | C25: ='Summary Data'!H25 -> 1454 | D25: =SUM(B25:C25) -> 5120.9945 | E25: =SUM(I25,K25,M25,O25,Q25,S25) -> 74923.083 | F25: =E25/B25 -> 20.431741 | G25: =LN(F25) -> 3.0170896 | H25: 2004 | I25: =B28*SUM('Escapement Age'!S28:T28)+C28*'Escapement Age'!S28 -> 848.70794 | J25: 2005 | K25: =B29*SUM('Escapement Age'!U29:W29)+C29*SUM('Escapement Age'!U29:V29) -> 18474.486 | L25: 2006 | M25: =B30*SUM('Escapement Age'!X30:Z30)+C30*SUM('Escapement Age'!X30:Y30) -> 44609.088 | N25: 2007 | O25: =B31*SUM('Escapement Age'!AA31:AC31)+'Run Reconstruction 1'!C31*SUM('Escapement Age'!AA31:AC31) -> 10939.693 | P25: 2008 | Q25: =B32*SUM('Escapement Age'!AD32:AF32)+C32*SUM('Escapement Age'!AD32:AF32) -> 51.108572 | R25: 2009 | S25: =B33*SUM('Escapement Age'!AG33)+C33*SUM('Escapement Age'!AG33) -> 0 | U25: =B25/1000 -> 3.6669945 | V25: =E25/1000 -> 74.923083 | Y25: beta^ | Z25: slope | AA25: {=LINEST(G6:G37,B6:B37,1,1)} -> -4.0698178e-05 | AB25: 1.6827988 | AC25: intercept | AD25: ln(alpha^)
A26: 2002 | B26: ='Summary Data'!C26 -> 23987.72 | C26: ='Summary Data'!H26 -> 2686 | D26: =SUM(B26:C26) -> 26673.72 | E26: =SUM(I26,K26,M26,O26,Q26,S26) -> 142828.14 | F26: =E26/B26 -> 5.954219 | G26: =LN(F26) -> 1.7841 | H26: 2005 | I26: =B29*SUM('Escapement Age'!S29:T29)+C29*'Escapement Age'!S29 -> 1307.2713 | J26: 2006 | K26: =B30*SUM('Escapement Age'!U30:W30)+C30*SUM('Escapement Age'!U30:V30) -> 72199.68 | L26: 2007 | M26: =B31*SUM('Escapement Age'!X31:Z31)+C31*SUM('Escapement Age'!X31:Y31) -> 66893.531 | N26: 2008 | O26: =B32*SUM('Escapement Age'!AA32:AC32)+'Run Reconstruction 1'!C32*SUM('Escapement Age'!AA32:AC32) -> 2427.6572 | P26: 2009 | Q26: =B33*SUM('Escapement Age'!AD33:AF33)+C33*SUM('Escapement Age'!AD33:AF33) -> 0 | R26: 2010 | S26: =B34*SUM('Escapement Age'!AG34)+C34*SUM('Escapement Age'!AG34) -> 0 | U26: =B26/1000 -> 23.98772 | V26: =E26/1000 -> 142.82814 | Z26: SE | AA26: 6.6787219e-06 | AB26: 0.2756426 | AC26: SE
A27: 2003 | B27: ='Summary Data'!C27 -> 69892.77 | C27: ='Summary Data'!H27 -> 12038 | D27: =SUM(B27:C27) -> 81930.77 | E27: =SUM(I27,K27,M27,O27,Q27,S27) -> 12287.441 | F27: =E27/B27 -> 0.17580418 | G27: =LN(F27) -> -1.7383845 | H27: 2006 | I27: =B30*SUM('Escapement Age'!S30:T30)+C30*'Escapement Age'!S30 -> 0 | J27: 2007 | K27: =B31*SUM('Escapement Age'!U31:W31)+C31*SUM('Escapement Age'!U31:V31) -> 4662.8199 | L27: 2008 | M27: =B32*SUM('Escapement Age'!X32:Z32)+C32*SUM('Escapement Age'!X32:Y32) -> 7206.3086 | N27: 2009 | O27: =B33*SUM('Escapement Age'!AA33:AC33)+'Run Reconstruction 1'!C33*SUM('Escapement Age'!AA33:AC33) -> 418.31253 | P27: 2010 | Q27: =B34*SUM('Escapement Age'!AD34:AF34)+C34*SUM('Escapement Age'!AD34:AF34) -> 0 | R27: 2011 | S27: =B35*SUM('Escapement Age'!AG35)+C35*SUM('Escapement Age'!AG35) -> 0 | U27: =B27/1000 -> 69.89277 | V27: =E27/1000 -> 12.287441 | Z27: r-sq | AA27: 0.55312769 | AB27: 0.98895758 | AC27: RMSE | AD27: sigma^
A28: 2004 | B28: ='Summary Data'!C28 -> 77262.734 | C28: ='Summary Data'!H28 -> 12938 | D28: =SUM(B28:C28) -> 90200.734 | E28: =SUM(I28,K28,M28,O28,Q28,S28) -> 17135.228 | F28: =E28/B28 -> 0.22177869 | G28: =LN(F28) -> -1.5060753 | H28: 2007 | I28: =B31*SUM('Escapement Age'!S31:T31)+C31*'Escapement Age'!S31 -> 0 | J28: 2008 | K28: =B32*SUM('Escapement Age'!U32:W32)+C32*SUM('Escapement Age'!U32:V32) -> 1765.7623 | L28: 2009 | M28: =B33*SUM('Escapement Age'!X33:Z33)+C33*SUM('Escapement Age'!X33:Y33) -> 11873.64 | N28: 2010 | O28: =B34*SUM('Escapement Age'!AA34:AC34)+'Run Reconstruction 1'!C34*SUM('Escapement Age'!AA34:AC34) -> 3495.8256 | P28: 2011 | Q28: =B35*SUM('Escapement Age'!AD35:AF35)+C35*SUM('Escapement Age'!AD35:AF35) -> 0 | R28: 2012 | S28: =B36*SUM('Escapement Age'!AG36)+C36*SUM('Escapement Age'!AG36) -> 0 | U28: =B28/1000 -> 77.262734 | V28: =E28/1000 -> 17.135228 | Z28: F | AA28: 37.133271 | AB28: 30 | AC28: df
A29: 2005 | B29: ='Summary Data'!C29 -> 65653.383 | C29: ='Summary Data'!H29 -> 7295 | D29: =SUM(B29:C29) -> 72948.383 | E29: =SUM(I29,K29,M29,O29,Q29,S29) -> 10064.965 | F29: =E29/B29 -> 0.15330458 | G29: =LN(F29) -> -1.8753286 | H29: 2008 | I29: =B32*SUM('Escapement Age'!S32:T32)+C32*'Escapement Age'!S32 -> 22.314818 | J29: 2009 | K29: =B33*SUM('Escapement Age'!U33:W33)+C33*SUM('Escapement Age'!U33:V33) -> 1619.3294 | L29: 2010 | M29: =B34*SUM('Escapement Age'!X34:Z34)+C34*SUM('Escapement Age'!X34:Y34) -> 4827.5686 | N29: 2011 | O29: =B35*SUM('Escapement Age'!AA35:AC35)+'Run Reconstruction 1'!C35*SUM('Escapement Age'!AA35:AC35) -> 3595.7516 | P29: 2012 | Q29: =B36*SUM('Escapement Age'!AD36:AF36)+C36*SUM('Escapement Age'!AD36:AF36) -> 0 | R29: 2013 | S29: =B37*SUM('Escapement Age'!AG37)+C37*SUM('Escapement Age'!AG37) -> 0 | U29: =B29/1000 -> 65.653383 | V29: =E29/1000 -> 10.064965 | Z29: SSR | AA29: 36.317717 | AB29: 29.341113 | AC29: SSE
A30: 2006 | B30: ='Summary Data'!C30 -> 103952.86 | C30: ='Summary Data'!H30 -> 25233 | D30: =SUM(B30:C30) -> 129185.86 | E30: =SUM(I30,K30,M30,O30,Q30,S30) -> 29816.498 | F30: =E30/B30 -> 0.28682712 | G30: =LN(F30) -> -1.2488756 | H30: 2009 | I30: =B33*SUM('Escapement Age'!S33:T33)+C33*'Escapement Age'!S33 -> 553.68989 | J30: 2010 | K30: =B34*SUM('Escapement Age'!U34:W34)+C34*SUM('Escapement Age'!U34:V34) -> 11835.864 | L30: 2011 | M30: =B35*SUM('Escapement Age'!X35:Z35)+C35*SUM('Escapement Age'!X35:Y35) -> 15461.732 | N30: 2012 | O30: =B36*SUM('Escapement Age'!AA36:AC36)+'Run Reconstruction 1'!C36*SUM('Escapement Age'!AA36:AC36) -> 1965.2129 | P30: 2013 | Q30: =B37*SUM('Escapement Age'!AD37:AF37)+C37*SUM('Escapement Age'!AD37:AF37) -> 0 | R30: 2014 | S30: =B38*SUM('Escapement Age'!AG38)+C38*SUM('Escapement Age'!AG38) -> 0 | U30: =B30/1000 -> 103.95286 | V30: =E30/1000 -> 29.816498
A31: 2007 | B31: ='Summary Data'!C31 -> 66938.383 | C31: ='Summary Data'!H31 -> 15737 | D31: =SUM(B31:C31) -> 82675.383 | E31: =SUM(I31,K31,M31,O31,Q31,S31) -> 29874.618 | F31: =E31/B31 -> 0.44630027 | G31: =LN(F31) -> -0.80676331 | H31: 2010 | I31: =B34*SUM('Escapement Age'!S34:T34)+C34*'Escapement Age'!S34 -> 0 | J31: 2011 | K31: =B35*SUM('Escapement Age'!U35:W35)+C35*SUM('Escapement Age'!U35:V35) -> 3348.4318 | L31: 2012 | M31: =B36*SUM('Escapement Age'!X36:Z36)+C36*SUM('Escapement Age'!X36:Y36) -> 16949.961 | N31: 2013 | O31: =B37*SUM('Escapement Age'!AA37:AC37)+'Run Reconstruction 1'!C37*SUM('Escapement Age'!AA37:AC37) -> 9480.1502 | P31: 2014 | Q31: =B38*SUM('Escapement Age'!AD38:AF38)+C38*SUM('Escapement Age'!AD38:AF38) -> 96.075376 | R31: 2015 | S31: =B39*SUM('Escapement Age'!AG39)+C39*SUM('Escapement Age'!AG39) -> 0 | U31: =B31/1000 -> 66.938383 | V31: =E31/1000 -> 29.874618 | AA31: SLR | AB31: AR1
A32: 2008 | B32: ='Summary Data'!C32 -> 10063.983 | C32: ='Summary Data'!H32 -> 1461 | D32: =SUM(B32:C32) -> 11524.983 | E32: =SUM(I32,K32,M32,O32,Q32,S32) -> 67741.007 | F32: =E32/B32 -> 6.7310335 | G32: =LN(F32) -> 1.9067287 | H32: 2011 | I32: =B35*SUM('Escapement Age'!S35:T35)+C35*'Escapement Age'!S35 -> 2437.5422 | J32: 2012 | K32: =B36*SUM('Escapement Age'!U36:W36)+C36*SUM('Escapement Age'!U36:V36) -> 23899.734 | L32: 2013 | M32: =B37*SUM('Escapement Age'!X37:Z37)+C37*SUM('Escapement Age'!X37:Y37) -> 36407.811 | N32: 2014 | O32: =B38*SUM('Escapement Age'!AA38:AC38)+'Run Reconstruction 1'!C38*SUM('Escapement Age'!AA38:AC38) -> 4995.9195 | P32: 2015 | Q32: =B39*SUM('Escapement Age'!AD39:AF39)+C39*SUM('Escapement Age'!AD39:AF39) -> 0 | R32: 2016 | S32: =B40*SUM('Escapement Age'!AG40)+C40*SUM('Escapement Age'!AG40) -> 0 | U32: =B32/1000 -> 10.063983 | V32: =E32/1000 -> 67.741007 | Z32: lnalpha^ | AA32: =AB25 -> 1.6827988 | AB32: 1.5528306
A33: 2009 | B33: ='Summary Data'!C33 -> 12568.761 | C33: ='Summary Data'!H33 -> 2040 | D33: =SUM(B33:C33) -> 14608.761 | E33: =SUM(I33,K33,M33,O33,Q33,S33) -> 24216.492 | F33: =E33/B33 -> 1.9267208 | G33: =LN(F33) -> 0.65581948 | H33: 2012 | I33: =B36*SUM('Escapement Age'!S36:T36)+C36*'Escapement Age'!S36 -> 3541.8578 | J33: 2013 | K33: =B37*SUM('Escapement Age'!U37:W37)+C37*SUM('Escapement Age'!U37:V37) -> 10109.023 | L33: 2014 | M33: =B38*SUM('Escapement Age'!X38:Z38)+C38*SUM('Escapement Age'!X38:Y38) -> 10376.141 | N33: 2015 | O33: =B39*SUM('Escapement Age'!AA39:AC39)+'Run Reconstruction 1'!C39*SUM('Escapement Age'!AA39:AC39) -> 189.47053 | P33: 2016 | Q33: =B40*SUM('Escapement Age'!AD40:AF40)+C40*SUM('Escapement Age'!AD40:AF40) -> 0 | R33: 2017 | S33: =B41*SUM('Escapement Age'!AG41)+C41*SUM('Escapement Age'!AG41) -> 0 | U33: =B33/1000 -> 12.568761 | V33: =E33/1000 -> 24.216492 | Z33: beta^ | AA33: =-AA25 -> 4.0698178e-05 | AB33: 3.7985844e-05
A34: 2010 | B34: ='Summary Data'!C34 -> 17156.231 | C34: ='Summary Data'!H34 -> 3028 | D34: =SUM(B34:C34) -> 20184.231 | E34: =SUM(I34,K34,M34,O34,Q34,S34) -> 17254.525 | F34: =E34/B34 -> 1.0057293 | G34: =LN(F34) -> 0.0057129748 | H34: 2013 | I34: =B37*SUM('Escapement Age'!S37:T37)+C37*'Escapement Age'!S37 -> 1623.2371 | J34: 2014 | K34: =B38*SUM('Escapement Age'!U38:W38)+C38*SUM('Escapement Age'!U38:V38) -> 6179.8896 | L34: 2015 | M34: =B39*SUM('Escapement Age'!X39:Z39)+C39*SUM('Escapement Age'!X39:Y39) -> 8715.6444 | N34: 2016 | O34: =B40*SUM('Escapement Age'!AA40:AC40)+'Run Reconstruction 1'!C40*SUM('Escapement Age'!AA40:AC40) -> 735.75342 | P34: 2017 | Q34: =B41*SUM('Escapement Age'!AD41:AF41)+C41*SUM('Escapement Age'!AD41:AF41) -> 0 | R34: 2018 | S34: =B42*SUM('Escapement Age'!AG42)+C42*SUM('Escapement Age'!AG42) -> 0 | U34: =B34/1000 -> 17.156231 | V34: =E34/1000 -> 17.254525 | Z34: sigma^ | AA34: =AB27 -> 0.98895758 | AB34: 0.96204303
A35: 2011 | B35: ='Summary Data'!C35 -> 22719.733 | C35: ='Summary Data'!H35 -> 2656 | D35: =SUM(B35:C35) -> 25375.733 | E35: =SUM(I35,K35,M35,O35,Q35,S35) -> 25591.964 | F35: =E35/B35 -> 1.1264201 | G35: =LN(F35) -> 0.11904456 | H35: 2014 | I35: =B38*SUM('Escapement Age'!S38:T38)+C38*'Escapement Age'!S38 -> 2837.3512 | J35: 2015 | K35: =B39*SUM('Escapement Age'!U39:W39)+C39*SUM('Escapement Age'!U39:V39) -> 6627.1179 | L35: 2016 | M35: =B40*SUM('Escapement Age'!X40:Z40)+C40*SUM('Escapement Age'!X40:Y40) -> 9722.456 | N35: 2017 | O35: =B41*SUM('Escapement Age'!AA41:AC41)+'Run Reconstruction 1'!C41*SUM('Escapement Age'!AA41:AC41) -> 6405.0391 | P35: 2018 | Q35: =B42*SUM('Escapement Age'!AD42:AF42)+C42*SUM('Escapement Age'!AD42:AF42) -> 0 | R35: 2019 | S35: 0 | U35: =B35/1000 -> 22.719733 | V35: =E35/1000 -> 25.591964 | Z35: lnalpha' | AA35: =AA32+AA34^2/2 -> 2.1718174 | AB35: 2.0531963
A36: 2012 | B36: ='Summary Data'!C36 -> 40943.877 | C36: ='Summary Data'!H36 -> 6385 | D36: =SUM(B36:C36) -> 47328.877 | E36: =SUM(I36,K36,M36,O36,Q36,S36) -> 39575.912 | F36: =E36/B36 -> 0.96658927 | G36: =LN(F36) -> -0.033981624 | H36: 2015 | I36: =B39*SUM('Escapement Age'!S39:T39)+C39*'Escapement Age'!S39 -> 1537.7443 | J36: 2016 | K36: =B40*SUM('Escapement Age'!U40:W40)+C40*SUM('Escapement Age'!U40:V40) -> 15557.215 | L36: 2017 | M36: =B41*SUM('Escapement Age'!X41:Z41)+C41*SUM('Escapement Age'!X41:Y41) -> 21309.072 | N36: 2018 | O36: =B42*SUM('Escapement Age'!AA42:AC42)+'Run Reconstruction 1'!C42*SUM('Escapement Age'!AA42:AC42) -> 1171.8798 | P36: 2019 | Q36: 0 | R36: 2020 | S36: 0 | U36: =B36/1000 -> 40.943877 | V36: =E36/1000 -> 39.575912 | Z36: Smax^ | AA36: =1/AA33 -> 24571.125 | AB36: =1/AB33 -> 26325.596
A37: 2013 | B37: ='Summary Data'!C37 -> 49124.281 | C37: ='Summary Data'!H37 -> 8866 | D37: =SUM(B37:C37) -> 57990.281 | E37: =SUM(I37,K37,M37,O37,Q37,S37) -> 24156.273 | F37: =E37/B37 -> 0.49173794 | G37: =LN(F37) -> -0.70980934 | H37: 2016 | I37: =B40*SUM('Escapement Age'!S40:T40)+C40*'Escapement Age'!S40 -> 623.94521 | J37: 2017 | K37: =B41*SUM('Escapement Age'!U41:W41)+C41*SUM('Escapement Age'!U41:V41) -> 4928.8262 | L37: 2018 | M37: =B42*SUM('Escapement Age'!X42:Z42)+C42*SUM('Escapement Age'!X42:Y42) -> 13867.244 | N37: 2019 | O37: =O77 -> 4736.2573 | P37: 2020 | Q37: 0 | R37: 2021 | S37: 0 | U37: =B37/1000 -> 49.124281 | V37: =E37/1000 -> 24.156273 | Z37: Seq^ | AA37: =AA35/AA33 -> 53363.996 | AB37: =AB35/AB33 -> 54051.616
A38: 2014 | B38: ='Summary Data'!C38 -> 19936.125 | C38: ='Summary Data'!H38 -> 5716 | D38: =SUM(B38:C38) -> 25652.125 | E38: =SUM(I38,K38,M38,O38,Q38,S38) -> 113959.32 | F38: Incomplete | H38: 2017 | I38: =B41*SUM('Escapement Age'!S41:T41)+C41*'Escapement Age'!S41 -> 26654.277 | J38: 2018 | K38: =B42*SUM('Escapement Age'!U42:W42)+C42*SUM('Escapement Age'!U42:V42) -> 87305.044 | L38: 2019 | N38: 2020 | P38: 2021 | R38: 2022 | Z38: Smsy^ | AA38: =AA37*(0.5-0.07*AA35) -> 18569.218 | AB38: =AB37*(0.5-0.07*AB35) -> 19257.308
A39: 2015 | B39: ='Summary Data'!C39 -> 13982.744 | C39: ='Summary Data'!H39 -> 4538 | D39: =SUM(B39:C39) -> 18520.744 | E39: =SUM(I39,K39,M39,O39,Q39,S39) -> 3361.1111 | F39: Incomplete | H39: 2018 | I39: =B42*SUM('Escapement Age'!S42:T42)+C42*'Escapement Age'!S42 -> 3361.1111 | J39: 2019 | L39: 2020 | N39: 2021 | P39: 2022 | R39: 2023 | Z39: Umsy^ | AA39: =AA35*(0.5-0.07*AA35) -> 0.75573334 | AB39: =AB35*(0.5-0.07*AB35) -> 0.73150509
A40: 2016 | B40: ='Summary Data'!C40 -> 22774 | C40: ='Summary Data'!H40 -> 4081 | D40: =SUM(B40:C40) -> 26855 | Z40: MSY^ | AA40: =AA38*EXP(AA35-AA33*AA38)-AA38 -> 57953.627 | AB40: =AB38*EXP(AB35-AB33*AB38)-AB38 -> 52952.927
A41: 2017 | B41: ='Summary Data'!C41 -> 55702 | C41: ='Summary Data'!H41 -> 7363 | D41: =SUM(B41:C41) -> 63065 | Z41: S Contrast | AA41: =MAX(B6:B28)/MIN(B6:B28) -> 169.49497
...

Sheet Run Reconstruction 2
A1: Redoubt Lake sockeye salmon brood table:
A2: RED data imputed for missing escapement in 1998 - based on average age at return, BY1982-1990.
H4: Estimated Return by Year:
A5: Year | B5: Escapement | C5: Harvest | D5: Run | E5: Return | F5: R/S | G5: Ln R/S | H5: Year | I5: age 3 | K5: age 4 | M5: age 5 | O5: age 6 | Q5: age 7 | S5: age 8 | U5: S | V5: R
A6: 1982 | B6: ='Summary Data'!C6 -> 455.84087 | C6: ='Summary Data'!H6 -> 97 | D6: =SUM(B6:C6) -> 552.84087 | E6: =SUM(I6,K6,M6,O6,Q6,S6) -> 6855.6678 | F6: =E6/B6 -> 15.039608 | G6: =LN(F6) -> 2.7106872 | H6: 1985 | I6: =B9*SUM('Escapement Age'!S9:T9)+C9*'Escapement Age'!S9 -> 75.45557 | J6: 1986 | K6: =B10*SUM('Escapement Age'!U10:W10)+C10*SUM('Escapement Age'!U10:V10) -> 1807.8226 | L6: 1987 | M6: =B11*SUM('Escapement Age'!X11:Z11)+C11*SUM('Escapement Age'!X11:Y11) -> 4612.1024 | N6: 1988 | O6: =B12*SUM('Escapement Age'!AA12:AC12)+'Run Reconstruction 2'!C12*SUM('Escapement Age'!AA12:AC12) -> 339.78668 | P6: 1989 | Q6: =B13*SUM('Escapement Age'!AD13:AF13)+C13*SUM('Escapement Age'!AD13:AF13) -> 20.500583 | R6: 1990 | S6: =B14*SUM('Escapement Age'!AG14)+C14*SUM('Escapement Age'!AG14) -> 0 | U6: =B6/1000 -> 0.45584087 | V6: =E6/1000 -> 6.8556678
A7: 1983 | B7: ='Summary Data'!C7 -> 2539.7855 | C7: ='Summary Data'!H7 -> 36 | D7: =SUM(B7:C7) -> 2575.7855 | E7: =SUM(I7,K7,M7,O7,Q7,S7) -> 12843.288 | F7: =E7/B7 -> 5.0568398 | G7: =LN(F7) -> 1.6207417 | H7: 1986 | I7: =B10*SUM('Escapement Age'!S10:T10)+C10*'Escapement Age'!S10 -> 68.625318 | J7: 1987 | K7: =B11*SUM('Escapement Age'!U11:W11)+C11*SUM('Escapement Age'!U11:V11) -> 5948.6908 | L7: 1988 | M7: =B12*SUM('Escapement Age'!X12:Z12)+C12*SUM('Escapement Age'!X12:Y12) -> 2786.2508 | N7: 1989 | O7: =B13*SUM('Escapement Age'!AA13:AC13)+'Run Reconstruction 2'!C13*SUM('Escapement Age'!AA13:AC13) -> 4018.1143 | P7: 1990 | Q7: =B14*SUM('Escapement Age'!AD14:AF14)+C14*SUM('Escapement Age'!AD14:AF14) -> 0 | R7: 1991 | S7: =B15*SUM('Escapement Age'!AG15)+C15*SUM('Escapement Age'!AG15) -> 21.607026 | U7: =B7/1000 -> 2.5397855 | V7: =E7/1000 -> 12.843288
A8: 1984 | B8: ='Summary Data'!C8 -> 11579.407 | C8: ='Summary Data'!H8 -> 175 | D8: =SUM(B8:C8) -> 11754.407 | E8: =SUM(I8,K8,M8,O8,Q8,S8) -> 50074.938 | F8: =E8/B8 -> 4.3244821 | G8: =LN(F8) -> 1.4642924 | H8: 1987 | I8: =B11*SUM('Escapement Age'!S11:T11)+C11*'Escapement Age'!S11 -> 94.201613 | J8: 1988 | K8: =B12*SUM('Escapement Age'!U12:W12)+C12*SUM('Escapement Age'!U12:V12) -> 465.99317 | L8: 1989 | M8: =B13*SUM('Escapement Age'!X13:Z13)+C13*SUM('Escapement Age'!X13:Y13) -> 27202.667 | N8: 1990 | O8: =B14*SUM('Escapement Age'!AA14:AC14)+'Run Reconstruction 2'!C14*SUM('Escapement Age'!AA14:AC14) -> 21080.476 | P8: 1991 | Q8: =B15*SUM('Escapement Age'!AD15:AF15)+C15*SUM('Escapement Age'!AD15:AF15) -> 1231.6005 | R8: 1992 | S8: =B16*SUM('Escapement Age'!AG16)+C16*SUM('Escapement Age'!AG16) -> 0 | U8: =B8/1000 -> 11.579407 | V8: =E8/1000 -> 50.074938
A9: 1985 | B9: ='Summary Data'!C9 -> 10991.361 | C9: ='Summary Data'!H9 -> 238 | D9: =SUM(B9:C9) -> 11229.361 | E9: =SUM(I9,K9,M9,O9,Q9,S9) -> 96153.771 | F9: =E9/B9 -> 8.7481221 | G9: =LN(F9) -> 2.1688391 | H9: 1988 | I9: =B12*SUM('Escapement Age'!S12:T12)+C12*'Escapement Age'!S12 -> 0 | J9: 1989 | K9: =B13*SUM('Escapement Age'!U13:W13)+C13*SUM('Escapement Age'!U13:V13) -> 2775.6397 | L9: 1990 | M9: =B14*SUM('Escapement Age'!X14:Z14)+C14*SUM('Escapement Age'!X14:Y14) -> 53395.456 | N9: 1991 | O9: =B15*SUM('Escapement Age'!AA15:AC15)+'Run Reconstruction 2'!C15*SUM('Escapement Age'!AA15:AC15) -> 39778.535 | P9: 1992 | Q9: =B16*SUM('Escapement Age'!AD16:AF16)+C16*SUM('Escapement Age'!AD16:AF16) -> 204.13948 | R9: 1993 | S9: =B17*SUM('Escapement Age'!AG17)+C17*SUM('Escapement Age'!AG17) -> 0 | U9: =B9/1000 -> 10.991361 | V9: =E9/1000 -> 96.153771
A10: 1986 | B10: ='Summary Data'!C10 -> 9798.1704 | C10: ='Summary Data'!H10 -> 98 | D10: =SUM(B10:C10) -> 9896.1704 | E10: =SUM(I10,K10,M10,O10,Q10,S10) -> 10915.724 | F10: =E10/B10 -> 1.1140574 | G10: =LN(F10) -> 0.10800863 | H10: 1989 | I10: =B13*SUM('Escapement Age'!S13:T13)+C13*'Escapement Age'!S13 -> 151.1453 | J10: 1990 | K10: =B14*SUM('Escapement Age'!U14:W14)+C14*SUM('Escapement Age'!U14:V14) -> 4221.5122 | L10: 1991 | M10: =B15*SUM('Escapement Age'!X15:Z15)+C15*SUM('Escapement Age'!X15:Y15) -> 3238.2931 | N10: 1992 | O10: =B16*SUM('Escapement Age'!AA16:AC16)+'Run Reconstruction 2'!C16*SUM('Escapement Age'!AA16:AC16) -> 3038.5377 | P10: 1993 | Q10: =B17*SUM('Escapement Age'!AD17:AF17)+C17*SUM('Escapement Age'!AD17:AF17) -> 266.23567 | R10: 1994 | S10: =B18*SUM('Escapement Age'!AG18)+C18*SUM('Escapement Age'!AG18) -> 0 | U10: =B10/1000 -> 9.7981704 | V10: =E10/1000 -> 10.915724
A11: 1987 | B11: ='Summary Data'!C11 -> 14251.358 | C11: ='Summary Data'!H11 -> 285 | D11: =SUM(B11:C11) -> 14536.358 | E11: =SUM(I11,K11,M11,O11,Q11,S11) -> 14253.971 | F11: =E11/B11 -> 1.0001834 | G11: =LN(F11) -> 0.00018333767 | H11: 1990 | I11: =B14*SUM('Escapement Age'!S14:T14)+C14*'Escapement Age'!S14 -> 466.4897 | J11: 1991 | K11: =B15*SUM('Escapement Age'!U15:W15)+C15*SUM('Escapement Age'!U15:V15) -> 4196.3247 | L11: 1992 | M11: =B16*SUM('Escapement Age'!X16:Z16)+C16*SUM('Escapement Age'!X16:Y16) -> 4694.5996 | N11: 1993 | O11: =B17*SUM('Escapement Age'!AA17:AC17)+'Run Reconstruction 2'!C17*SUM('Escapement Age'!AA17:AC17) -> 4150.8561 | P11: 1994 | Q11: =B18*SUM('Escapement Age'!AD18:AF18)+C18*SUM('Escapement Age'!AD18:AF18) -> 745.70127 | R11: 1995 | S11: =B19*SUM('Escapement Age'!AG19)+C19*SUM('Escapement Age'!AG19) -> 0 | U11: =B11/1000 -> 14.251358 | V11: =E11/1000 -> 14.253971
A12: 1988 | B12: ='Summary Data'!C12 -> 3252.0307 | C12: ='Summary Data'!H12 -> 340 | D12: =SUM(B12:C12) -> 3592.0307 | E12: =SUM(I12,K12,M12,O12,Q12,S12) -> 32610.622 | F12: =E12/B12 -> 10.027772 | G12: =LN(F12) -> 2.3053584 | H12: 1991 | I12: =B15*SUM('Escapement Age'!S15:T15)+C15*'Escapement Age'!S15 -> 101.13291 | J12: 1992 | K12: =B16*SUM('Escapement Age'!U16:W16)+C16*SUM('Escapement Age'!U16:V16) -> 1736.5725 | L12: 1993 | M12: =B17*SUM('Escapement Age'!X17:Z17)+C17*SUM('Escapement Age'!X17:Y17) -> 14049.982 | N12: 1994 | O12: =B18*SUM('Escapement Age'!AA18:AC18)+'Run Reconstruction 2'!C18*SUM('Escapement Age'!AA18:AC18) -> 16618.485 | P12: 1995 | Q12: =B19*SUM('Escapement Age'!AD19:AF19)+C19*SUM('Escapement Age'!AD19:AF19) -> 104.44825 | R12: 1996 | S12: =B20*SUM('Escapement Age'!AG20)+C20*SUM('Escapement Age'!AG20) -> 0 | U12: =B12/1000 -> 3.2520307 | V12: =E12/1000 -> 32.610622
A13: 1989 | B13: ='Summary Data'!C13 -> 31570.475 | C13: ='Summary Data'!H13 -> 2686 | D13: =SUM(B13:C13) -> 34256.475 | E13: =SUM(I13,K13,M13,O13,Q13,S13) -> 27573.431 | F13: =E13/B13 -> 0.87339299 | G13: =LN(F13) -> -0.13536966 | H13: 1992 | I13: =B16*SUM('Escapement Age'!S16:T16)+C16*'Escapement Age'!S16 -> 738.6691 | J13: 1993 | K13: =B17*SUM('Escapement Age'!U17:W17)+C17*SUM('Escapement Age'!U17:V17) -> 9320.6459 | L13: 1994 | M13: =B18*SUM('Escapement Age'!X18:Z18)+C18*SUM('Escapement Age'!X18:Y18) -> 15444.282 | N13: 1995 | O13: =B19*SUM('Escapement Age'!AA19:AC19)+'Run Reconstruction 2'!C19*SUM('Escapement Age'!AA19:AC19) -> 2054.149 | P13: 1996 | Q13: =B20*SUM('Escapement Age'!AD20:AF20)+C20*SUM('Escapement Age'!AD20:AF20) -> 15.685151 | R13: 1997 | S13: =B21*SUM('Escapement Age'!AG21)+C21*SUM('Escapement Age'!AG21) -> 0 | U13: =B13/1000 -> 31.570475 | V13: =E13/1000 -> 27.573431
A14: 1990 | B14: ='Summary Data'!C14 -> 73180.572 | C14: ='Summary Data'!H14 -> 6029 | D14: =SUM(B14:C14) -> 79209.572 | E14: =SUM(I14,K14,M14,O14,Q14,S14) -> 44788.023 | F14: =E14/B14 -> 0.61202067 | G14: =LN(F14) -> -0.49098921 | H14: 1993 | I14: =B17*SUM('Escapement Age'!S17:T17)+C17*'Escapement Age'!S17 -> 268.78462 | J14: 1994 | K14: =B18*SUM('Escapement Age'!U18:W18)+C18*SUM('Escapement Age'!U18:V18) -> 12580.691 | L14: 1995 | M14: =B19*SUM('Escapement Age'!X19:Z19)+C19*SUM('Escapement Age'!X19:Y19) -> 28879.942 | N14: 1996 | O14: =B20*SUM('Escapement Age'!AA20:AC20)+'Run Reconstruction 2'!C20*SUM('Escapement Age'!AA20:AC20) -> 3058.6045 | P14: 1997 | Q14: =B21*SUM('Escapement Age'!AD21:AF21)+C21*SUM('Escapement Age'!AD21:AF21) -> 0 | R14: 1998 | S14: 0 | U14: =B14/1000 -> 73.180572 | V14: =E14/1000 -> 44.788023
A15: 1991 | B15: ='Summary Data'!C15 -> 45509.809 | C15: ='Summary Data'!H15 -> 3106 | D15: =SUM(B15:C15) -> 48615.809 | E15: =SUM(I15,K15,M15,O15,Q15,S15) -> 36169.986 | F15: =E15/B15 -> 0.7947734 | G15: =LN(F15) -> -0.22969824 | H15: 1994 | I15: =B18*SUM('Escapement Age'!S18:T18)+C18*'Escapement Age'!S18 -> 384.19488 | J15: 1995 | K15: =B19*SUM('Escapement Age'!U19:W19)+C19*SUM('Escapement Age'!U19:V19) -> 5419.2378 | L15: 1996 | M15: =B20*SUM('Escapement Age'!X20:Z20)+C20*SUM('Escapement Age'!X20:Y20) -> 14775.412 | N15: 1997 | O15: =B21*SUM('Escapement Age'!AA21:AC21)+'Run Reconstruction 2'!C21*SUM('Escapement Age'!AA21:AC21) -> 15148.317 | P15: 1998 | Q15: =Q55 -> 442.82388 | R15: 1999 | S15: =B23*SUM('Escapement Age'!AG23)+C23*SUM('Escapement Age'!AG23) -> 0 | U15: =B15/1000 -> 45.509809 | V15: =E15/1000 -> 36.169986
A16: 1992 | B16: ='Summary Data'!C16 -> 10325.817 | C16: ='Summary Data'!H16 -> 101 | D16: =SUM(B16:C16) -> 10426.817 | E16: =SUM(I16,K16,M16,O16,Q16,S16) -> 36360.9 | F16: =E16/B16 -> 3.5213583 | G16: =LN(F16) -> 1.2588468 | H16: 1995 | I16: =B19*SUM('Escapement Age'!S19:T19)+C19*'Escapement Age'!S19 -> 3173.9954 | J16: 1996 | K16: =B20*SUM('Escapement Age'!U20:W20)+C20*SUM('Escapement Age'!U20:V20) -> 6196.6404 | L16: 1997 | M16: =B21*SUM('Escapement Age'!X21:Z21)+C21*SUM('Escapement Age'!X21:Y21) -> 17217.03 | N16: 1998 | O16: =O56 -> 9773.2345 | P16: 1999 | Q16: =B23*SUM('Escapement Age'!AD23:AF23)+C23*SUM('Escapement Age'!AD23:AF23) -> 0 | R16: 2000 | S16: =B24*SUM('Escapement Age'!AG24)+C24*SUM('Escapement Age'!AG24) -> 0 | U16: =B16/1000 -> 10.325817 | V16: =E16/1000 -> 36.3609
A17: 1993 | B17: ='Summary Data'!C17 -> 25018.473 | C17: ='Summary Data'!H17 -> 3142 | D17: =SUM(B17:C17) -> 28160.473 | E17: =SUM(I17,K17,M17,O17,Q17,S17) -> 29846.499 | F17: =E17/B17 -> 1.1929784 | G17: =LN(F17) -> 0.17645307 | H17: 1996 | I17: =B20*SUM('Escapement Age'!S20:T20)+C20*'Escapement Age'!S20 -> 584.58164 | J17: 1997 | K17: =B21*SUM('Escapement Age'!U21:W21)+C21*SUM('Escapement Age'!U21:V21) -> 4583.2368 | L17: 1998 | M17: =M57 -> 14094.259 | N17: 1999 | O17: =B23*SUM('Escapement Age'!AA23:AC23)+'Run Reconstruction 2'!C23*SUM('Escapement Age'!AA23:AC23) -> 10584.422 | P17: 2000 | Q17: =B24*SUM('Escapement Age'!AD24:AF24)+C24*SUM('Escapement Age'!AD24:AF24) -> 0 | R17: 2001 | S17: =B25*SUM('Escapement Age'!AG25)+C25*SUM('Escapement Age'!AG25) -> 0 | U17: =B17/1000 -> 25.018473 | V17: =E17/1000 -> 29.846499
A18: 1994 | B18: ='Summary Data'!C18 -> 39710.383 | C18: ='Summary Data'!H18 -> 6168 | D18: =SUM(B18:C18) -> 45878.383 | E18: =SUM(I18,K18,M18,O18,Q18,S18) -> 78072.019 | F18: =E18/B18 -> 1.9660354 | G18: =LN(F18) -> 0.67601903 | H18: 1997 | I18: =B21*SUM('Escapement Age'!S21:T21)+C21*'Escapement Age'!S21 -> 821.33642 | J18: 1998 | K18: =K58 -> 18376.025 | L18: 1999 | M18: =B23*SUM('Escapement Age'!X23:Z23)+C23*SUM('Escapement Age'!X23:Y23) -> 58639.824 | N18: 2000 | O18: =B24*SUM('Escapement Age'!AA24:AC24)+'Run Reconstruction 2'!C24*SUM('Escapement Age'!AA24:AC24) -> 234.83308 | P18: 2001 | Q18: =B25*SUM('Escapement Age'!AD25:AF25)+C25*SUM('Escapement Age'!AD25:AF25) -> 0 | R18: 2002 | S18: =B26*SUM('Escapement Age'!AG26)+C26*SUM('Escapement Age'!AG26) -> 0 | U18: =B18/1000 -> 39.710383 | V18: =E18/1000 -> 78.072019
A19: 1995 | B19: ='Summary Data'!C19 -> 34797.618 | C19: ='Summary Data'!H19 -> 5502 | D19: =SUM(B19:C19) -> 40299.618 | E19: =SUM(I19,K19,M19,O19,Q19,S19) -> 3708.1257 | F19: =E19/B19 -> 0.10656263 | G19: =LN(F19) -> -2.2390224 | H19: 1998 | I19: =I59 -> 41.488164 | J19: 1999 | K19: =B23*SUM('Escapement Age'!U23:W23)+C23*SUM('Escapement Age'!U23:V23) -> 1063.761 | L19: 2000 | M19: =B24*SUM('Escapement Age'!X24:Z24)+C24*SUM('Escapement Age'!X24:Y24) -> 2465.7474 | N19: 2001 | O19: =B25*SUM('Escapement Age'!AA25:AC25)+'Run Reconstruction 2'!C25*SUM('Escapement Age'!AA25:AC25) -> 99.840673 | P19: 2002 | Q19: =B26*SUM('Escapement Age'!AD26:AF26)+C26*SUM('Escapement Age'!AD26:AF26) -> 37.288518 | R19: 2003 | S19: =B27*SUM('Escapement Age'!AG27)+C27*SUM('Escapement Age'!AG27) -> 0 | U19: =B19/1000 -> 34.797618 | V19: =E19/1000 -> 3.7081257
