Workbook
Name RED: #REF!
Name RS: #REF!

Sheet read me
A1: Welcome to the weir-based escapement estimate workbook for Redoubt Lake sockeye and coho salmon.
A3: Instructions for use inseason:
A4: 1) | B4: enter daily weir counts into the "Currentyear" worksheet
A5: 2) | B5: print the "prediction figure" worksheet
A6: 3)
A9: Instructions for prepping the workbook for a new year:
A10: 1)
A11: 2) | B11: make a new "past year" column in the "Sockeye w EM Fill-in" worksheet by:
B12: a) "copy" the latest year column, and
B13: b) insert "insert copied cells" this copied column over the copied column. This inserts a new column to the left. Then, in the right most column…
C14: i) put the current year in the column heading
C15: ii) delete the data and cell shading
C16: iii) copy the daily counts from the "Currentyear" worksheet, and
C17: iv) run the "fill missing counts" macro based on all prior data (and interpolations)
C18: v) enter the formula to sum the daily weir counts for the new year in row 124
B19: c) delete daily counts from "Currentyear" worksheet and enter the new year
B20: d) repeat steps a to b for the "Coho w EM Fill-ini" worksheet
A21: 3)

Sheet Currentyear
A1: Redoubt Lake Adult Salmon Escapement Data | J1: Year = | K1: 45818 | L1: <==just edit for current year (i.e., leave 6/10/yyyy)
A2: Enter data into blue shaded cells. | F2: Yellow shaded cells are calculated.
B4: last updated = | C4: =VLOOKUP(MAX(C7:C126),C7:N126,12) -> 45899
A5: Date | B5: Sockeye | D5: Coho | F5: Chinook | H5: Pink | J5: Chum | L5: Dolly Varden
A6: M/D | B6: Daily | C6: Cum. | D6: Daily | E6: Cum. | F6: Daily | G6: Cum. | H6: Daily | I6: Cum. | J6: Daily | K6: Cum. | L6: Daily | M6: Cum.
A7: =K1 -> 45818 | C7: =IF(B7="","",SUM(B$7:B7)) | E7: =IF(D7="","",SUM(D$7:D7)) | G7: =IF(F7="","",SUM(F$7:F7)) | I7: =IF(H7="","",SUM(H$7:H7)) | K7: =IF(J7="","",SUM(J$7:J7)) | M7: =IF(L7="","",SUM(L$7:L7)) | N7: =A7 -> 45818
A8: =A7+1 -> 45819 | C8: =IF(B8="","",SUM(B$7:B8)) | E8: =IF(D8="","",SUM(D$7:D8)) | G8: =IF(F8="","",SUM(F$7:F8)) | I8: =IF(H8="","",SUM(H$7:H8)) | K8: =IF(J8="","",SUM(J$7:J8)) | M8: =IF(L8="","",SUM(L$7:L8)) | N8: =A8 -> 45819
A9: =A8+1 -> 45820 | C9: =IF(B9="","",SUM(B$7:B9)) | E9: =IF(D9="","",SUM(D$7:D9)) | G9: =IF(F9="","",SUM(F$7:F9)) | I9: =IF(H9="","",SUM(H$7:H9)) | K9: =IF(J9="","",SUM(J$7:J9)) | M9: =IF(L9="","",SUM(L$7:L9)) | N9: =A9 -> 45820
A10: =A9+1 -> 45821 | C10: =IF(B10="","",SUM(B$7:B10)) | G10: =IF(F10="","",SUM(F$7:F10)) | I10: =IF(H10="","",SUM(H$7:H10)) | K10: =IF(J10="","",SUM(J$7:J10)) | M10: =IF(L10="","",SUM(L$7:L10)) | N10: =A10 -> 45821
A11: =A10+1 -> 45822 | B11: 1 | C11: =IF(B11="","",SUM(B$7:B11)) -> 1 | G11: =IF(F11="","",SUM(F$7:F11)) | I11: =IF(H11="","",SUM(H$7:H11)) | K11: =IF(J11="","",SUM(J$7:J11)) | M11: =IF(L11="","",SUM(L$7:L11)) | N11: =A11 -> 45822
A12: =A11+1 -> 45823 | B12: 7 | C12: =IF(B12="","",SUM(B$7:B12)) -> 8 | E12: =IF(D12="","",SUM(D$7:D12)) | G12: =IF(F12="","",SUM(F$7:F12)) | I12: =IF(H12="","",SUM(H$7:H12)) | K12: =IF(J12="","",SUM(J$7:J12)) | M12: =IF(L12="","",SUM(L$7:L12)) | N12: =A12 -> 45823
A13: =A12+1 -> 45824 | B13: 13 | C13: =IF(B13="","",SUM(B$7:B13)) -> 21 | E13: =IF(D13="","",SUM(D$7:D13)) | N13: =A13 -> 45824
A14: =A13+1 -> 45825 | B14: 7 | C14: =IF(B14="","",SUM(B$7:B14)) -> 28 | E14: =IF(D14="","",SUM(D$7:D14)) | N14: =A14 -> 45825
A15: =A14+1 -> 45826 | B15: 1 | C15: =IF(B15="","",SUM(B$7:B15)) -> 29 | E15: =IF(D15="","",SUM(D$7:D15)) | N15: =A15 -> 45826
A16: =A15+1 -> 45827 | B16: 8 | C16: =IF(B16="","",SUM(B$7:B16)) -> 37 | E16: =IF(D16="","",SUM(D$7:D16)) | N16: =A16 -> 45827
A17: =A16+1 -> 45828 | B17: 549 | C17: =IF(B17="","",SUM(B$7:B17)) -> 586 | E17: =IF(D17="","",SUM(D$7:D17)) | N17: =A17 -> 45828
A18: =A17+1 -> 45829 | B18: 2 | C18: =IF(B18="","",SUM(B$7:B18)) -> 588 | E18: =IF(D18="","",SUM(D$7:D18)) | N18: =A18 -> 45829
A19: =A18+1 -> 45830 | B19: 0 | C19: =IF(B19="","",SUM(B$7:B19)) -> 588 | E19: =IF(D19="","",SUM(D$7:D19)) | N19: =A19 -> 45830
A20: =A19+1 -> 45831 | B20: 626 | C20: =IF(B20="","",SUM(B$7:B20)) -> 1214 | E20: =IF(D20="","",SUM(D$7:D20)) | N20: =A20 -> 45831
A21: =A20+1 -> 45832 | B21: 517 | C21: =IF(B21="","",SUM(B$7:B21)) -> 1731 | E21: =IF(D21="","",SUM(D$7:D21)) | N21: =A21 -> 45832
A22: =A21+1 -> 45833 | B22: 724 | C22: =IF(B22="","",SUM(B$7:B22)) -> 2455 | E22: =IF(D22="","",SUM(D$7:D22)) | N22: =A22 -> 45833
A23: =A22+1 -> 45834 | B23: 872 | C23: =IF(B23="","",SUM(B$7:B23)) -> 3327 | E23: =IF(D23="","",SUM(D$7:D23)) | N23: =A23 -> 45834
A24: =A23+1 -> 45835 | B24: 312 | C24: =IF(B24="","",SUM(B$7:B24)) -> 3639 | E24: =IF(D24="","",SUM(D$7:D24)) | N24: =A24 -> 45835
... A88: =A87+1 -> 45899 | B88: 208 | C88: =IF(B88="","",SUM(B$7:B88)) -> 228571 | E88: =IF(D88="","",SUM(D$7:D88)) | N88: =A88 -> 45899
A89: =A88+1 -> 45900 | C89: =IF(B89="","",SUM(B$7:B89)) | E89: =IF(D89="","",SUM(D$7:D89)) | N89: =A89 -> 45900
A90: =A89+1 -> 45901 | C90: =IF(B90="","",SUM(B$7:B90)) | E90: =IF(D90="","",SUM(D$7:D90)) | N90: =A90 -> 45901
A91: =A90+1 -> 45902 | C91: =IF(B91="","",SUM(B$7:B91)) | E91: =IF(D91="","",SUM(D$7:D91)) | G91: =IF(F91="","",SUM(F$7:F91)) | I91: =IF(H91="","",SUM(H$7:H91)) | K91: =IF(J91="","",SUM(J$7:J91)) | M91: =IF(L91="","",SUM(L$7:L91)) | N91: =A91 -> 45902
A92: =A91+1 -> 45903 | C92: =IF(B92="","",SUM(B$7:B92)) | E92: =IF(D92="","",SUM(D$7:D92)) | G92: =IF(F92="","",SUM(F$7:F92)) | I92: =IF(H92="","",SUM(H$7:H92)) | K92: =IF(J92="","",SUM(J$7:J92)) | M92: =IF(L92="","",SUM(L$7:L92)) | N92: =A92 -> 45903
A93: =A92+1 -> 45904 | C93: =IF(B93="","",SUM(B$7:B93)) | E93: =IF(D93="","",SUM(D$7:D93)) | G93: =IF(F93="","",SUM(F$7:F93)) | I93: =IF(H93="","",SUM(H$7:H93)) | K93: =IF(J93="","",SUM(J$7:J93)) | M93: =IF(L93="","",SUM(L$7:L93)) | N93: =A93 -> 45904
A94: =A93+1 -> 45905 | C94: =IF(B94="","",SUM(B$7:B94)) | E94: =IF(D94="","",SUM(D$7:D94)) | G94: =IF(F94="","",SUM(F$7:F94)) | I94: =IF(H94="","",SUM(H$7:H94)) | K94: =IF(J94="","",SUM(J$7:J94)) | M94: =IF(L94="","",SUM(L$7:L94)) | N94: =A94 -> 45905
A95: =A94+1 -> 45906 | C95: =IF(B95="","",SUM(B$7:B95)) | E95: =IF(D95="","",SUM(D$7:D95)) | G95: =IF(F95="","",SUM(F$7:F95)) | I95: =IF(H95="","",SUM(H$7:H95)) | K95: =IF(J95="","",SUM(J$7:J95)) | M95: =IF(L95="","",SUM(L$7:L95)) | N95: =A95 -> 45906
A96: =A95+1 -> 45907 | C96: =IF(B96="","",SUM(B$7:B96)) | E96: =IF(D96="","",SUM(D$7:D96)) | G96: =IF(F96="","",SUM(F$7:F96)) | I96: =IF(H96="","",SUM(H$7:H96)) | K96: =IF(J96="","",SUM(J$7:J96)) | M96: =IF(L96="","",SUM(L$7:L96)) | N96: =A96 -> 45907
A97: =A96+1 -> 45908 | C97: =IF(B97="","",SUM(B$7:B97)) | E97: =IF(D97="","",SUM(D$7:D97)) | G97: =IF(F97="","",SUM(F$7:F97)) | I97: =IF(H97="","",IF(ISERROR(H97+I96),H97,H97+I96)) | K97: =IF(J97="","",IF(ISERROR(J97+K96),J97,J97+K96)) | M97: =IF(L97="","",SUM(L$7:L97)) | N97: =A97 -> 45908
A98: =A97+1 -> 45909 | C98: =IF(B98="","",SUM(B$7:B98)) | E98: =IF(D98="","",SUM(D$7:D98)) | G98: =IF(F98="","",SUM(F$7:F98)) | I98: =IF(H98="","",IF(ISERROR(H98+I97),H98,H98+I97)) | K98: =IF(J98="","",IF(ISERROR(J98+K97),J98,J98+K97)) | M98: =IF(L98="","",SUM(L$7:L98)) | N98: =A98 -> 45909
A99: =A98+1 -> 45910 | C99: =IF(B99="","",SUM(B$7:B99)) | E99: =IF(D99="","",SUM(D$7:D99)) | G99: =IF(F99="","",SUM(F$7:F99)) | I99: =IF(H99="","",IF(ISERROR(H99+I98),H99,H99+I98)) | K99: =IF(J99="","",IF(ISERROR(J99+K98),J99,J99+K98)) | M99: =IF(L99="","",SUM(L$7:L99)) | N99: =A99 -> 45910
A100: =A99+1 -> 45911 | C100: =IF(B100="","",SUM(B$7:B100)) | E100: =IF(D100="","",SUM(D$7:D100)) | G100: =IF(F100="","",SUM(F$7:F100)) | I100: =IF(H100="","",IF(ISERROR(H100+I99),H100,H100+I99)) | K100: =IF(J100="","",IF(ISERROR(J100+K99),J100,J100+K99)) | M100: =IF(L100="","",SUM(L$7:L100)) | N100: =A100 -> 45911
A101: =A100+1 -> 45912 | C101: =IF(B101="","",SUM(B$7:B101)) | E101: =IF(D101="","",SUM(D$7:D101)) | G101: =IF(F101="","",SUM(F$7:F101)) | I101: =IF(H101="","",IF(ISERROR(H101+I100),H101,H101+I100)) | K101: =IF(J101="","",IF(ISERROR(J101+K100),J101,J101+K100)) | M101: =IF(L101="","",SUM(L$7:L101)) | N101: =A101 -> 45912
A102: =A101+1 -> 45913 | C102: =IF(B102="","",SUM(B$7:B102)) | E102: =IF(D102="","",SUM(D$7:D102)) | G102: =IF(F102="","",SUM(F$7:F102)) | I102: =IF(H102="","",IF(ISERROR(H102+I101),H102,H102+I101)) | K102: =IF(J102="","",IF(ISERROR(J102+K101),J102,J102+K101)) | M102: =IF(L102="","",SUM(L$7:L102)) | N102: =A102 -> 45913
A103: =A102+1 -> 45914 | C103: =IF(B103="","",SUM(B$7:B103)) | E103: =IF(D103="","",SUM(D$7:D103)) | G103: =IF(F103="","",SUM(F$7:F103)) | I103: =IF(H103="","",IF(ISERROR(H103+I102),H103,H103+I102)) | K103: =IF(J103="","",IF(ISERROR(J103+K102),J103,J103+K102)) | M103: =IF(L103="","",SUM(L$7:L103)) | N103: =A103 -> 45914
A104: =A103+1 -> 45915 | C104: =IF(B104="","",SUM(B$7:B104)) | E104: =IF(D104="","",SUM(D$7:D104)) | G104: =IF(F104="","",SUM(F$7:F104)) | I104: =IF(H104="","",IF(ISERROR(H104+I103),H104,H104+I103)) | K104: =IF(J104="","",IF(ISERROR(J104+K103),J104,J104+K103)) | M104: =IF(L104="","",SUM(L$7:L104)) | N104: =A104 -> 45915
...

Sheet Sockeye w EM Fill-in
A1: ="Table 1. Daily weir counts and escapement estimates for Redoubt Lake sockeye salmon, 1953 through "&MAX(B3:AU3)&"." -> Table 1. Daily weir counts and escapement estimates for Redoubt Lake sockeye salmon, 1953 through 2025.
BF2: ="Data for Charting "&MAX(B3:AN3)+1&" esc. prediction" -> Data for Charting 2019 esc. prediction | BI2: Upper | BJ2: Lower | BL2: 5-Year Running Averages:
A3: Date | B3: 1953 | C3: 1954 | D3: 1955 | E3: 1982 | F3: 1983 | G3: 1984 | H3: 1985 | I3: 1986 | J3: 1987 | K3: 1988 | L3: 1989 | M3: 1990 | N3: 1991 | O3: 1992 | P3: 1993 | Q3: 1994 | R3: 1995 | S3: 1996 | T3: 1997 | U3: 1999 | V3: 2000 | W3: 2001 | X3: 2002 | Y3: 2003 | Z3: 2004 | AA3: 2005 | AB3: 2006 | AC3: 2007 | AD3: 2008 | AE3: 2009 | AF3: 2010 | AG3: 2011 | AH3: 2012 | AI3: 2013 | AJ3: 2014 | AK3: 2015 | AL3: 2016 | AM3: 2017 | AN3: 2018 | AO3: 2019 | AP3: 2020 | AQ3: 2021 | AR3: 2022 | AS3: 2023 | AT3: 2024 | AU3: 2025 | AY3: Years w/ Weir Counts 1953-1999 | AZ3: Percent w/ Counts 1953-1999 | BA3: ="Avg. 1953-"&MAX(B3:AT3) -> Avg. 1953-2024 | BB3: ="Min. 1953-"&MAX(B3:AT3) -> Min. 1953-2024 | BC3: ="Max. 1953-"&MAX(B3:AT3) -> Max. 1953-2024 | BD3: Average Daily % of Run | BE3: Average Cum. % of Run | BF3: =A3 -> Date | BG3: ="Ave. Cum. Escapement (1953-1955 and 1982-"&MAX(B3:AT3)&")" -> Ave. Cum. Escapement (1953-1955 and 1982-2024) | BH3: ="Cumulative "&MAX(B3:AT3)+1&" Escapement = ("&ROUND(MAX(BH4:BH123),0)&")" -> Cumulative 2025 Escapement = (228571) | BI3: (w/ Mean Absolute % Error) | BK3: ="Esc. Prediction for "&MAX(B3:AT3)+1&" = ("&FIXED(VLOOKUP(Currentyear!C4,'Sockeye w EM Fill-in'!BF4:BK123,6),0)&")" -> Esc. Prediction for 2025 = (234,489) | BL3: Rho | BM3: P-value | BN3: N | BO3: Relative Change in Predictions for Current Year | BP3: Relative Error in Prediction Model
A4: =Currentyear!K1 -> 45818 | B4: 0 | C4: 0 | D4: 0 | E4: 0 | F4: 0 | G4: 0 | H4: 0 | I4: 0 | J4: 0 | K4: 0 | L4: 0 | M4: 0 | N4: 0 | O4: 0 | P4: 0 | Q4: 0 | R4: 0 | S4: 0 | T4: 0 | U4: 0 | V4: 0 | W4: 0 | X4: 3 | Y4: 2 | Z4: 6 | AA4: 0 | AB4: 1.571118 | AC4: 1.0116903 | AD4: 0 | AE4: 0.18996116 | AF4: 0.25646273 | AG4: 0.33962965 | AH4: 0.61205624 | AI4: 0.73434235 | AJ4: 0.29801843 | AK4: 0.22451598 | AL4: 0.34077095 | AM4: 0.83346801 | AN4: 1.1044092 | AO4: 0.89886672 | AP4: 0.62244181 | AQ4: 0.91682936 | AR4: 1.346739 | AS4: 2.371034 | AT4: 3.3387604 | AY4: 1 | AZ4: 0.05 | BA4: =AVERAGE(B4:AS4) -> 0.56073532 | BB4: =MIN(B4:AS4) -> 0 | BC4: =MAX(B4:AS4) -> 6 | BD4: =SUM(B4:AS4)/SUM($B$4:$AS$123) -> 1.496294e-05 | BE4: =BD4 -> 1.496294e-05 | BF4: =A4 -> 45818 | BG4: =BA4 -> 0.56073532 | BH4: =Currentyear!C7 | BI4: =IF(ISERR(BJ4/BC4),"",($BH4/$BE4)*(1+$BC264)) | BJ4: =IF(ISERR(BK4/BD4),"",($BH4/$BE4)*(1-$BC264)) | BK4: =IF(ISERR(BH4/BE4),"",$BH4/$BE4)
A5: =A4+1 -> 45819 | B5: 0 | C5: 0 | D5: 0 | E5: 0 | F5: 0 | G5: 0 | H5: 0 | I5: 0 | J5: 0 | K5: 0 | L5: 0 | M5: 0 | N5: 0 | O5: 0 | P5: 0 | Q5: 0 | R5: 0 | S5: 0 | T5: 0 | U5: 0 | V5: 0 | W5: 0 | X5: 2 | Y5: 0 | Z5: 29 | AA5: 0 | AB5: 4.4276961 | AC5: 2.8511272 | AD5: 0 | AE5: 0.5353451 | AF5: 0.72275859 | AG5: 0.9571381 | AH5: 1.7248858 | AI5: 2.0695103 | AJ5: 0.83987013 | AK5: 0.63272685 | AL5: 0.9603545 | AM5: 2.3488644 | AN5: 3.112426 | AO5: 2.5331698 | AP5: 1.7541542 | AQ5: 2.5837918 | AR5: 3.7953555 | AS5: 6.6820049 | AT5: 9.4092339 | AY5: 1 | AZ5: 0.05 | BA5: =AVERAGE(B5:AS5) -> 1.5802541 | BB5: =MIN(B5:AS5) -> 0 | BC5: =MAX(B5:AS5) -> 29 | BD5: =SUM(B5:AS5)/SUM($B$4:$AS$123) -> 4.2168285e-05 | BE5: =BD5+BE4 -> 5.7131225e-05 | BF5: =A5 -> 45819 | BG5: =BA5+BG4 -> 2.1409894 | BH5: =Currentyear!C8 | BI5: =IF(ISERR(BJ5/BC5),"",($BH5/$BE5)*(1+$BC265)) | BJ5: =IF(ISERR(BK5/BD5),"",($BH5/$BE5)*(1-$BC265)) | BK5: =IF(ISERR(BH5/BE5),"",$BH5/$BE5)
A6: =A5+1 -> 45820 | B6: 0 | C6: 0 | D6: 0 | E6: 0 | F6: 0 | G6: 0 | H6: 0 | I6: 0 | J6: 0 | K6: 0 | L6: 0 | M6: 0 | N6: 0 | O6: 0 | P6: 0 | Q6: 0 | R6: 0 | S6: 0 | T6: 0 | U6: 0 | V6: 0 | W6: 0 | X6: 1 | Y6: 2 | Z6: 18 | AA6: 0 | AB6: 2.999407 | AC6: 1.9314088 | AD6: 0 | AE6: 0.36265313 | AF6: 0.48961066 | AG6: 0.64838387 | AH6: 1.168471 | AI6: 1.4019263 | AJ6: 0.56894428 | AK6: 0.42862141 | AL6: 0.65056273 | AM6: 1.5911662 | AN6: 2.1084176 | AO6: 1.7160183 | AP6: 1.188298 | AQ6: 1.7503106 | AR6: 2.5710473 | AS6: 4.5265194 | AT6: 6.3739971 | AY6: 2 | AZ6: 0.1 | BA6: =AVERAGE(B6:AS6) -> 1.0704947 | BB6: =MIN(B6:AS6) -> 0 | BC6: =MAX(B6:AS6) -> 18 | BD6: =SUM(B6:AS6)/SUM($B$4:$AS$123) -> 2.8565613e-05 | BE6: =BD6+BE5 -> 8.5696838e-05 | BF6: =A6 -> 45820 | BG6: =BA6+BG5 -> 3.2114841 | BH6: =Currentyear!C9 | BI6: =IF(ISERR(BJ6/BC6),"",($BH6/$BE6)*(1+$BC266)) | BJ6: =IF(ISERR(BK6/BD6),"",($BH6/$BE6)*(1-$BC266)) | BK6: =IF(ISERR(BH6/BE6),"",$BH6/$BE6)
A7: =A6+1 -> 45821 | B7: 2.4607931 | C7: 2.0783826 | D7: 2.4812371 | E7: 0.048876057 | F7: 0.27232026 | G7: 1.2415643 | H7: 1.178513 | I7: 1.050577 | J7: 1.5280556 | K7: 0.34868843 | L7: 3.3850417 | M7: 7.8465492 | N7: 4.8796415 | O7: 1.1071522 | P7: 0 | Q7: 0 | R7: 3.7310617 | S7: 9 | T7: 3.0985378 | U7: 6.1924392 | V7: 1 | W7: 11 | X7: 4 | Y7: 3 | Z7: 29 | AA7: 0 | AB7: 14.272811 | AC7: 9.1906942 | AD7: 1 | AE7: 1.725701 | AF7: 2.348455 | AG7: 3.1100229 | AH7: 5.6046607 | AI7: 6.7244469 | AJ7: 2.7289848 | AK7: 2.0559154 | AL7: 1 | AM7: 7.5255462 | AN7: 9.9719275 | AO7: 26 | AP7: 6.1934968 | AQ7: 3 | AR7: 13.006983 | AS7: 0 | AT7: 29.147301 | AY7: 3 | AZ7: 0.15 | BA7: =AVERAGE(B7:AS7) -> 4.8952063 | BB7: =MIN(B7:AS7) -> 0 | BC7: =MAX(B7:AS7) -> 29 | BD7: =SUM(B7:AS7)/SUM($B$4:$AS$123) -> 0.00013062612 | BE7: =BD7+BE6 -> 0.00021632296 | BF7: =A7 -> 45821 | BG7: =BA7+BG6 -> 8.1066904 | BH7: =Currentyear!C10 | BI7: =IF(ISERR(BJ7/BC7),"",($BH7/$BE7)*(1+$BC267)) | BJ7: =IF(ISERR(BK7/BD7),"",($BH7/$BE7)*(1-$BC267)) | BK7: =IF(ISERR(BH7/BE7),"",$BH7/$BE7)
A8: =A7+1 -> 45822 | B8: 1.7396143 | C8: 1.469276 | D8: 1.7540669 | E8: 0.034552068 | F8: 0.19251201 | G8: 0.87770205 | H8: 0.83312905 | I8: 0.74268693 | J8: 1.080232 | K8: 0.24649915 | L8: 2.3929956 | M8: 5.5469799 | N8: 3.4495767 | O8: 0.78268173 | P8: 0 | Q8: 0 | R8: 6 | S8: 3 | T8: 2.1904568 | U8: 4.3776359 | V8: 0 | W8: 6 | X8: 24 | Y8: 3 | Z8: 24 | AA8: 5 | AB8: 14.098727 | AC8: 9.0785958 | AD8: 0 | AE8: 1.7046527 | AF8: 2.3014172 | AG8: 3.0477314 | AH8: 5.4924034 | AI8: 41 | AJ8: 3.3268684 | AK8: 2.5063386 | AL8: 3 | AM8: 9.2638247 | AN8: 12.27528 | AO8: 7 | AP8: 1 | AQ8: 4 | AR8: 13.998296 | AS8: 0 | AT8: 31.368732 | AU8: 1 | AY8: 4 | AZ8: 0.2 | BA8: =AVERAGE(B8:AS8) -> 5.2682894 | BB8: =MIN(B8:AS8) -> 0 | BC8: =MAX(B8:AS8) -> 41 | BD8: =SUM(B8:AS8)/SUM($B$4:$AS$123) -> 0.00014058165 | BE8: =BD8+BE7 -> 0.00035690461 | BF8: =A8 -> 45822 | BG8: =BA8+BG7 -> 13.37498 | BH8: =Currentyear!C11 -> 1 | BI8: =IF(ISERR(BJ8/BC8),"",($BH8/$BE8)*(1+$BC268)) -> 5256.0621 | BJ8: =IF(ISERR(BK8/BD8),"",($BH8/$BE8)*(1-$BC268)) -> 347.67613 | BK8: =IF(ISERR(BH8/BE8),"",$BH8/$BE8) -> 2801.8691
A9: =A8+1 -> 45823 | B9: 2.3194858 | C9: 1.9590347 | D9: 2.3387559 | E9: 0.046069425 | F9: 0.25668268 | G9: 1.1702694 | H9: 1.1108387 | I9: 0.99024924 | J9: 1.4403094 | K9: 0.32866553 | L9: 3.1906608 | M9: 7.3959732 | N9: 4.5994356 | O9: 1.0435756 | P9: 0 | Q9: 6 | R9: 2 | S9: 4 | T9: 2.920609 | U9: 5.8368479 | V9: 2 | W9: 3 | X9: 21 | Y9: 2 | Z9: 22 | AA9: 0 | AB9: 14.132558 | AC9: 9.1003808 | AD9: 7 | AE9: 1.7087432 | AF9: 2.4372866 | AG9: 3.2276612 | AH9: 5.8166601 | AI9: 33 | AJ9: 3.3256666 | AK9: 0 | AL9: 3 | AM9: 9.1345751 | AN9: 12.104014 | AO9: 57 | AP9: 1 | AQ9: 1 | AR9: 1 | AS9: 12 | AT9: 7 | AU9: 7 | AY9: 4 | AZ9: 0.2 | BA9: =AVERAGE(B9:AS9) -> 6.2485229 | BB9: =MIN(B9:AS9) -> 0 | BC9: =MAX(B9:AS9) -> 57 | BD9: =SUM(B9:AS9)/SUM($B$4:$AS$123) -> 0.00016673869 | BE9: =BD9+BE8 -> 0.0005236433 | BF9: =A9 -> 45823 | BG9: =BA9+BG8 -> 19.623503 | BH9: =Currentyear!C12 -> 8 | BI9: =IF(ISERR(BJ9/BC9),"",($BH9/$BE9)*(1+$BC269)) -> 25974.872 | BJ9: =IF(ISERR(BK9/BD9),"",($BH9/$BE9)*(1-$BC269)) -> 4580.2782 | BK9: =IF(ISERR(BH9/BE9),"",$BH9/$BE9) -> 15277.575
A10: =A9+1 -> 45824 | B10: 0 | C10: 8.8016618 | D10: 10.507695 | E10: 0.20698332 | F10: 1.1532385 | G10: 5.2578525 | H10: 4.9908391 | I10: 4.4490478 | J10: 6.4711035 | K10: 1.4766471 | L10: 14.335181 | M10: 33.229047 | N10: 1 | O10: 4.6886357 | P10: 14 | Q10: 19 | R10: 51 | S10: 0 | T10: 13.121877 | U10: 26.22412 | V10: 0 | W10: 5 | X10: 60 | Y10: 11 | Z10: 43 | AA10: 0 | AB10: 48.406705 | AC10: 31.17054 | AD10: 12 | AE10: 5.8527713 | AF10: 8.1251602 | AG10: 10.760025 | AH10: 19.390947 | AI10: 220 | AJ10: 19 | AK10: 0 | AL10: 9 | AM10: 36.32888 | AN10: 2 | AO10: 74 | AP10: 0 | AQ10: 22 | AR10: 2 | AS10: 100 | AT10: 0 | AU10: 13 | AY10: 6 | AZ10: 0.3 | BA10: =AVERAGE(B10:AS10) -> 21.794294 | BB10: =MIN(B10:AS10) -> 0 | BC10: =MAX(B10:AS10) -> 220 | BD10: =SUM(B10:AS10)/SUM($B$4:$AS$123) -> 0.00058156979 | BE10: =BD10+BE9 -> 0.0011052131 | BF10: =A10 -> 45824 | BG10: =BA10+BG9 -> 41.417797 | BH10: =Currentyear!C13 -> 21 | BI10: =IF(ISERR(BJ10/BC10),"",($BH10/$BE10)*(1+$BC270)) -> 27225.636 | BJ10: =IF(ISERR(BK10/BD10),"",($BH10/$BE10)*(1-$BC270)) -> 10776.085 | BK10: =IF(ISERR(BH10/BE10),"",$BH10/$BE10) -> 19000.861
A11: =A10+1 -> 45825 | B11: 0 | C11: 5.3305552 | D11: 6.3637808 | E11: 0.12535542 | F11: 0.69843644 | G11: 3.184316 | H11: 3.0226046 | I11: 2.6944792 | J11: 3.9190979 | K11: 0.89430257 | L11: 4 | M11: 20.124525 | N11: 0 | O11: 0 | P11: 0 | Q11: 20 | R11: 27 | S11: 12 | T11: 7.9470096 | U11: 15.882128 | V11: 4 | W11: 10 | X11: 76 | Y11: 0 | Z11: 23 | AA11: 3 | AB11: 35.591048 | AC11: 86 | AD11: 5 | AE11: 0 | AF11: 6.9973551 | AG11: 0 | AH11: 0 | AI11: 276 | AJ11: 4 | AK11: 1 | AL11: 8 | AM11: 3 | AN11: 42 | AO11: 88 | AP11: 0 | AQ11: 11 | AR11: 0 | AS11: 160 | AT11: 3 | AU11: 7 | AY11: 8 | AZ11: 0.4 | BA11: =AVERAGE(B11:AS11) -> 22.176704 | BB11: =MIN(B11:AS11) -> 0 | BC11: =MAX(B11:AS11) -> 276 | BD11: =SUM(B11:AS11)/SUM($B$4:$AS$123) -> 0.00059177421 | BE11: =BD11+BE10 -> 0.0016969873 | BF11: =A11 -> 45825 | BG11: =BA11+BG10 -> 63.594502 | BH11: =Currentyear!C14 -> 28 | BI11: =IF(ISERR(BJ11/BC11),"",($BH11/$BE11)*(1+$BC271)) -> 26397.764 | BJ11: =IF(ISERR(BK11/BD11),"",($BH11/$BE11)*(1-$BC271)) -> 6601.8939 | BK11: =IF(ISERR(BH11/BE11),"",$BH11/$BE11) -> 16499.829 | BL11: {=[1]!daniels(BK7:BK11,1)} -> #NAME? | BM11: #NAME? | BN11: #NAME? | BO11: =(BK11-AVERAGE(BK7:BK11))/AVERAGE(BK7:BK11) -> 0.23178705 | BP11: =(BI11-BK11)/BK11 -> 0.59988107
A12: =A11+1 -> 45826 | B12: 0 | C12: 9.0534826 | D12: 10.808326 | E12: 0.21290523 | F12: 1.1862333 | G12: 5.4082828 | H12: 5.13363 | I12: 4.5763377 | J12: 6.6562456 | K12: 1.5188948 | L12: 23 | M12: 34.179749 | N12: 0 | O12: 0 | P12: 3 | Q12: 32 | R12: 41 | S12: 8 | T12: 13.497302 | U12: 26.974408 | V12: 1 | W12: 0 | X12: 39 | Y12: 1 | Z12: 53 | AA12: 119 | AB12: 62.731283 | AC12: 220 | AD12: 0 | AE12: 0 | AF12: 13.44319 | AG12: 0 | AH12: 0 | AI12: 341 | AJ12: 241 | AK12: 1 | AL12: 4 | AM12: 1 | AN12: 2 | AO12: 31 | AP12: 12 | AQ12: 77 | AR12: 1 | AS12: 351 | AT12: 325 | AU12: 1 | AY12: 8 | AZ12: 0.4 | BA12: =AVERAGE(B12:AS12) -> 40.849552 | BB12: =MIN(B12:AS12) -> 0 | BC12: =MAX(B12:AS12) -> 351 | BD12: =SUM(B12:AS12)/SUM($B$4:$AS$123) -> 0.0010900497 | BE12: =BD12+BE11 -> 0.002787037 | BF12: =A12 -> 45826 | BG12: =BA12+BG11 -> 104.44405 | BH12: =Currentyear!C15 -> 29 | BI12: =IF(ISERR(BJ12/BC12),"",($BH12/$BE12)*(1+$BC272)) -> 16702.771 | BJ12: =IF(ISERR(BK12/BD12),"",($BH12/$BE12)*(1-$BC272)) -> 4107.8597 | BK12: =IF(ISERR(BH12/BE12),"",$BH12/$BE12) -> 10405.316 | BL12: {=[1]!daniels(BK8:BK12,1)} -> #NAME? | BM12: #NAME? | BN12: #NAME? | BO12: =(BK12-AVERAGE(BK8:BK12))/AVERAGE(BK8:BK12) -> -0.18689986 | BP12: =(BI12-BK12)/BK12 -> 0.60521527
A13: =A12+1 -> 45827 | B13: 0 | C13: 12.246894 | D13: 14.620719 | E13: 0.28800274 | F13: 1.6046503 | G13: 7.3159322 | H13: 6.9444018 | I13: 6.1905373 | J13: 9.0040856 | K13: 2.0546506 | L13: 25 | M13: 46.235883 | N13: 0 | O13: 1 | P13: 0 | Q13: 70 | R13: 34 | S13: 14 | T13: 19 | U13: 36.48902 | V13: 0 | W13: 6 | X13: 17 | Y13: 0 | Z13: 61 | AA13: 8 | AB13: 56.845158 | AC13: 447 | AD13: 11 | AE13: 9 | AF13: 0 | AG13: 12 | AH13: 0 | AI13: 397 | AJ13: 42 | AK13: 0 | AL13: 12 | AM13: 48 | AN13: 2 | AO13: 26 | AP13: 11 | AQ13: 60 | AR13: 52 | AS13: 20 | AT13: 1419 | AU13: 8 | AY13: 9 | AZ13: 0.45 | BA13: =AVERAGE(B13:AS13) -> 36.450908 | BB13: =MIN(B13:AS13) -> 0 | BC13: =MAX(B13:AS13) -> 447 | BD13: =SUM(B13:AS13)/SUM($B$4:$AS$123) -> 0.00097267414 | BE13: =BD13+BE12 -> 0.0037597112 | BF13: =A13 -> 45827 | BG13: =BA13+BG12 -> 140.89496 | BH13: =Currentyear!C16 -> 37 | BI13: =IF(ISERR(BJ13/BC13),"",($BH13/$BE13)*(1+$BC273)) -> 16038.11 | BJ13: =IF(ISERR(BK13/BD13),"",($BH13/$BE13)*(1-$BC273)) -> 3644.253 | BK13: =IF(ISERR(BH13/BE13),"",$BH13/$BE13) -> 9841.1814 | BL13: {=[1]!daniels(BK9:BK13,1)} -> #NAME? | BM13: #NAME? | BN13: #NAME? | BO13: =(BK13-AVERAGE(BK9:BK13))/AVERAGE(BK9:BK13) -> -0.30720067 | BP13: =(BI13-BK13)/BK13 -> 0.62969355
A14: =A13+1 -> 45828 | B14: 7 | C14: 11 | D14: 19.886881 | E14: 0.39173698 | F14: 2.1826211 | G14: 9.9510208 | H14: 9.4456707 | I14: 8.4202755 | J14: 12.247222 | K14: 2.7947049 | L14: 11 | M14: 62.889351 | N14: 1 | O14: 0 | P14: 39 | Q14: 47 | R14: 68 | S14: 18 | T14: 78 | U14: 8 | V14: 1 | W14: 10 | X14: 20 | Y14: 1 | Z14: 136 | AA14: 49 | AB14: 90.440617 | AC14: 97 | AD14: 4 | AE14: 7 | AF14: 0 | AG14: 0 | AH14: 0 | AI14: 93 | AJ14: 66 | AK14: 0 | AL14: 2 | AM14: 52 | AN14: 0 | AO14: 31 | AP14: 0 | AQ14: 96 | AR14: 0 | AS14: 108 | AT14: 37 | AU14: 549 | AY14: 11 | AZ14: 0.55 | BA14: =AVERAGE(B14:AS14) -> 29.082957 | BB14: =MIN(B14:AS14) -> 0 | BC14: =MAX(B14:AS14) -> 136 | BD14: =SUM(B14:AS14)/SUM($B$4:$AS$123) -> 0.00077606408 | BE14: =BD14+BE13 -> 0.0045357753 | BF14: =A14 -> 45828 | BG14: =BA14+BG13 -> 169.97792 | BH14: =Currentyear!C17 -> 586 | BI14: =IF(ISERR(BJ14/BC14),"",($BH14/$BE14)*(1+$BC274)) -> 213754.06 | BJ14: =IF(ISERR(BK14/BD14),"",($BH14/$BE14)*(1-$BC274)) -> 44636.163 | BK14: =IF(ISERR(BH14/BE14),"",$BH14/$BE14) -> 129195.11 | BL14: {=[1]!daniels(BK10:BK14,1)} -> #NAME? | BM14: #NAME? | BN14: #NAME? | BO14: =(BK14-AVERAGE(BK10:BK14))/AVERAGE(BK10:BK14) -> 2.4928492 | BP14: =(BI14-BK14)/BK14 -> 0.6545058
A15: =A14+1 -> 45829 | B15: 33 | C15: 12 | D15: 15 | E15: 0.52134985 | F15: 2.9047786 | G15: 0 | H15: 12.570932 | I15: 11.206267 | J15: 16.299424 | K15: 3.7193807 | L15: 11 | M15: 83.697367 | N15: 0 | O15: 0 | P15: 35 | Q15: 54 | R15: 134 | S15: 21 | T15: 32 | U15: 76 | V15: 3 | W15: 9 | X15: 36 | Y15: 0 | Z15: 36 | AA15: 58 | AB15: 99.39742 | AC15: 61 | AD15: 7 | AE15: 0 | AF15: 0 | AG15: 0 | AH15: 2 | AI15: 667 | AJ15: 349 | AK15: 1 | AL15: 6 | AM15: 170 | AN15: 0 | AO15: 30 | AP15: 0 | AQ15: 104 | AR15: 33 | AS15: 29 | AT15: 1067 | AU15: 2 | AY15: 13 | AZ15: 0.65 | BA15: =AVERAGE(B15:AS15) -> 51.234475 | BB15: =MIN(B15:AS15) -> 0 | BC15: =MAX(B15:AS15) -> 667 | BD15: =SUM(B15:AS15)/SUM($B$4:$AS$123) -> 0.0013671662 | BE15: =BD15+BE14 -> 0.0059029415 | BF15: =A15 -> 45829 | BG15: =BA15+BG14 -> 221.21239 | BH15: =Currentyear!C18 -> 588 | BI15: =IF(ISERR(BJ15/BC15),"",($BH15/$BE15)*(1+$BC275)) -> 156024.48 | BJ15: =IF(ISERR(BK15/BD15),"",($BH15/$BE15)*(1-$BC275)) -> 43198.234 | BK15: =IF(ISERR(BH15/BE15),"",$BH15/$BE15) -> 99611.355 | BL15: {=[1]!daniels(BK11:BK15,1)} -> #NAME? | BM15: #NAME? | BN15: #NAME? | BO15: =(BK15-AVERAGE(BK11:BK15))/AVERAGE(BK11:BK15) -> 0.87554711 | BP15: =(BI15-BK15)/BK15 -> 0.56633223
A16: =A15+1 -> 45830 | B16: 11 | C16: 4 | D16: 40 | E16: 0.73850855 | F16: 4.1147108 | G16: 0 | H16: 1 | I16: 15.874032 | J16: 23.08865 | K16: 5.2686204 | L16: 11 | M16: 118.55997 | N16: 0 | O16: 0 | P16: 10 | Q16: 277 | R16: 67 | S16: 10 | T16: 51 | U16: 135 | V16: 1 | W16: 4 | X16: 23 | Y16: 0 | Z16: 33 | AA16: 47 | AB16: 246 | AC16: 63 | AD16: 1 | AE16: 12 | AF16: 18 | AG16: 0 | AH16: 120 | AI16: 535 | AJ16: 155 | AK16: 2 | AL16: 1 | AM16: 334 | AN16: 6 | AO16: 10 | AP16: 1 | AQ16: 118 | AR16: 3 | AS16: 765 | AT16: 1527 | AU16: 0 | AY16: 14 | AZ16: 0.7 | BA16: =AVERAGE(B16:AS16) -> 74.605557 | BB16: =MIN(B16:AS16) -> 0 | BC16: =MAX(B16:AS16) -> 765 | BD16: =SUM(B16:AS16)/SUM($B$4:$AS$123) -> 0.0019908118 | BE16: =BD16+BE15 -> 0.0078937533 | BF16: =A16 -> 45830 | BG16: =BA16+BG15 -> 295.81795 | BH16: =Currentyear!C19 -> 588 | BI16: =IF(ISERR(BJ16/BC16),"",($BH16/$BE16)*(1+$BC276)) -> 114352.91 | BJ16: =IF(ISERR(BK16/BD16),"",($BH16/$BE16)*(1-$BC276)) -> 34625.65 | BK16: =IF(ISERR(BH16/BE16),"",$BH16/$BE16) -> 74489.28 | BL16: {=[1]!daniels(BK12:BK16,1)} -> #NAME? | BM16: #NAME? | BN16: #NAME? | BO16: =(BK16-AVERAGE(BK12:BK16))/AVERAGE(BK12:BK16) -> 0.15115231 | BP16: =(BI16-BK16)/BK16 -> 0.53515929
A17: =A16+1 -> 45831 | B17: 93 | C17: 3 | D17: 40 | E17: 8 | F17: 13 | G17: 0 | H17: 0 | I17: 26.216205 | J17: 38.131254 | K17: 8.7012062 | L17: 18 | M17: 195.80358 | N17: 0 | O17: 3 | P17: 7 | Q17: 30 | R17: 125 | S17: 7 | T17: 156 | U17: 524 | V17: 8 | W17: 10 | X17: 74 | Y17: 2 | Z17: 103 | AA17: 71 | AB17: 160 | AC17: 44 | AD17: 13 | AE17: 52 | AF17: 0 | AG17: 0 | AH17: 65 | AI17: 92 | AJ17: 143 | AK17: 3 | AL17: 81 | AM17: 108 | AN17: 358 | AO17: 6 | AP17: 1 | AQ17: 304 | AR17: 3 | AS17: 2060 | AT17: 45 | AU17: 626 | AY17: 16 | AZ17: 0.8 | BA17: =AVERAGE(B17:AS17) -> 114.92846 | BB17: =MIN(B17:AS17) -> 0 | BC17: =MAX(B17:AS17) -> 2060 | BD17: =SUM(B17:AS17)/SUM($B$4:$AS$123) -> 0.0030668082 | BE17: =BD17+BE16 -> 0.010960561 | BF17: =A17 -> 45831 | BG17: =BA17+BG16 -> 410.74641 | BH17: =Currentyear!C20 -> 1214 | BI17: =IF(ISERR(BJ17/BC17),"",($BH17/$BE17)*(1+$BC277)) -> 177146.2 | BJ17: =IF(ISERR(BK17/BD17),"",($BH17/$BE17)*(1-$BC277)) -> 44375.303 | BK17: =IF(ISERR(BH17/BE17),"",$BH17/$BE17) -> 110760.75 | BL17: {=[1]!daniels(BK13:BK17,1)} -> #NAME? | BM17: #NAME? | BN17: #NAME? | BO17: =(BK17-AVERAGE(BK13:BK17))/AVERAGE(BK13:BK17) -> 0.30645619 | BP17: =(BI17-BK17)/BK17 -> 0.59935895
A18: =A17+1 -> 45832 | B18: 38 | C18: 3 | D18: 67 | E18: 1 | F18: 11 | G18: 1 | H18: 0 | I18: 27.506781 | J18: 40.008387 | K18: 9.129551 | L18: 24 | M18: 28 | N18: 0 | O18: 3 | P18: 285 | Q18: 105 | R18: 149 | S18: 2 | T18: 155 | U18: 411 | V18: 16 | W18: 31 | X18: 54 | Y18: 7 | Z18: 561 | AA18: 89 | AB18: 143 | AC18: 15 | AD18: 2 | AE18: 14 | AF18: 4 | AG18: 0 | AH18: 66 | AI18: 311 | AJ18: 50 | AK18: 0 | AL18: 260 | AM18: 1055 | AN18: 535 | AO18: 12 | AP18: 3 | AQ18: 35 | AR18: 14 | AS18: 48 | AT18: 75 | AU18: 517 | AY18: 17 | AZ18: 0.85 | BA18: =AVERAGE(B18:AS18) -> 106.4692 | BB18: =MIN(B18:AS18) -> 0 | BC18: =MAX(B18:AS18) -> 1055 | BD18: =SUM(B18:AS18)/SUM($B$4:$AS$123) -> 0.002841077 | BE18: =BD18+BE17 -> 0.013801638 | BF18: =A18 -> 45832 | BG18: =BA18+BG17 -> 517.21561 | BH18: =Currentyear!C21 -> 1731 | BI18: =IF(ISERR(BJ18/BC18),"",($BH18/$BE18)*(1+$BC278)) -> 202383.93 | BJ18: =IF(ISERR(BK18/BD18),"",($BH18/$BE18)*(1-$BC278)) -> 48455.854 | BK18: =IF(ISERR(BH18/BE18),"",$BH18/$BE18) -> 125419.89 | BL18: {=[1]!daniels(BK14:BK18,1)} -> #NAME? | BM18: #NAME? | BN18: #NAME? | BO18: =(BK18-AVERAGE(BK14:BK18))/AVERAGE(BK14:BK18) -> 0.16242243 | BP18: =(BI18-BK18)/BK18 -> 0.61365097
A19: =A18+1 -> 45833 | B19: 47 | C19: 47 | D19: 464 | E19: 0 | F19: 12 | G19: 0 | H19: 0 | I19: 27.206629 | J19: 39.571819 | K19: 9.02993 | L19: 4 | M19: 32 | N19: 0 | O19: 1 | P19: 228 | Q19: 234 | R19: 31 | S19: 16 | T19: 92 | U19: 61 | V19: 9 | W19: 39 | X19: 42 | Y19: 11 | Z19: 343 | AA19: 9 | AB19: 71 | AC19: 63 | AD19: 0 | AE19: 0 | AF19: 2 | AG19: 19 | AH19: 41 | AI19: 205 | AJ19: 927 | AK19: 13 | AL19: 69 | AM19: 193 | AN19: 0 | AO19: 1062 | AP19: 0 | AQ19: 490 | AR19: 34 | AS19: 319 | AT19: 842 | AU19: 724 | AY19: 17 | AZ19: 0.85 | BA19: =AVERAGE(B19:AS19) -> 120.58655 | BB19: =MIN(B19:AS19) -> 0 | BC19: =MAX(B19:AS19) -> 1062 | BD19: =SUM(B19:AS19)/SUM($B$4:$AS$123) -> 0.0032177916 | BE19: =BD19+BE18 -> 0.01701943 | BF19: =A19 -> 45833 | BG19: =BA19+BG18 -> 637.80216 | BH19: =Currentyear!C22 -> 2455 | BI19: =IF(ISERR(BJ19/BC19),"",($BH19/$BE19)*(1+$BC279)) -> 237579.34 | BJ19: =IF(ISERR(BK19/BD19),"",($BH19/$BE19)*(1-$BC279)) -> 50914.457 | BK19: =IF(ISERR(BH19/BE19),"",$BH19/$BE19) -> 144246.9 | BL19: {=[1]!daniels(BK15:BK19,1)} -> #NAME? | BM19: #NAME? | BN19: #NAME? | BO19: =(BK19-AVERAGE(BK15:BK19))/AVERAGE(BK15:BK19) -> 0.30062732 | BP19: =(BI19-BK19)/BK19 -> 0.64703257
A20: =A19+1 -> 45834 | B20: 42 | C20: 36 | D20: 274 | E20: 2 | F20: 12 | G20: 37 | H20: 0 | I20: 0 | J20: 33.246019 | K20: 7.5864399 | L20: 2 | M20: 147 | N20: 180 | O20: 2 | P20: 28 | Q20: 167 | R20: 18 | S20: 7 | T20: 89 | U20: 46 | V20: 15 | W20: 54 | X20: 1 | Y20: 48 | Z20: 201 | AA20: 514 | AB20: 44 | AC20: 401 | AD20: 2 | AE20: 2 | AF20: 3 | AG20: 36 | AH20: 59 | AI20: 537 | AJ20: 124 | AK20: 12 | AL20: 160 | AM20: 32 | AN20: 799 | AO20: 1022 | AP20: 0 | AQ20: 261 | AR20: 157 | AS20: 1496 | AT20: 207 | AU20: 872 | AY20: 18 | AZ20: 0.9 | BA20: =AVERAGE(B20:AS20) -> 161.5871 | BB20: =MIN(B20:AS20) -> 0 | BC20: =MAX(B20:AS20) -> 1496 | BD20: =SUM(B20:AS20)/SUM($B$4:$AS$123) -> 0.0043118706 | BE20: =BD20+BE19 -> 0.021331301 | BF20: =A20 -> 45834 | BG20: =BA20+BG19 -> 799.38926 | BH20: =Currentyear!C23 -> 3327 | BI20: =IF(ISERR(BJ20/BC20),"",($BH20/$BE20)*(1+$BC280)) -> 249386.77 | BJ20: =IF(ISERR(BK20/BD20),"",($BH20/$BE20)*(1-$BC280)) -> 62549.206 | BK20: =IF(ISERR(BH20/BE20),"",$BH20/$BE20) -> 155967.99 | BL20: {=[1]!daniels(BK16:BK20,1)} -> #NAME? | BM20: #NAME? | BN20: #NAME? | BO20: =(BK20-AVERAGE(BK16:BK20))/AVERAGE(BK16:BK20) -> 0.27657444 | BP20: =(BI20-BK20)/BK20 -> 0.59896125
A21: =A20+1 -> 45835 | B21: 118 | C21: 4 | D21: 144 | E21: 2 | F21: 0 | G21: 8 | H21: 0 | I21: 0 | J21: 0 | K21: 14.770711 | L21: 17 | M21: 85 | N21: 54 | O21: 6 | P21: 42 | Q21: 253 | R21: 187 | S21: 7 | T21: 438 | U21: 820 | V21: 21 | W21: 77 | X21: 38 | Y21: 24 | Z21: 930 | AA21: 368 | AB21: 28 | AC21: 183 | AD21: 3 | AE21: 1 | AF21: 9 | AG21: 0 | AH21: 522 | AI21: 425 | AJ21: 146 | AK21: 93 | AL21: 176 | AM21: 3 | AN21: 502 | AO21: 1982 | AP21: 0 | AQ21: 282 | AR21: 0 | AS21: 3360 | AT21: 1109 | AU21: 312 | AY21: 19 | AZ21: 0.95 | BA21: =AVERAGE(B21:AS21) -> 258.47206 | BB21: =MIN(B21:AS21) -> 0 | BC21: =MAX(B21:AS21) -> 3360 | BD21: =SUM(B21:AS21)/SUM($B$4:$AS$123) -> 0.006897197 | BE21: =BD21+BE20 -> 0.028228498 | BF21: =A21 -> 45835 | BG21: =BA21+BG20 -> 1057.8613 | BH21: =Currentyear!C24 -> 3639 | BI21: =IF(ISERR(BJ21/BC21),"",($BH21/$BE21)*(1+$BC281)) -> 213559.2 | BJ21: =IF(ISERR(BK21/BD21),"",($BH21/$BE21)*(1-$BC281)) -> 44265.365 | BK21: =IF(ISERR(BH21/BE21),"",$BH21/$BE21) -> 128912.28 | BL21: {=[1]!daniels(BK17:BK21,1)} -> #NAME? | BM21: #NAME? | BN21: #NAME? | BO21: =(BK21-AVERAGE(BK17:BK21))/AVERAGE(BK17:BK21) -> -0.031183167 | BP21: =(BI21-BK21)/BK21 -> 0.65662414
A22: =A21+1 -> 45836 | B22: 171 | C22: 53 | D22: 148 | E22: 7 | F22: 8 | G22: 3 | H22: 0 | I22: 0 | J22: 0 | K22: 12.790016 | L22: 29 | M22: 109 | N22: 92 | O22: 3 | P22: 195 | Q22: 210 | R22: 180 | S22: 7 | T22: 267 | U22: 410 | V22: 24 | W22: 91 | X22: 8 | Y22: 74 | Z22: 197 | AA22: 433 | AB22: 142 | AC22: 71 | AD22: 3 | AE22: 17 | AF22: 1 | AG22: 0 | AH22: 201 | AI22: 1030 | AJ22: 304 | AK22: 2 | AL22: 437 | AM22: 457 | AN22: 869 | AO22: 766 | AP22: 9 | AQ22: 150 | AR22: 113 | AS22: 924 | AT22: 1345 | AU22: 3293 | AY22: 19 | AZ22: 0.95 | BA22: =AVERAGE(B22:AS22) -> 186.99523 | BB22: =MIN(B22:AS22) -> 0 | BC22: =MAX(B22:AS22) -> 1030 | BD22: =SUM(B22:AS22)/SUM($B$4:$AS$123) -> 0.0049898736 | BE22: =BD22+BE21 -> 0.033218371 | BF22: =A22 -> 45836 | BG22: =BA22+BG21 -> 1244.8566 | BH22: =Currentyear!C25 -> 6932 | BI22: =IF(ISERR(BJ22/BC22),"",($BH22/$BE22)*(1+$BC282)) -> 351189.42 | BJ22: =IF(ISERR(BK22/BD22),"",($BH22/$BE22)*(1-$BC282)) -> 66169.995 | BK22: =IF(ISERR(BH22/BE22),"",$BH22/$BE22) -> 208679.71 | BL22: {=[1]!daniels(BK18:BK22,1)} -> #NAME? | BM22: #NAME? | BN22: #NAME? | BO22: =(BK22-AVERAGE(BK18:BK22))/AVERAGE(BK18:BK22) -> 0.36708851 | BP22: =(BI22-BK22)/BK22 -> 0.68291122
... A85: =A84+1 -> 45899 | B85: 32 | C85: 23 | D85: 7 | E85: 1.5435778 | F85: 5 | G85: 17 | H85: 37.219175 | I85: 33.178767 | J85: 48.258244 | K85: 26 | L85: 106.90459 | M85: 72 | N85: 111 | O85: 86 | P85: 35 | Q85: 182 | R85: 207 | S85: 65.047046 | T85: 97.856379 | U85: 447 | V85: 10.267692 | W85: 3 | X85: 51 | Y85: 967 | Z85: 127 | AA85: 252 | AB85: 626 | AC85: 490 | AD85: 32 | AE85: 6 | AF85: 80 | AG85: 53 | AH85: 57 | AI85: 28 | AJ85: 221 | AK85: 65.101567 | AL85: 15 | AM85: 253 | AN85: 175 | AO85: 44 | AP85: 150 | AQ85: 412 | AR85: 236 | AS85: 475 | AT85: 875.32634 | AU85: 208 | AY85: 13 | AZ85: 0.65 | BA85: =AVERAGE(B85:AS85) -> 147.00857 | BB85: =MIN(B85:AS85) -> 1.5435778 | BC85: =MAX(B85:AS85) -> 967 | BD85: =SUM(B85:AS85)/SUM($B$4:$AS$123) -> 0.0039228498 | BE85: =BD85+BE84 -> 0.97476254 | BF85: =A85 -> 45899 | BG85: =BA85+BG84 -> 36529.17 | BH85: =Currentyear!C88 -> 228571 | BI85: =IF(ISERR(BJ85/BC85),"",($BH85/$BE85)*(1+$BC345)) -> 235533.34 | BJ85: =IF(ISERR(BK85/BD85),"",($BH85/$BE85)*(1-$BC345)) -> 233444.47 | BK85: =IF(ISERR(BH85/BE85),"",$BH85/$BE85) -> 234488.9 | BL85: {=[1]!daniels(BK81:BK85,1)} -> #NAME? | BM85: #NAME? | BN85: #NAME? | BO85: =(BK85-AVERAGE(BK81:BK85))/AVERAGE(BK81:BK85) -> -0.0056185389 | BP85: =(BI85-BK85)/BK85 -> 0.004454089
A86: =A85+1 -> 45900 | B86: 30 | C86: 10 | D86: 5 | E86: 1.003943 | F86: 12 | G86: 8 | H86: 24.207351 | I86: 21.57947 | J86: 31.387162 | K86: 34 | L86: 69.530747 | M86: 42 | N86: 207 | O86: 183 | P86: 25 | Q86: 77 | R86: 69 | S86: 42.306599 | T86: 63.645789 | U86: 111 | V86: 6.6781072 | W86: 2 | X86: 29 | Y86: 236 | Z86: 119 | AA86: 400 | AB86: 265.56738 | AC86: 349 | AD86: 17 | AE86: 41 | AF86: 18 | AG86: 96 | AH86: 104 | AI86: 62 | AJ86: 126 | AK86: 41.19125 | AL86: 105 | AM86: 371 | AN86: 120 | AO86: 29 | AP86: 171 | AQ86: 251 | AR86: 274 | AS86: 729 | AT86: 680.55738 | AY86: 13 | AZ86: 0.65 | BA86: =AVERAGE(B86:AS86) -> 114.29768 | BB86: =MIN(B86:AS86) -> 1.003943 | BC86: =MAX(B86:AS86) -> 729 | BD86: =SUM(B86:AS86)/SUM($B$4:$AS$123) -> 0.0030499761 | BE86: =BD86+BE85 -> 0.97781252 | BF86: =A86 -> 45900 | BG86: =BA86+BG85 -> 36643.468 | BH86: =Currentyear!C89 | BI86: =IF(ISERR(BJ86/BC86),"",($BH86/$BE86)*(1+$BC346)) | BJ86: =IF(ISERR(BK86/BD86),"",($BH86/$BE86)*(1-$BC346)) | BK86: =IF(ISERR(BH86/BE86),"",$BH86/$BE86) | BL86: {=[1]!daniels(BK82:BK86,1)} -> #NAME? | BM86: #NAME? | BN86: #NAME? | BO86: =(BK86-AVERAGE(BK82:BK86))/AVERAGE(BK82:BK86) -> #VALUE! | BP86: =(BI86-BK86)/BK86 -> #VALUE!
A87: =A86+1 -> 45901 | B87: 14 | C87: 6 | D87: 18 | E87: 1.895102 | F87: 4 | G87: 25 | H87: 45.695225 | I87: 40.734681 | J87: 59.24826 | K87: 27 | L87: 131.25034 | M87: 70 | N87: 176 | O87: 82 | P87: 98 | Q87: 108 | R87: 144.66679 | S87: 79.860433 | T87: 120.14155 | U87: 762 | V87: 12.605989 | W87: 6 | X87: 22 | Y87: 81 | Z87: 486 | AA87: 598 | AB87: 459.7803 | AC87: 304 | AD87: 6 | AE87: 63 | AF87: 37 | AG87: 46 | AH87: 4 | AI87: 103 | AJ87: 80.441431 | AK87: 60.601576 | AL87: 20 | AM87: 122 | AN87: 126 | AO87: 417 | AP87: 174 | AQ87: 313 | AR87: 100 | AS87: 776 | AT87: 870.25773 | AY87: 12 | AZ87: 0.6 | BA87: =AVERAGE(B87:AS87) -> 146.15731 | BB87: =MIN(B87:AS87) -> 1.895102 | BC87: =MAX(B87:AS87) -> 776 | BD87: =SUM(B87:AS87)/SUM($B$4:$AS$123) -> 0.0039001344 | BE87: =BD87+BE86 -> 0.98171265 | BF87: =A87 -> 45901 | BG87: =BA87+BG86 -> 36789.625 | BH87: =Currentyear!C90 | BI87: =IF(ISERR(BJ87/BC87),"",($BH87/$BE87)*(1+$BC347)) | BJ87: =IF(ISERR(BK87/BD87),"",($BH87/$BE87)*(1-$BC347)) | BK87: =IF(ISERR(BH87/BE87),"",$BH87/$BE87) | BL87: {=[1]!daniels(BK83:BK87,1)} -> #NAME? | BM87: #NAME? | BN87: #NAME? | BO87: =(BK87-AVERAGE(BK83:BK87))/AVERAGE(BK83:BK87) -> #VALUE! | BP87: =(BI87-BK87)/BK87 -> #VALUE!
A88: =A87+1 -> 45902 | B88: 15 | C88: 20 | D88: 6 | E88: 1.0888109 | F88: 1 | G88: 27 | H88: 26.25371 | I88: 23.403681 | J88: 34.040462 | K88: 26 | L88: 75.4085 | M88: 79 | N88: 64 | O88: 48 | P88: 59.758541 | Q88: 94.851295 | R88: 83.11678 | S88: 45.882969 | T88: 69.026059 | U88: 358 | V88: 7.2426382 | W88: 16 | X88: 21 | Y88: 233 | Z88: 142 | AA88: 200 | AB88: 253.67463 | AC88: 373 | AD88: 22 | AE88: 68 | AF88: 158 | AG88: 13 | AH88: 10 | AI88: 38 | AJ88: 51.424596 | AK88: 38.741374 | AL88: 31 | AM88: 307 | AN88: 199.15824 | AO88: 65 | AP88: 57 | AQ88: 158.36171 | AR88: 44 | AS88: 776 | AT88: 600.76175 | AY88: 10 | AZ88: 0.5 | BA88: =AVERAGE(B88:AS88) -> 100.89623 | BB88: =MIN(B88:AS88) -> 1 | BC88: =MAX(B88:AS88) -> 776 | BD88: =SUM(B88:AS88)/SUM($B$4:$AS$123) -> 0.0026923651 | BE88: =BD88+BE87 -> 0.98440502 | BF88: =A88 -> 45902 | BG88: =BA88+BG87 -> 36890.521 | BH88: =Currentyear!C91 | BI88: =IF(ISERR(BJ88/BC88),"",($BH88/$BE88)*(1+$BC348)) | BJ88: =IF(ISERR(BK88/BD88),"",($BH88/$BE88)*(1-$BC348)) | BK88: =IF(ISERR(BH88/BE88),"",$BH88/$BE88) | BL88: {=[1]!daniels(BK84:BK88,1)} -> #NAME? | BM88: #NAME? | BN88: #NAME? | BO88: =(BK88-AVERAGE(BK84:BK88))/AVERAGE(BK84:BK88) -> #VALUE! | BP88: =(BI88-BK88)/BK88 -> #VALUE!
A89: =A88+1 -> 45903 | B89: 23 | C89: 31.34038 | D89: 0 | E89: 0.73701261 | F89: 1 | G89: 25 | H89: 17.771052 | I89: 15.841877 | J89: 23.041881 | K89: 7 | L89: 51.043773 | M89: 21 | N89: 73.581167 | O89: 3 | P89: 40.450366 | Q89: 64.20454 | R89: 56.261484 | S89: 31.058036 | T89: 46.723519 | U89: 251 | V89: 4.9025187 | W89: 7 | X89: 68 | Y89: 175 | Z89: 397 | AA89: 321 | AB89: 250.8015 | AC89: 377 | AD89: 44 | AE89: 12 | AF89: 66 | AG89: 76 | AH89: 109.97265 | AI89: 131.94469 | AJ89: 53.547164 | AK89: 40.340438 | AL89: 12 | AM89: 244 | AN89: 201.29259 | AO89: 3 | AP89: 136 | AQ89: 160.77687 | AR89: 209 | AS89: 475 | AT89: 589.82751 | AY89: 8 | AZ89: 0.4 | BA89: =AVERAGE(B89:AS89) -> 99.059853 | BB89: =MIN(B89:AS89) -> 0 | BC89: =MAX(B89:AS89) -> 475 | BD89: =SUM(B89:AS89)/SUM($B$4:$AS$123) -> 0.0026433624 | BE89: =BD89+BE88 -> 0.98704838 | BF89: =A89 -> 45903 | BG89: =BA89+BG88 -> 36989.581 | BH89: =Currentyear!C92 | BI89: =IF(ISERR(BJ89/BC89),"",($BH89/$BE89)*(1+$BC349)) | BJ89: =IF(ISERR(BK89/BD89),"",($BH89/$BE89)*(1-$BC349)) | BK89: =IF(ISERR(BH89/BE89),"",$BH89/$BE89) | BL89: {=[1]!daniels(BK85:BK89,1)} -> #NAME? | BM89: #NAME? | BN89: #NAME? | BO89: =(BK89-AVERAGE(BK85:BK89))/AVERAGE(BK85:BK89) -> #VALUE! | BP89: =(BI89-BK89)/BK89 -> #VALUE!
A90: =A89+1 -> 45904 | B90: 0 | C90: 38.483632 | D90: 45.942944 | E90: 0.90499611 | F90: 0 | G90: 18 | H90: 21.821517 | I90: 19.452635 | J90: 28.293698 | K90: 12 | L90: 62.677919 | M90: 253 | N90: 90.352146 | O90: 20.500189 | P90: 49.670011 | Q90: 78.838351 | R90: 69.084875 | S90: 38.136935 | T90: 57.372972 | U90: 57 | V90: 6.0199247 | W90: 0 | X90: 39 | Y90: 405 | Z90: 683 | AA90: 188 | AB90: 326.01451 | AC90: 287 | AD90: 18 | AE90: 13 | AF90: 24 | AG90: 56 | AH90: 128.06778 | AI90: 153.65515 | AJ90: 62.357929 | AK90: 46.978139 | AL90: 32 | AM90: 224 | AN90: 231.74194 | AO90: 113 | AP90: 91 | AQ90: 187.10946 | AR90: 274.8468 | AS90: 797 | AT90: 723.7564 | AY90: 6 | AZ90: 0.3 | BA90: =AVERAGE(B90:AS90) -> 121.55283 | BB90: =MIN(B90:AS90) -> 0 | BC90: =MAX(B90:AS90) -> 797 | BD90: =SUM(B90:AS90)/SUM($B$4:$AS$123) -> 0.0032435761 | BE90: =BD90+BE89 -> 0.99029196 | BF90: =A90 -> 45904 | BG90: =BA90+BG89 -> 37111.134 | BH90: =Currentyear!C93 | BI90: =IF(ISERR(BJ90/BC90),"",($BH90/$BE90)*(1+$BC350)) | BJ90: =IF(ISERR(BK90/BD90),"",($BH90/$BE90)*(1-$BC350)) | BK90: =IF(ISERR(BH90/BE90),"",$BH90/$BE90) | BL90: {=[1]!daniels(BK86:BK90,1)} -> #NAME? | BM90: #NAME? | BN90: #NAME? | BO90: =(BK90-AVERAGE(BK86:BK90))/AVERAGE(BK86:BK90) -> #VALUE! | BP90: =(BI90-BK90)/BK90 -> #VALUE!
A91: =A90+1 -> 45905 | B91: 4 | C91: 24.335238 | D91: 29.052156 | E91: 0.57227695 | F91: 0 | G91: 21 | H91: 13.798901 | I91: 12.300931 | J91: 17.891603 | K91: 5 | L91: 39.634566 | M91: 7 | N91: 57.134445 | O91: 12.963355 | P91: 31.408977 | Q91: 49.853663 | R91: 43.686024 | S91: 24.116003 | T91: 36.279967 | U91: 178 | V91: 3.8067171 | W91: 4 | X91: 20 | Y91: 354 | Z91: 239 | AA91: 146 | AB91: 196.36615 | AC91: 505 | AD91: 5 | AE91: 17 | AF91: 12 | AG91: 14 | AH91: 90.482495 | AI91: 108.56049 | AJ91: 44.057146 | AK91: 33.191012 | AL91: 50.377406 | AM91: 256 | AN91: 171.69112 | AO91: 80 | AP91: 58 | AQ91: 138.02304 | AR91: 202.74331 | AS91: 356.94463 | AT91: 502.62991 | AY91: 6 | AZ91: 0.3 | BA91: =AVERAGE(B91:AS91) -> 84.415264 | BB91: =MIN(B91:AS91) -> 0 | BC91: =MAX(B91:AS91) -> 505 | BD91: =SUM(B91:AS91)/SUM($B$4:$AS$123) -> 0.0022525789 | BE91: =BD91+BE90 -> 0.99254453 | BF91: =A91 -> 45905 | BG91: =BA91+BG90 -> 37195.549 | BH91: =Currentyear!C94 | BI91: =IF(ISERR(BJ91/BC91),"",($BH91/$BE91)*(1+$BC351)) | BJ91: =IF(ISERR(BK91/BD91),"",($BH91/$BE91)*(1-$BC351)) | BK91: =IF(ISERR(BH91/BE91),"",$BH91/$BE91) | BL91: {=[1]!daniels(BK87:BK91,1)} -> #NAME? | BM91: #NAME? | BN91: #NAME? | BO91: =(BK91-AVERAGE(BK87:BK91))/AVERAGE(BK87:BK91) -> #VALUE! | BP91: =(BI91-BK91)/BK91 -> #VALUE!
A92: =A91+1 -> 45906 | B92: 5 | C92: 46.293545 | D92: 55.266659 | E92: 1.0886571 | F92: 2 | G92: 12 | H92: 26.250002 | I92: 23.400376 | J92: 34.035655 | K92: 24 | L92: 75.39785 | M92: 8 | N92: 108.68832 | O92: 24.660521 | P92: 59.750101 | Q92: 94.837899 | R92: 83.105041 | S92: 45.876489 | T92: 69.01631 | U92: 358 | V92: 7.2416152 | W92: 2 | X92: 13 | Y92: 159 | Z92: 95 | AA92: 81 | AB92: 216.22997 | AC92: 236 | AD92: 6 | AE92: 31 | AF92: 80 | AG92: 50.430113 | AH92: 90.881541 | AI92: 109.03927 | AJ92: 44.251447 | AK92: 33.337391 | AL92: 50.599581 | AM92: 54 | AN92: 159.56426 | AO92: 28 | AP92: 86.664145 | AQ92: 127.65247 | AR92: 187.50988 | AS92: 330.12505 | AT92: 464.86405 | AY92: 6 | AZ92: 0.3 | BA92: =AVERAGE(B92:AS92) -> 78.072594 | BB92: =MIN(B92:AS92) -> 1.0886571 | BC92: =MAX(B92:AS92) -> 358 | BD92: =SUM(B92:AS92)/SUM($B$4:$AS$123) -> 0.0020833279 | BE92: =BD92+BE91 -> 0.99462786 | BF92: =A92 -> 45906 | BG92: =BA92+BG91 -> 37273.622 | BH92: =Currentyear!C95 | BI92: =IF(ISERR(BJ92/BC92),"",($BH92/$BE92)*(1+$BC352)) | BJ92: =IF(ISERR(BK92/BD92),"",($BH92/$BE92)*(1-$BC352)) | BK92: =IF(ISERR(BH92/BE92),"",$BH92/$BE92) | BL92: {=[1]!daniels(BK88:BK92,1)} -> #NAME? | BM92: #NAME? | BN92: #NAME? | BO92: =(BK92-AVERAGE(BK88:BK92))/AVERAGE(BK88:BK92) -> #VALUE! | BP92: =(BI92-BK92)/BK92 -> #VALUE!
A93: =A92+1 -> 45907 | B93: 0 | C93: 3.4156074 | D93: 4.0776572 | E93: 0.080322756 | F93: 0 | G93: 11 | H93: 1.9367646 | I93: 1.7265149 | J93: 2.5112018 | K93: 6 | L93: 5.5629667 | M93: 3 | N93: 8.0191874 | O93: 1.8194903 | P93: 4.4084523 | Q93: 6.9972827 | R93: 6.1316148 | S93: 3.3848363 | T93: 5.0921271 | U93: 10.176635 | V93: 0.53429726 | W93: 0 | X93: 26 | Y93: 59 | Z93: 131 | AA93: 290 | AB93: 84.536852 | AC93: 161 | AD93: 6 | AE93: 7 | AF93: 15.835518 | AG93: 20.970733 | AH93: 37.791953 | AI93: 45.342617 | AJ93: 18.401411 | AK93: 13.862937 | AL93: 21.041203 | AM93: 253 | AN93: 80.975783 | AO93: 65.905314 | AP93: 45.637715 | AQ93: 67.222343 | AR93: 98.743515 | AS93: 173.84528 | AT93: 244.79942 | AY93: 5 | AZ93: 0.25 | BA93: =AVERAGE(B93:AS93) -> 41.113367 | BB93: =MIN(B93:AS93) -> 0 | BC93: =MAX(B93:AS93) -> 290 | BD93: =SUM(B93:AS93)/SUM($B$4:$AS$123) -> 0.0010970895 | BE93: =BD93+BE92 -> 0.99572495 | BF93: =A93 -> 45907 | BG93: =BA93+BG92 -> 37314.735 | BH93: =Currentyear!C96 | BI93: =IF(ISERR(BJ93/BC93),"",($BH93/$BE93)*(1+$BC353)) | BJ93: =IF(ISERR(BK93/BD93),"",($BH93/$BE93)*(1-$BC353)) | BK93: =IF(ISERR(BH93/BE93),"",$BH93/$BE93) | BL93: {=[1]!daniels(BK89:BK93,1)} -> #NAME? | BM93: #NAME? | BN93: #NAME? | BO93: =(BK93-AVERAGE(BK89:BK93))/AVERAGE(BK89:BK93) -> #VALUE! | BP93: =(BI93-BK93)/BK93 -> #VALUE!
A94: =A93+1 -> 45908 | B94: 0 | C94: 4.4402896 | D94: 5.3009544 | E94: 0.10441958 | F94: 0 | G94: 5 | H94: 2.5177939 | I94: 2.2444694 | J94: 3.2645623 | K94: 7 | L94: 7.2318567 | M94: 14 | N94: 10.424944 | O94: 2.3653374 | P94: 5.730988 | Q94: 9.0964675 | R94: 7.9710993 | S94: 4.4002872 | T94: 6.6197652 | U94: 13.229625 | V94: 0.69458644 | W94: 2 | X94: 5.5515428 | Y94: 129 | Z94: 151 | AA94: 157 | AB94: 79.439864 | AC94: 311 | AD94: 10.600648 | AE94: 13.238994 | AF94: 18.071093 | AG94: 23.931271 | AH94: 43.127223 | AI94: 51.74385 | AJ94: 20.999226 | AK94: 15.820034 | AL94: 24.01169 | AM94: 58.728526 | AN94: 77.819814 | AO94: 63.336705 | AP94: 43.85902 | AQ94: 64.602404 | AR94: 94.895063 | AS94: 167.0698 | AT94: 235.25855 | AY94: 5 | AZ94: 0.25 | BA94: =AVERAGE(B94:AS94) -> 39.511005 | BB94: =MIN(B94:AS94) -> 0 | BC94: =MAX(B94:AS94) -> 311 | BD94: =SUM(B94:AS94)/SUM($B$4:$AS$123) -> 0.0010543313 | BE94: =BD94+BE93 -> 0.99677928 | BF94: =A94 -> 45908 | BG94: =BA94+BG93 -> 37354.246 | BH94: =Currentyear!C97 | BI94: =IF(ISERR(BJ94/BC94),"",($BH94/$BE94)*(1+$BC354)) | BJ94: =IF(ISERR(BK94/BD94),"",($BH94/$BE94)*(1-$BC354)) | BK94: =IF(ISERR(BH94/BE94),"",$BH94/$BE94) | BL94: {=[1]!daniels(BK90:BK94,1)} -> #NAME? | BM94: #NAME? | BN94: #NAME? | BO94: =(BK94-AVERAGE(BK90:BK94))/AVERAGE(BK90:BK94) -> #VALUE! | BP94: =(BI94-BK94)/BK94 -> #VALUE!
A95: =A94+1 -> 45909 | B95: 0 | C95: 7.3435558 | D95: 8.766963 | E95: 0.17269393 | F95: 1 | G95: 3 | H95: 4.1640438 | I95: 3.7120071 | J95: 5.3990838 | K95: 3 | L95: 11.960378 | M95: 36 | N95: 17.241253 | O95: 3.9119042 | P95: 9.4781724 | Q95: 15.044158 | R95: 13.182972 | S95: 7.2773981 | T95: 10.948073 | U95: 21.879765 | V95: 1.1487391 | W95: 1 | X95: 9.0686598 | Y95: 40 | Z95: 31.002941 | AA95: 89 | AB95: 50.661807 | AC95: 257 | AD95: 7.4173673 | AE95: 9.2634411 | AF95: 12.644503 | AG95: 16.744921 | AH95: 30.176499 | AI95: 36.205629 | AJ95: 14.693344 | AK95: 11.069418 | AL95: 16.801192 | AM95: 41.092868 | AN95: 54.451211 | AO95: 44.317252 | AP95: 30.688543 | AQ95: 45.202872 | AR95: 66.398913 | AS95: 116.90021 | AT95: 164.61249 | AY95: 5 | AZ95: 0.25 | BA95: =AVERAGE(B95:AS95) -> 27.646199 | BB95: =MIN(B95:AS95) -> 0 | BC95: =MAX(B95:AS95) -> 257 | BD95: =SUM(B95:AS95)/SUM($B$4:$AS$123) -> 0.00073772492 | BE95: =BD95+BE94 -> 0.99751701 | BF95: =A95 -> 45909 | BG95: =BA95+BG94 -> 37381.893 | BH95: =Currentyear!C98 | BI95: =IF(ISERR(BJ95/BC95),"",($BH95/$BE95)*(1+$BC355)) | BJ95: =IF(ISERR(BK95/BD95),"",($BH95/$BE95)*(1-$BC355)) | BK95: =IF(ISERR(BH95/BE95),"",$BH95/$BE95) | BL95: {=[1]!daniels(BK91:BK95,1)} -> #NAME? | BM95: #NAME? | BN95: #NAME? | BO95: =(BK95-AVERAGE(BK91:BK95))/AVERAGE(BK91:BK95) -> #VALUE! | BP95: =(BI95-BK95)/BK95 -> #VALUE!
A96: =A95+1 -> 45910 | B96: 0 | C96: 2.3909252 | D96: 2.85436 | E96: 0.05622593 | F96: 1 | G96: 5 | H96: 1.3557352 | I96: 1.2085604 | J96: 1.7578412 | K96: 1 | L96: 3.8940767 | M96: 7 | N96: 5.6134312 | O96: 1.2736432 | P96: 3.0859166 | Q96: 4.8980979 | R96: 4.2921304 | S96: 2.3693854 | T96: 3.564489 | U96: 7.1236444 | V96: 0.37400808 | W96: 0 | X96: 2.9366812 | Y96: 55 | Z96: 15.593838 | AA96: 96 | AB96: 32.799657 | AC96: 21.12069 | AD96: 3.1754316 | AE96: 3.96575 | AF96: 5.4132086 | AG96: 7.1686289 | AH96: 12.91879 | AI96: 15.499907 | AJ96: 6.2903329 | AK96: 4.7389023 | AL96: 7.1927186 | AM96: 17.592171 | AN96: 23.31098 | AO96: 18.972554 | AP96: 13.138 | AQ96: 19.351695 | AR96: 28.425883 | AS96: 50.045874 | AT96: 70.471864 | AY96: 5 | AZ96: 0.25 | BA96: =AVERAGE(B96:AS96) -> 11.835549 | BB96: =MIN(B96:AS96) -> 0 | BC96: =MAX(B96:AS96) -> 96 | BD96: =SUM(B96:AS96)/SUM($B$4:$AS$123) -> 0.00031582568 | BE96: =BD96+BE95 -> 0.99783283 | BF96: =A96 -> 45910 | BG96: =BA96+BG95 -> 37393.728 | BH96: =Currentyear!C99 | BI96: =IF(ISERR(BJ96/BC96),"",($BH96/$BE96)*(1+$BC356)) | BJ96: =IF(ISERR(BK96/BD96),"",($BH96/$BE96)*(1-$BC356)) | BK96: =IF(ISERR(BH96/BE96),"",$BH96/$BE96) | BL96: {=[1]!daniels(BK92:BK96,1)} -> #NAME? | BM96: #NAME? | BN96: #NAME? | BO96: =(BK96-AVERAGE(BK92:BK96))/AVERAGE(BK92:BK96) -> #VALUE! | BP96: =(BI96-BK96)/BK96 -> #VALUE!
A97: =A96+1 -> 45911 | B97: 2 | C97: 5.2941914 | D97: 6.3203687 | E97: 0.12450027 | F97: 1 | G97: 4 | H97: 3.0019851 | I97: 2.6760981 | J97: 3.8923627 | K97: 7 | L97: 8.6225984 | M97: 17 | N97: 12.42974 | O97: 2.82021 | P97: 6.833101 | Q97: 10.845788 | R97: 9.504003 | S97: 5.2464963 | T97: 7.892797 | U97: 15.773784 | V97: 0.82816075 | W97: 0 | X97: 6.5026513 | Y97: 169 | Z97: 40.766037 | AA97: 36 | AB97: 55.042671 | AC97: 35.443638 | AD97: 5.3288436 | AE97: 6.6551145 | AF97: 9.0841639 | AG97: 12.030019 | AH97: 21.679639 | AI97: 26.011134 | AJ97: 10.556108 | AK97: 7.9525785 | AL97: 12.070445 | AM97: 29.522263 | AN97: 39.119269 | AO97: 31.83875 | AP97: 22.047506 | AQ97: 32.475004 | AR97: 47.702832 | AS97: 83.984373 | AT97: 118.2622 | AY97: 5 | AZ97: 0.25 | BA97: =AVERAGE(B97:AS97) -> 19.861801 | BB97: =MIN(B97:AS97) -> 0 | BC97: =MAX(B97:AS97) -> 169 | BD97: =SUM(B97:AS97)/SUM($B$4:$AS$123) -> 0.00053000216 | BE97: =BD97+BE96 -> 0.99836284 | BF97: =A97 -> 45911 | BG97: =BA97+BG96 -> 37413.59 | BH97: =Currentyear!C100 | BI97: =IF(ISERR(BJ97/BC97),"",($BH97/$BE97)*(1+$BC357)) | BJ97: =IF(ISERR(BK97/BD97),"",($BH97/$BE97)*(1-$BC357)) | BK97: =IF(ISERR(BH97/BE97),"",$BH97/$BE97) | BL97: {=[1]!daniels(BK93:BK97,1)} -> #NAME? | BM97: #NAME? | BN97: #NAME? | BO97: =(BK97-AVERAGE(BK93:BK97))/AVERAGE(BK93:BK97) -> #VALUE! | BP97: =(BI97-BK97)/BK97 -> #VALUE!
... A123: =A122+1 -> 45937 | B123: 0 | C123: 0 | D123: 0 | E123: 0 | F123: 0 | G123: 0 | H123: 0 | I123: 0 | J123: 0 | K123: 0 | L123: 0 | M123: 0 | N123: 0 | O123: 0 | P123: 0 | Q123: 0 | R123: 0 | S123: 0 | T123: 0 | U123: 0 | V123: 0 | W123: 0 | X123: 0 | Y123: 0 | Z123: 0 | AA123: 0 | AB123: 0 | AC123: 0 | AD123: 0 | AE123: 0 | AF123: 0 | AG123: 0 | AH123: 0 | AI123: 0 | AJ123: 0 | AK123: 0 | AL123: 0 | AM123: 0 | AN123: 0 | AO123: 0 | AP123: 0 | AQ123: 0 | AR123: 0 | AS123: 0 | AT123: 0 | AY123: 1 | AZ123: 0.05 | BA123: =AVERAGE(B123:AS123) -> 0 | BB123: =MIN(B123:AS123) -> 0 | BC123: =MAX(B123:AS123) -> 0 | BD123: =SUM(B123:AS123)/SUM($B$4:$AS$123) -> 0 | BE123: =BD123+BE122 -> 1 | BF123: =A123 -> 45937 | BG123: =BA123+BG122 -> 37474.943 | BH123: =Currentyear!C126 | BI123: =IF(ISERR(BJ123/BC123),"",($BH123/$BE123)*(1+$BC383)) | BJ123: =IF(ISERR(BK123/BD123),"",($BH123/$BE123)*(1-$BC383)) | BK123: =IF(ISERR(BH123/BE123),"",$BH123/$BE123) | BL123: {=[1]!daniels(BK119:BK123,1)} -> #NAME? | BM123: #NAME? | BN123: #NAME? | BO123: =(BK123-AVERAGE(BK119:BK123))/AVERAGE(BK119:BK123) -> #VALUE! | BP123: =(BI123-BK123)/BK123 -> #VALUE!
A124: Sum of Daily Weir Counts | B124: 22942 | C124: 19148 | D124: 22877 | E124: 430 | F124: 2525 | G124: 11545 | H124: 10669 | I124: 9414 | J124: 12990 | K124: 1889 | L124: 28669 | M124: 72517 | N124: 45039 | O124: 10231 | P124: 24707 | Q124: 39216 | R124: 34216 | S124: 18725 | T124: 28127 | U124: 57469 | V124: 2948 | W124: =SUM(W7:W97) -> 3661 | X124: =SUM(X7:X93) -> 23918.447 | Y124: =SUM(Y4:Y101) -> 69859 | Z124: =SUM(Z4:Z94) -> 77049 | AA124: =SUM(AA4:AA97) -> 65546 | AB124: =SUM(AB16:AB85) -> 101067 | AC124: =SUM(AC11:AC95) -> 66708 | AD124: =SUM(AD11:AD95) -> 10019.018 | AE124: =SUM(AE11:AE93) -> 12503 | AF124: =SUM(AF11:AF93) -> 17066.276 | AG124: =SUM(AG11:AG74,AG80:AG91) -> 21645 | AH124: =SUM(AH11:AH88) -> 40272 | AI124: =SUM(AI8:AI88) -> 48355 | AJ124: =SUM(AJ10:AJ64,AJ68:AJ86) -> 18694 | AK124: =SUM(AK10:AK51,AK54:AK77, AK80:AK84) -> 12540 | AL124: =SUM(AL7:AL90) -> 22553 | AM124: =SUM(AM11:AM93) -> 55397 | AN124: =SUM(AN10:AN87) -> 72409 | AO124: =SUM(AO7:AO92) -> 59745 | AP124: =SUM(AP8:AP91) -> 41279 | AQ124: =SUM(AQ8:AQ91) -> 60808.271 | AR124: =SUM(AR9:AR54,AR57:AR89) -> 84996 | AS124: =SUM(AS7:AS48,AS50:AS79,AS81:AS90) -> 152090 | AT124: =SUM(AT9:AT64,AT67:AT78,AT82:AT84) -> 206546 | AU124: =SUM(AU9:AU64,AU67:AU78,AU82:AU84) -> 213179 | AY124: =AVERAGE(B124:AN124) -> 31168.07
A125: Estimated passage when weir not operating | B125: =B128-B124 -> 8.5018123 | C125: =C128-C124 -> 235.96405 | D125: =D128-D124 -> 264.17291 | E125: =E128-E124 -> 25.840866 | F125: =F128-F124 -> 14.78551 | G125: =G128-G124 -> 34.40694 | H125: =H128-H124 -> 322.36136 | I125: =I128-I124 -> 384.17038 | ... AU125: =AU128-AU124 -> 15392
A126: Additional fish counted by weir personnel | AR126: =88+695+6 -> 789 | AS126: =1214+102 -> 1316 | AT126: 3618 | AU126: 3618
A127: Total Weir Count | B127: =B124+B126 -> 22942 | C127: =C124+C126 -> 19148 | D127: =D124+D126 -> 22877 | E127: =E124+E126 -> 430 | F127: =F124+F126 -> 2525 | G127: =G124+G126 -> 11545 | H127: =H124+H126 -> 10669 | I127: =I124+I126 -> 9414 | ... AU127: =AU124+AU126 -> 216797
...

Sheet Coho w EM Fill-in
A1: ="Table 1. Daily weir counts and escapement estimates for Redoubt Lake coho salmon, 1953 through "&MAX(B3:AT3)&"." -> Table 1. Daily weir counts and escapement estimates for Redoubt Lake coho salmon, 1953 through 2024.
BC2: ="Data for Charting "&MAX(B3:AT3)+1&" esc. prediction" -> Data for Charting 2025 esc. prediction | BF2: Upper | BG2: Lower | BI2: 5-Year Running Averages:
A3: Date | B3: 1953 | C3: 1954 | D3: 1955 | E3: 1982 | F3: 1983 | G3: 1984 | H3: 1985 | I3: 1986 | J3: 1987 | K3: 1988 | L3: 1989 | M3: 1990 | N3: 1991 | O3: 1992 | P3: 1993 | Q3: 1994 | R3: 1995 | S3: 1996 | T3: 1997 | U3: 1999 | V3: 2000 | W3: 2001 | X3: 2002 | Y3: 2003 | Z3: 2004 | AA3: 2005 | AB3: 2006 | AC3: 2007 | AD3: 2008 | AE3: 2009 | AF3: 2010 | AG3: 2011 | AH3: 2012 | AI3: 2013 | AJ3: 2014 | AK3: 2015 | AL3: 2016 | AM3: 2017 | AN3: 2018 | AO3: 2019 | AP3: 2020 | AQ3: 2021 | AR3: 2022 | AS3: 2023 | AT3: 2024 | AV3: Years w/ Weir Counts 1953-2005 | AW3: Percent w/ Counts 1953-2005 | AX3: ="Avg. 1953-"&MAX(B3:AT3) -> Avg. 1953-2024 | AY3: ="Min. 1953-"&MAX(B3:AT3) -> Min. 1953-2024 | AZ3: ="Max. 1953-"&MAX(B3:AT3) -> Max. 1953-2024 | BA3: Average Daily % of Run | BB3: Average Cum. % of Run | BC3: =A3 -> Date | BD3: ="Ave. Cum. Escapement (1953-1955 and 1982-"&MAX(B3:AT3)&")" -> Ave. Cum. Escapement (1953-1955 and 1982-2024) | BE3: ="Cumulative "&MAX(B3:AT3)+1&" Escapement = ("&ROUND(MAX(BE4:BE123),0)&")" -> Cumulative 2025 Escapement = (0) | BF3: (w/ Mean Absolute % Error) | BH3: ="Esc. Prediction for "&MAX(B3:AT3)+1&" = ("&FIXED(VLOOKUP(Currentyear!C4,'Coho w EM Fill-in'!BC4:BH123,6),0)&")" -> #VALUE! | BI3: Rho | BJ3: P-value | BK3: N | BL3: Relative Change in Predictions for Current Year | BM3: Relative Error in Prediction Model
A4: =Currentyear!K1 -> 45818 | B4: 0 | C4: 0 | D4: 0 | E4: 0 | F4: 0 | G4: 0 | H4: 0 | I4: 0 | J4: 0 | K4: 0 | L4: 0 | M4: 0 | N4: 0 | O4: 0 | P4: 0 | Q4: 0 | R4: 0 | S4: 0 | T4: 0 | U4: 0 | V4: 0 | W4: 0 | X4: 0 | Y4: 0 | Z4: 0 | AA4: 0 | AB4: 0 | AC4: 0 | AD4: 0 | AE4: 0 | AF4: 0 | AG4: 0 | AH4: 0 | AI4: 0 | AJ4: 0 | AK4: 0 | AL4: 0 | AM4: 0 | AN4: 0 | AO4: 0 | AP4: 0 | AQ4: 0 | AR4: 0 | AS4: 0 | AT4: 0 | AV4: 3 | AW4: 0.11538462 | AX4: =AVERAGE(B4:AP4) -> 0 | AY4: =MIN(B4:AP4) -> 0 | AZ4: =MAX(B4:AP4) -> 0 | BA4: =SUM(B4:AP4)/SUM($B$4:$AP$123) -> 0 | BB4: =BA4 -> 0 | BC4: =A4 -> 45818 | BD4: =AX4 -> 0 | BE4: =Currentyear!E7 | BF4: =IF(ISERR(BG4/AZ4),"",($BE4/$BB4)*(1+$AZ263)) | BG4: =IF(ISERR(BH4/BA4),"",($BE4/$BB4)*(1-$AZ263)) | BH4: =IF(ISERR(BE4/BB4),"",$BE4/$BB4)
A5: =A4+1 -> 45819 | B5: 0 | C5: 0 | D5: 0 | E5: 0 | F5: 0 | G5: 0 | H5: 0 | I5: 0 | J5: 0 | K5: 0 | L5: 0 | M5: 0 | N5: 0 | O5: 0 | P5: 0 | Q5: 0 | R5: 0 | S5: 0 | T5: 0 | U5: 0 | V5: 0 | W5: 0 | X5: 0 | Y5: 0 | Z5: 0 | AA5: 0 | AB5: 0 | AC5: 0 | AD5: 0 | AE5: 0 | AF5: 0 | AG5: 0 | AH5: 0 | AI5: 0 | AJ5: 0 | AK5: 0 | AL5: 0 | AM5: 0 | AN5: 0 | AO5: 0 | AP5: 0 | AQ5: 0 | AR5: 0 | AS5: 0 | AT5: 0 | AV5: 4 | AW5: 0.15384615 | AX5: =AVERAGE(B5:AP5) -> 0 | AY5: =MIN(B5:AP5) -> 0 | AZ5: =MAX(B5:AP5) -> 0 | BA5: =SUM(B5:AP5)/SUM($B$4:$AP$123) -> 0 | BB5: =BA5+BB4 -> 0 | BC5: =A5 -> 45819 | BD5: =AX5+BD4 -> 0 | BE5: =Currentyear!E8 | BF5: =IF(ISERR(BG5/AZ5),"",($BE5/$BB5)*(1+$AZ264)) | BG5: =IF(ISERR(BH5/BA5),"",($BE5/$BB5)*(1-$AZ264)) | BH5: =IF(ISERR(BE5/BB5),"",$BE5/$BB5)
A6: =A5+1 -> 45820 | B6: 0 | C6: 0 | D6: 0 | E6: 0 | F6: 0 | G6: 0 | H6: 0 | I6: 0 | J6: 0 | K6: 0 | L6: 0 | M6: 0 | N6: 0 | O6: 0 | P6: 0 | Q6: 0 | R6: 0 | S6: 0 | T6: 0 | U6: 0 | V6: 0 | W6: 0 | X6: 0 | Y6: 0 | Z6: 0 | AA6: 0 | AB6: 0 | AC6: 0 | AD6: 0 | AE6: 0 | AF6: 0 | AG6: 0 | AH6: 0 | AI6: 0 | AJ6: 0 | AK6: 0 | AL6: 0 | AM6: 0 | AN6: 0 | AO6: 0 | AP6: 0 | AQ6: 0 | AR6: 0 | AS6: 0 | AT6: 0 | AV6: 4 | AW6: 0.15384615 | AX6: =AVERAGE(B6:AP6) -> 0 | AY6: =MIN(B6:AP6) -> 0 | AZ6: =MAX(B6:AP6) -> 0 | BA6: =SUM(B6:AP6)/SUM($B$4:$AP$123) -> 0 | BB6: =BA6+BB5 -> 0 | BC6: =A6 -> 45820 | BD6: =AX6+BD5 -> 0 | BE6: =Currentyear!E9 | BF6: =IF(ISERR(BG6/AZ6),"",($BE6/$BB6)*(1+$AZ265)) | BG6: =IF(ISERR(BH6/BA6),"",($BE6/$BB6)*(1-$AZ265)) | BH6: =IF(ISERR(BE6/BB6),"",$BE6/$BB6)
A7: =A6+1 -> 45821 | B7: 0 | C7: 0 | D7: 0 | E7: 0 | F7: 0 | G7: 0 | H7: 0 | I7: 0 | J7: 0 | K7: 0 | L7: 0 | M7: 0 | N7: 0 | O7: 0 | P7: 0 | Q7: 0 | R7: 0 | S7: 0 | T7: 0 | U7: 0 | V7: 0 | W7: 0 | X7: 0 | Y7: 0 | Z7: 0 | AA7: 0 | AB7: 0 | AC7: 0 | AD7: 0 | AE7: 0 | AF7: 0 | AG7: 0 | AH7: 0 | AI7: 0 | AJ7: 0 | AK7: 0 | AL7: 0 | AM7: 0 | AN7: 0 | AO7: 0 | AP7: 0 | AQ7: 0 | AR7: 0 | AS7: 0 | AT7: 0 | AV7: 7 | AW7: 0.26923077 | AX7: =AVERAGE(B7:AP7) -> 0 | AY7: =MIN(B7:AP7) -> 0 | AZ7: =MAX(B7:AP7) -> 0 | BA7: =SUM(B7:AP7)/SUM($B$4:$AP$123) -> 0 | BB7: =BA7+BB6 -> 0 | BC7: =A7 -> 45821 | BD7: =AX7+BD6 -> 0 | BE7: =Currentyear!E10 -> 0 | BF7: =IF(ISERR(BG7/AZ7),"",($BE7/$BB7)*(1+$AZ266)) | BG7: =IF(ISERR(BH7/BA7),"",($BE7/$BB7)*(1-$AZ266)) | BH7: =IF(ISERR(BE7/BB7),"",$BE7/$BB7)
A8: =A7+1 -> 45822 | B8: 0 | C8: 0 | D8: 0 | E8: 0 | F8: 0 | G8: 0 | H8: 0 | I8: 0 | J8: 0 | K8: 0 | L8: 0 | M8: 0 | N8: 0 | O8: 0 | P8: 0 | Q8: 0 | R8: 0 | S8: 0 | T8: 0 | U8: 0 | V8: 0 | W8: 0 | X8: 0 | Y8: 0 | Z8: 0 | AA8: 0 | AB8: 0 | AC8: 0 | AD8: 0 | AE8: 0 | AF8: 0 | AG8: 0 | AH8: 0 | AI8: 0 | AJ8: 0 | AK8: 0 | AL8: 0 | AM8: 0 | AN8: 0 | AO8: 0 | AP8: 0 | AQ8: 0 | AR8: 0 | AS8: 0 | AT8: 0 | AV8: 8 | AW8: 0.30769231 | AX8: =AVERAGE(B8:AP8) -> 0 | AY8: =MIN(B8:AP8) -> 0 | AZ8: =MAX(B8:AP8) -> 0 | BA8: =SUM(B8:AP8)/SUM($B$4:$AP$123) -> 0 | BB8: =BA8+BB7 -> 0 | BC8: =A8 -> 45822 | BD8: =AX8+BD7 -> 0 | BE8: =Currentyear!E11 -> 0 | BF8: =IF(ISERR(BG8/AZ8),"",($BE8/$BB8)*(1+$AZ267)) | BG8: =IF(ISERR(BH8/BA8),"",($BE8/$BB8)*(1-$AZ267)) | BH8: =IF(ISERR(BE8/BB8),"",$BE8/$BB8)
A9: =A8+1 -> 45823 | B9: 0 | C9: 0 | D9: 0 | E9: 0 | F9: 0 | G9: 0 | H9: 0 | I9: 0 | J9: 0 | K9: 0 | L9: 0 | M9: 0 | N9: 0 | O9: 0 | P9: 0 | Q9: 0 | R9: 0 | S9: 0 | T9: 0 | U9: 0 | V9: 0 | W9: 0 | X9: 0 | Y9: 0 | Z9: 0 | AA9: 0 | AB9: 0 | AC9: 0 | AD9: 0 | AE9: 0 | AF9: 0 | AG9: 0 | AH9: 0 | AI9: 0 | AJ9: 0 | AK9: 0 | AL9: 0 | AM9: 0 | AN9: 0 | AO9: 0 | AP9: 0 | AQ9: 0 | AR9: 0 | AS9: 0 | AT9: 0 | AV9: 11 | AW9: 0.42307692 | AX9: =AVERAGE(B9:AP9) -> 0 | AY9: =MIN(B9:AP9) -> 0 | AZ9: =MAX(B9:AP9) -> 0 | BA9: =SUM(B9:AP9)/SUM($B$4:$AP$123) -> 0 | BB9: =BA9+BB8 -> 0 | BC9: =A9 -> 45823 | BD9: =AX9+BD8 -> 0 | BE9: =Currentyear!E12 | BF9: =IF(ISERR(BG9/AZ9),"",($BE9/$BB9)*(1+$AZ268)) | BG9: =IF(ISERR(BH9/BA9),"",($BE9/$BB9)*(1-$AZ268)) | BH9: =IF(ISERR(BE9/BB9),"",$BE9/$BB9)
