Workbook

Sheet Data Entry - Projections
A1: Redoubt Sockeye Tracking | Q1: OEG Range = | R1: 7000 | S1: 25000
B3: ENTER | J3: Forecasts -- Sockeye Salmon
B4: DATA | C4: _ | D4: _ | E4: _ | F4: _ | G4: _ | H4: _
B5: BELOW | F5: 10-year | G5: 10-year | H5: 10-year | J5: Three | K5: 10-year | L5: Three | N5: 1983-present
D6: Escapement Goal | F6: Avg. | G6: Avg. | H6: Avg. | J6: Days | K6: On | L6: Days | N6: On
B7: 2025 | C7: 2025 | D7: _ | E7: _ | F7: Cum | G7: Cum | H7: Daily | J7: Early | K7: Time | L7: Late | N7: Time
A8: Day | B8: Daily | C8: Cum. | D8: Lower | E8: Upper | F8: Prop. | G8: Number | H8: No.
A10: 164 | D10: =$R$1*F10 -> 0 | E10: =$S$1*F10 -> 0 | F10: =HistData!GQ5 -> 0 | G10: =+HistData!AW5 -> 0 | H10: =+HistData!AV5 -> 0
A11: 165 | D11: =$R$1*F11 -> 0 | E11: =$S$1*F11 -> 0 | F11: =HistData!GQ6 -> 0 | G11: =+HistData!AW6 -> 0 | H11: =+HistData!AV6 -> 0 | AD11: Lower | AE11: Upper
A12: 166 | B12: 1 | C12: =IF(B12="",NA(),B12+C11) -> 1 | D12: =$R$1*F12 -> 0 | E12: =$S$1*F12 -> 0 | F12: =HistData!GQ7 -> 0 | G12: =+HistData!AW7 -> 0 | H12: =+HistData!AV7 -> 0 | AC12: 167 | AD12: 0.37395703 | AE12: 1.3355608 | AI12: SW | AJ12: Lower | AK12: Upper
A13: 167 | B13: 7 | C13: =IF(B13="",NA(),B13+C12) -> 8 | D13: =$R$1*F13 -> 0.46017334 | E13: =$S$1*F13 -> 1.6434762 | F13: =HistData!GQ8 -> 6.5739048e-05 | G13: =+HistData!AW8 -> 7.1428571 | H13: =+HistData!AV8 -> 7.1428571 | K13: =IF(B13="","",C13/F13) -> 121693.27 | AC13: 168 | AD13: 1.2071172 | AE13: 4.3111328 | AI13: 25 | AJ13: 8 | AK13: 28
A14: 168 | B14: 13 | C14: =IF(B14="",NA(),B14+C13) -> 21 | D14: =$R$1*F14 -> 1.1724318 | E14: =$S$1*F14 -> 4.1872565 | F14: =HistData!GQ9 -> 0.00016749026 | G14: =+HistData!AW9 -> 23.857143 | H14: =+HistData!AV9 -> 16.714286 | K14: =IF(B14="","",C14/F14) -> 125380.42 | AC14: 169 | AD14: 2.481626 | AE14: 8.86295 | AI14: 26 | AJ14: 111 | AK14: 395
A15: 169 | B15: 7 | C15: =IF(B15="",NA(),B15+C14) -> 28 | D15: =$R$1*F15 -> 2.7092981 | E15: =$S$1*F15 -> 9.6760647 | F15: =HistData!GQ10 -> 0.00038704259 | G15: =+HistData!AW10 -> 51.982143 | H15: =+HistData!AV10 -> 28.125 | K15: =IF(B15="","",C15/F15) -> 72343.46 | AC15: 170 | AD15: 7.780685 | AE15: 27.788161 | AI15: 27 | AJ15: 471 | AK15: 1681
A16: 170 | B16: 1 | C16: =IF(B16="",NA(),B16+C15) -> 29 | D16: =$R$1*F16 -> 6.8325806 | E16: =$S$1*F16 -> 24.402073 | F16: =HistData!GQ11 -> 0.00097608294 | G16: =+HistData!AW11 -> 139.09325 | H16: =+HistData!AV11 -> 87.111111 | K16: =IF(B16="","",C16/F16) -> 29710.59 | AC16: 171 | AD16: 13.834293 | AE16: 49.408188 | AI16: 28 | AJ16: 1055 | AK16: 3770
A17: 171 | B17: 8 | C17: =IF(B17="",NA(),B17+C16) -> 37 | D17: =$R$1*F17 -> 13.985804 | E17: =$S$1*F17 -> 49.949298 | F17: =HistData!GQ12 -> 0.0019979719 | G17: =+HistData!AW12 -> 303.49325 | H17: =+HistData!AV12 -> 164.4 | K17: =IF(B17="","",C17/F17) -> 18518.779 | AC17: 172 | AD17: 29.105139 | AE17: 103.94692 | AI17: 29 | AJ17: 2009 | AK17: 7175
A18: 172 | B18: 549 | C18: =IF(B18="",NA(),B18+C17) -> 586 | D18: =$R$1*F18 -> 16.278447 | E18: =$S$1*F18 -> 58.137311 | F18: =HistData!GQ13 -> 0.0023254925 | G18: =+HistData!AW13 -> 330.79325 | H18: =+HistData!AV13 -> 27.3 | K18: =IF(B18="","",C18/F18) -> 251989.64 | AC18: 173 | AD18: 38.553726 | AE18: 137.69188 | AI18: 30 | AJ18: 2985 | AK18: 10660
A19: 173 | B19: 2 | C19: =IF(B19="",NA(),B19+C18) -> 588 | D19: =$R$1*F19 -> 22.424283 | E19: =$S$1*F19 -> 80.086724 | F19: =HistData!GQ14 -> 0.0032034689 | G19: =+HistData!AW14 -> 459.59325 | H19: =+HistData!AV14 -> 128.8 | K19: =IF(B19="","",C19/F19) -> 183551.02 | AC19: 174 | AD19: 44.477237 | AE19: 158.84728 | AI19: 31 | AJ19: 4075 | AK19: 14544
A20: 174 | B20: 0 | C20: =IF(B20="",NA(),B20+C19) -> 588 | D20: =$R$1*F20 -> 33.228379 | E20: =$S$1*F20 -> 118.67278 | F20: =HistData!GQ15 -> 0.0047469114 | G20: =+HistData!AW15 -> 707.19325 | H20: =+HistData!AV15 -> 247.6 | K20: =IF(B20="","",C20/F20) -> 123870.02 | AC20: 175 | AD20: 70.659865 | AE20: 252.35666 | AI20: 32 | AJ20: 5093 | AK20: 18190
A21: 175 | B21: 626 | C21: =IF(B21="",NA(),B21+C20) -> 1214 | D21: =$R$1*F21 -> 46.757142 | E21: =$S$1*F21 -> 166.98979 | F21: =HistData!GQ16 -> 0.0066795918 | G21: =+HistData!AW16 -> 949.09325 | H21: =+HistData!AV16 -> 241.9 | K21: =IF(B21="","",C21/F21) -> 181747.63 | AC21: 176 | AD21: 91.983603 | AE21: 328.51287 | AI21: 33 | AJ21: 5913 | AK21: 21119
A22: 176 | B22: 517 | C22: =IF(B22="",NA(),B22+C21) -> 1731 | D22: =$R$1*F22 -> 53.264897 | E22: =$S$1*F22 -> 190.23177 | F22: =HistData!GQ17 -> 0.0076092709 | G22: =+HistData!AW17 -> 1009.9933 | H22: =+HistData!AV17 -> 60.9 | K22: =IF(B22="","",C22/F22) -> 227485.66 | AC22: 177 | AD22: 110.71163 | AE22: 395.39867 | AI22: 34 | AJ22: 6424 | AK22: 22943
A23: 177 | B23: 724 | C23: =IF(B23="",NA(),B23+C22) -> 2455 | D23: =$R$1*F23 -> 68.929786 | E23: =$S$1*F23 -> 246.17781 | F23: =HistData!GQ18 -> 0.0098471123 | G23: =+HistData!AW18 -> 1215.5933 | H23: =+HistData!AV18 -> 205.6 | K23: =IF(B23="","",C23/F23) -> 249311.67 | AC23: 178 | AD23: 145.33138 | AE23: 519.04065 | AI23: 35 | AJ23: 6766 | AK23: 24165
A24: 178 | B24: 872 | C24: =IF(B24="",NA(),B24+C23) -> 3327 | D24: =$R$1*F24 -> 104.90045 | E24: =$S$1*F24 -> 374.64447 | F24: =HistData!GQ19 -> 0.014985779 | G24: =+HistData!AW19 -> 1591.5933 | H24: =+HistData!AV19 -> 376 | K24: =IF(B24="","",C24/F24) -> 222010.48 | AC24: 179 | AD24: 205.8597 | AE24: 735.2132 | AI24: 36 | AJ24: 6971 | AK24: 24896
A25: 179 | B25: 312 | C25: =IF(B25="",NA(),B25+C24) -> 3639 | D25: =$R$1*F25 -> 147.46984 | E25: =$S$1*F25 -> 526.678 | F25: =HistData!GQ20 -> 0.02106712 | G25: =+HistData!AW20 -> 2221.1933 | H25: =+HistData!AV20 -> 629.6 | K25: =IF(B25="","",C25/F25) -> 172733.62 | AC25: 180 | AD25: 247.97709 | AE25: 885.63247 | AI25: 37 | AJ25: 7000 | AK25: 25000
A26: 180 | B26: 3293 | C26: =IF(B26="",NA(),B26+C25) -> 6932 | D26: =$R$1*F26 -> 185.94855 | E26: =$S$1*F26 -> 664.10196 | F26: =HistData!GQ21 -> 0.026564078 | G26: =+HistData!AW21 -> 2687.9933 | H26: =+HistData!AV21 -> 466.8 | K26: =IF(B26="","",C26/F26) -> 260953.91 | AC26: 181 | AD26: 310.37239 | AE26: 1108.4728
A27: 181 | B27: 1179 | C27: =IF(B27="",NA(),B27+C26) -> 8111 | D27: =$R$1*F27 -> 247.36432 | E27: =$S$1*F27 -> 883.44401 | F27: =HistData!GQ22 -> 0.03533776 | G27: =+HistData!AW22 -> 3326.0933 | H27: =+HistData!AV22 -> 638.1 | K27: =IF(B27="","",C27/F27) -> 229527.85 | AC27: 182 | AD27: 378.51457 | AE27: 1351.8377
A28: 182 | B28: 4691 | C28: =IF(B28="",NA(),B28+C27) -> 12802 | D28: =$R$1*F28 -> 298.6549 | E28: =$S$1*F28 -> 1066.6246 | F28: =HistData!GQ23 -> 0.042664985 | G28: =+HistData!AW23 -> 3877.5933 | H28: =+HistData!AV23 -> 551.5 | K28: =IF(B28="","",C28/F28) -> 300058.7 | AC28: 183 | AD28: 425.82273 | AE28: 1520.7955
A29: 183 | B29: 4513 | C29: =IF(B29="",NA(),B29+C28) -> 17315 | D29: =$R$1*F29 -> 333.7934 | E29: =$S$1*F29 -> 1192.1193 | F29: =HistData!GQ24 -> 0.047684771 | G29: =+HistData!AW24 -> 4424.4933 | H29: =+HistData!AV24 -> 546.9 | J29: =IF(B29="","",C29/F32) -> 251542.01 | K29: =IF(B29="","",C29/F29) -> 363113.83 | L29: =IF(B29="","",C29/F26) -> 651820.09 | N29: =IF(B29="","",C29/HistData!CU24) -> 497015.06 | P29: 5% of the way through the esc is way too early for inseason projections but they start here anyways | AC29: 184 | AD29: 470.73517 | AE29: 1681.197
A30: 184 | B30: 5432 | C30: =IF(B30="",NA(),B30+C29) -> 22747 | D30: =$R$1*F30 -> 360.76078 | E30: =$S$1*F30 -> 1288.4313 | F30: =HistData!GQ25 -> 0.051537254 | G30: =+HistData!AW25 -> 4912.7933 | H30: =+HistData!AV25 -> 488.3 | J30: =IF(B30="","",C30/F33) -> 269143.48 | K30: =IF(B30="","",C30/F30) -> 441370.05 | L30: =IF(B30="","",C30/F27) -> 643702.37 | N30: =IF(B30="","",C30/HistData!CU25) -> 572606.21 | AC30: 185 | AD30: 538.9056 | AE30: 1924.6629
A31: 185 | B31: 2001 | C31: =IF(B31="",NA(),B31+C30) -> 24748 | D31: =$R$1*F31 -> 410.2808 | E31: =$S$1*F31 -> 1465.2886 | F31: =HistData!GQ26 -> 0.058611543 | G31: =+HistData!AW26 -> 5458.0933 | H31: =+HistData!AV26 -> 545.3 | J31: =IF(B31="","",C31/F34) -> 265259.19 | K31: =IF(B31="","",C31/F31) -> 422237.65 | L31: =IF(B31="","",C31/F28) -> 580054.11 | N31: =IF(B31="","",C31/HistData!CU26) -> 542223.55 | AC31: 186 | AD31: 633.00199 | AE31: 2260.7214
A32: 186 | B32: 3651 | C32: =IF(B32="",NA(),B32+C31) -> 28399 | D32: =$R$1*F32 -> 481.84794 | E32: =$S$1*F32 -> 1720.8855 | F32: =HistData!GQ27 -> 0.06883542 | G32: =+HistData!AW27 -> 6163.5933 | H32: =+HistData!AV27 -> 705.5 | J32: =IF(B32="","",C32/F35) -> 283022.8 | K32: =IF(B32="","",C32/F32) -> 412563.76 | L32: =IF(B32="","",C32/F29) -> 595557.02 | N32: =IF(B32="","",C32/HistData!CU27) -> 528882.69 | AC32: 187 | AD32: 689.4825 | AE32: 2462.4375
A33: 187 | B33: 6184 | C33: =IF(B33="",NA(),B33+C32) -> 34583 | D33: =$R$1*F33 -> 591.6138 | E33: =$S$1*F33 -> 2112.9064 | F33: =HistData!GQ28 -> 0.084516258 | G33: =+HistData!AW28 -> 7844.0933 | H33: =+HistData!AV28 -> 1680.5 | J33: =IF(B33="","",C33/F36) -> 274673.28 | K33: =IF(B33="","",C33/F33) -> 409187.55 | L33: =IF(B33="","",C33/F30) -> 671029.16 | N33: =IF(B33="","",C33/HistData!CU28) -> 546462.27 | AC33: 188 | AD33: 772.20773 | AE33: 2757.8847
A34: 188 | B34: 5338 | C34: =IF(B34="",NA(),B34+C33) -> 39921 | D34: =$R$1*F34 -> 653.08199 | E34: =$S$1*F34 -> 2332.4357 | F34: =HistData!GQ29 -> 0.093297427 | G34: =+HistData!AW29 -> 8435.6933 | H34: =+HistData!AV29 -> 591.6 | J34: =IF(B34="","",C34/F37) -> 285224.93 | K34: =IF(B34="","",C34/F34) -> 427889.61 | L34: =IF(B34="","",C34/F31) -> 681111.57 | N34: =IF(B34="","",C34/HistData!CU29) -> 551384.01 | AC34: 189 | AD34: 817.66124 | AE34: 2920.2187
A35: 189 | B35: 7942 | C35: =IF(B35="",NA(),B35+C34) -> 47863 | D35: =$R$1*F35 -> 702.39216 | E35: =$S$1*F35 -> 2508.5434 | F35: =HistData!GQ30 -> 0.10034174 | G35: =+HistData!AW30 -> 9109.3933 | H35: =+HistData!AV30 -> 673.7 | J35: =IF(B35="","",C35/F38) -> 282923.23 | K35: =IF(B35="","",C35/F35) -> 476999.91 | L35: =IF(B35="","",C35/F32) -> 695325.17 | N35: =IF(B35="","",C35/HistData!CU30) -> 579279.6 | AC35: 190 | AD35: 967.487 | AE35: 3455.3107
A36: 190 | B36: 5410 | C36: =IF(B36="",NA(),B36+C35) -> 53273 | D36: =$R$1*F36 -> 881.34163 | E36: =$S$1*F36 -> 3147.6487 | F36: =HistData!GQ31 -> 0.12590595 | G36: =+HistData!AW31 -> 10985.393 | H36: =+HistData!AV31 -> 1876 | J36: =IF(B36="","",C36/F39) -> 281659.71 | K36: =IF(B36="","",C36/F36) -> 423117.42 | L36: =IF(B36="","",C36/F33) -> 630328.43 | N36: =IF(B36="","",C36/HistData!CU31) -> 545061.02 | AC36: 191 | AD36: 1055.4737 | AE36: 3769.5488
A37: 191 | B37: 5433 | C37: =IF(B37="",NA(),B37+C36) -> 58706 | D37: =$R$1*F37 -> 979.74254 | E37: =$S$1*F37 -> 3499.0805 | F37: =HistData!GQ32 -> 0.13996322 | G37: =+HistData!AW32 -> 11870.793 | H37: =+HistData!AV32 -> 885.4 | J37: =IF(B37="","",C37/F40) -> 287600.68 | K37: =IF(B37="","",C37/F37) -> 419438.77 | L37: =IF(B37="","",C37/F34) -> 629234.93 | N37: =IF(B37="","",C37/HistData!CU32) -> 530373.96 | AC37: 192 | AD37: 1240.4081 | AE37: 4430.0289
A38: 192 | B38: 6808 | C38: =IF(B38="",NA(),B38+C37) -> 65514 | D38: =$R$1*F38 -> 1184.2117 | E38: =$S$1*F38 -> 4229.3276 | F38: =HistData!GQ33 -> 0.1691731 | G38: =+HistData!AW33 -> 14686.793 | H38: =+HistData!AV33 -> 2816 | J38: =IF(B38="","",C38/F41) -> 286435.94 | K38: =IF(B38="","",C38/F38) -> 387260.14 | L38: =IF(B38="","",C38/F35) -> 652908.77 | N38: =IF(B38="","",C38/HistData!CU33) -> 498264.96 | AC38: 193 | AD38: 1363.885 | AE38: 4871.0179
A39: 193 | B39: 5114 | C39: =IF(B39="",NA(),B39+C38) -> 70628 | D39: =$R$1*F39 -> 1323.9771 | E39: =$S$1*F39 -> 4728.4895 | F39: =HistData!GQ34 -> 0.18913958 | G39: =+HistData!AW34 -> 16163.493 | H39: =+HistData!AV34 -> 1476.7 | J39: =IF(B39="","",C39/F42) -> 291006.46 | K39: =IF(B39="","",C39/F39) -> 373417.34 | L39: =IF(B39="","",C39/F36) -> 560958.41 | N39: =IF(B39="","",C39/HistData!CU34) -> 469537.93 | AC39: 194 | AD39: 1470.0081 | AE39: 5250.0291
A40: 194 | B40: 5290 | C40: =IF(B40="",NA(),B40+C39) -> 75918 | D40: =$R$1*F40 -> 1428.8631 | E40: =$S$1*F40 -> 5103.0825 | F40: =HistData!GQ35 -> 0.2041233 | G40: =+HistData!AW35 -> 17623.193 | H40: =+HistData!AV35 -> 1459.7 | J40: =IF(B40="","",C40/F43) -> 283681.06 | K40: =IF(B40="","",C40/F40) -> 371922.26 | L40: =IF(B40="","",C40/F37) -> 542413.93 | N40: =IF(B40="","",C40/HistData!CU35) -> 448210.64 | AC40: 195 | AD40: 1644.5464 | AE40: 5873.3802
A41: 195 | B41: 6436 | C41: =IF(B41="",NA(),B41+C40) -> 82354 | D41: =$R$1*F41 -> 1601.0491 | E41: =$S$1*F41 -> 5718.0324 | F41: =HistData!GQ36 -> 0.2287213 | G41: =+HistData!AW36 -> 19531.293 | H41: =+HistData!AV36 -> 1908.1 | J41: =IF(B41="","",C41/F44) -> 291973.44 | K41: =IF(B41="","",C41/F41) -> 360062.67 | L41: =IF(B41="","",C41/F38) -> 486803.15 | N41: =IF(B41="","",C41/HistData!CU36) -> 438436.12 | AC41: 196 | AD41: 1722.0801 | AE41: 6150.2861
... A90: 244 | B90: 417 | C90: =IF(B90="",NA(),B90+C89) -> 228974 | D90: =$R$1*F90 -> 6912.3059 | E90: =$S$1*F90 -> 24686.807 | F90: =HistData!GQ85 -> 0.98747228 | G90: =+HistData!AW85 -> 76606.9 | H90: =+HistData!AV85 -> 306.22222 | J90: =IF(B90="","",C90/F93) -> 230030.21 | K90: =IF(B90="","",C90/F90) -> 231878.92 | L90: =IF(B90="","",C90/F87) -> 235104.33 | N90: =IF(B90="","",C90/HistData!CU85) -> 232943.57 | AC90: 245 | AD90: 6929.9518 | AE90: 24749.828
...

Sheet Charts
B2: Redoubt sockeye salmon weir count charts

Sheet HistData
A1: Table . Historical sockeye daily weir counts | AW1: 10-year | AY1: Table . Historical sockeye daily esc. Proportions | CT1: 10-year | CU1: all-year | CW1: Table . Historical sockeye cum counts
AV2: 10-year | AW2: Cum | CT2: Cum | CU2: Cum | ER2: 10-year | ES2: 1983 current | GQ2: 10-year | GR2: 1983 current
A3: Date | B3: 1953 | C3: 1954 | D3: 1955 | E3: 1982 | F3: 1983 | G3: 1984 | H3: 1985 | I3: 1986 | J3: 1987 | K3: 1988 | L3: 1989 | M3: 1990 | N3: 1991 | O3: 1992 | P3: 1993 | Q3: 1994 | R3: 1995 | S3: 1996 | T3: 1997 | U3: 1998 | V3: 1999 | W3: 2000 | X3: 2001 | Y3: 2002 | Z3: 2003 | AA3: 2004 | AB3: 2005 | AC3: 2006 | AD3: 2007 | AE3: 2008 | AF3: 2009 | AG3: 2010 | AH3: 2011 | AI3: 2012 | AJ3: 2013 | AK3: 2014 | AL3: 2015 | AM3: 2016 | AN3: 2017 | AO3: 2018 | AP3: 2019 | AQ3: 2020 | AR3: 2021 | AS3: 2022 | AT3: 2023 | AU3: 2024 | AV3: Average | AW3: Daily | AY3: Date | AZ3: 1953 | BA3: 1954 | BB3: 1955 | BC3: 1982 | BD3: 1983 | BE3: 1984 | BF3: 1985 | BG3: 1986 | BH3: 1987 | BI3: 1988 | BJ3: 1989 | BK3: 1990 | BL3: 1991 | BM3: 1992 | BN3: 1993 | BO3: 1994 | BP3: 1995 | BQ3: 1996 | BR3: 1997 | BS3: 1998 | BT3: 1999 | BU3: 2000 | BV3: 2001 | BW3: 2002 | BX3: 2003 | BY3: 2004 | BZ3: 2005 | CA3: 2006 | CB3: 2007 | CC3: 2008 | CD3: 2009 | CE3: 2010 | CF3: 2011 | CG3: 2012 | CH3: 2013 | CI3: 2014 | CJ3: 2015 | CK3: 2016 | CL3: 2017 | CM3: 2018 | CN3: 2019 | CO3: 2020 | CP3: 2021 | CQ3: 2022 | CR3: 2023 | CS3: 2024 | CT3: Prop. | CU3: Prop. | CW3: Date | CX3: 1953 | CY3: 1954 | CZ3: 1955 | DA3: 1982 | DB3: 1983 | DC3: 1984 | DD3: 1985 | DE3: 1986 | DF3: 1987 | DG3: 1988 | DH3: 1989 | DI3: 1990 | DJ3: 1991 | DK3: 1992 | DL3: 1993 | DM3: 1994 | DN3: 1995 | DO3: 1996 | DP3: 1997 | DQ3: 1998 | DR3: 1999 | DS3: 2000 | DT3: 2001 | DU3: 2002 | DV3: 2003 | DW3: 2004 | DX3: 2005 | DY3: 2006 | DZ3: 2007 | EA3: 2008 | EB3: 2009 | EC3: 2010 | ED3: 2011 | EE3: 2012 | EF3: 2013 | EG3: 2014 | EH3: 2015 | EI3: 2016 | EJ3: 2017 | EK3: 2018 | EL3: 2019 | EM3: 2020 | EN3: 2021 | EO3: 2022 | EP3: 2023 | EQ3: 2024 | ER3: Average | ES3: Average | EV3: Date | EW3: 1979 | EX3: 1980 | EY3: 1981 | EZ3: 1982 | FA3: 1983 | FB3: 1984 | FC3: 1985 | FD3: 1986 | FE3: 1987 | FF3: 1988 | FG3: 1989 | FH3: 1990 | FI3: 1991 | FJ3: 1992 | FK3: 1993 | FL3: 1994 | FM3: 1995 | FN3: 1996 | FO3: 1997 | FP3: 1998 | FQ3: 1999 | FR3: 2000 | FS3: 2001 | FT3: 2002 | FU3: 2003 | FV3: 2004 | FW3: 2005 | FX3: 2006 | FY3: 2007 | FZ3: 2008 | GA3: 2009 | GB3: 2010 | GC3: 2011 | GD3: 2012 | GE3: 2013 | GF3: 2014 | GG3: 2015 | GH3: 2016 | GI3: 2017 | GJ3: 2018 | GK3: 2019 | GL3: 2020 | GM3: 2021 | GN3: 2022 | GO3: 2023 | GP3: 2024 | GQ3: Average | GR3: Average
A5: 164 | R5: 0 | W5: 0 | Y5: 3 | Z5: 2 | AA5: 6 | AB5: 0 | AE5: 0 | AQ5: 0 | AW5: =AW4+AV5 -> 0 | AY5: 164 | AZ5: =B5/B$104 -> 0 | BA5: =C5/C$104 -> 0 | BB5: =D5/D$104 -> 0 | BC5: =E5/E$104 -> 0 | BD5: =F5/F$104 -> 0 | BE5: =G5/G$104 -> 0 | BF5: =H5/H$104 -> 0 | BG5: =I5/I$104 -> 0 | ... BR5: =T5/T$104 -> 0 | BT5: =V5/V$104 -> 0 | BU5: =W5/W$104 -> 0 | BV5: =X5/X$104 -> 0 | BW5: =Y5/Y$104 -> 0.00012539475 | BX5: =Z5/Z$104 -> 2.8629096e-05 | BY5: =AA5/AA$104 -> 7.7872523e-05 | BZ5: =AB5/AB$104 -> 0 | CA5: =AC5/AC$104 -> 0 | ... CS5: =AU5/AU$104 -> 0 | CT5: =CT4+AVERAGE(CJ5:CS5) -> 0 | CU5: =CU4+AVERAGE(BD5:CS5) -> 5.6560089e-06 | CW5: 164 | CX5: =B5 -> 0 | CY5: =C5 -> 0 | CZ5: =D5 -> 0 | DA5: =E5 -> 0 | DB5: =F5 -> 0 | DC5: =G5 -> 0 | DD5: =H5 -> 0 | DE5: =I5 -> 0 | ... DP5: =T5 -> 0 | DR5: =V5 -> 0 | DS5: =W5 -> 0 | DT5: =X5 -> 0 | DU5: =Y5 -> 3 | DV5: =Z5 -> 2 | DW5: =AA5 -> 6 | DX5: =AB5 -> 0 | DY5: =AC5 -> 0 | ... EQ5: =AU5 -> 0 | ER5: =AVERAGE(EH5:EQ5) -> 0 | ES5: =AVERAGE(DB5:EQ5) -> 0.26829268 | EV5: 164 | EW5: =CX5/CX$102 -> 0 | EX5: =CY5/CY$102 -> 0 | EY5: =CZ5/CZ$102 -> 0 | EZ5: =DA5/DA$102 -> 0 | FA5: =DB5/DB$102 -> 0 | FB5: =DC5/DC$102 -> 0 | FC5: =DD5/DD$102 -> 0 | FD5: =DE5/DE$102 -> 0 | ... FO5: =DP5/DP$102 -> 0 | FQ5: =DR5/DR$102 -> 0 | FR5: =DS5/DS$102 -> 0 | FS5: =DT5/DT$102 -> 0 | FT5: =DU5/DU$102 -> 0.00012539475 | FU5: =DV5/DV$102 -> 2.8629096e-05 | FV5: =DW5/DW$102 -> 7.7872523e-05 | FW5: =DX5/DX$102 -> 0 | FX5: =DY5/DY$102 -> 0 | ... GP5: =EQ5/EQ$102 -> 0 | GQ5: =AVERAGE(GG5:GP5) -> 0 | GR5: =AVERAGE(FA5:GP5) -> 5.6560089e-06
A6: 165 | P6: 0 | W6: 0 | Y6: 2 | Z6: 0 | AA6: 29 | AB6: 0 | AE6: 0 | AQ6: 0 | AT6: 0 | AW6: =AW5+AV6 -> 0 | AY6: 165 | AZ6: =B6/B$104 -> 0 | BA6: =C6/C$104 -> 0 | BB6: =D6/D$104 -> 0 | BC6: =E6/E$104 -> 0 | BD6: =F6/F$104 -> 0 | BE6: =G6/G$104 -> 0 | BF6: =H6/H$104 -> 0 | BG6: =I6/I$104 -> 0 | ... BR6: =T6/T$104 -> 0 | BT6: =V6/V$104 -> 0 | BU6: =W6/W$104 -> 0 | BV6: =X6/X$104 -> 0 | BW6: =Y6/Y$104 -> 8.3596497e-05 | BX6: =Z6/Z$104 -> 0 | BY6: =AA6/AA$104 -> 0.00037638386 | BZ6: =AB6/AB$104 -> 0 | CA6: =AC6/AC$104 -> 0 | ... CS6: =AU6/AU$104 -> 0 | CT6: =CT5+AVERAGE(CJ6:CS6) -> 0 | CU6: =CU5+AVERAGE(BD6:CS6) -> 1.6875042e-05 | CW6: 165 | CX6: =CX5+B6 -> 0 | CY6: =CY5+C6 -> 0 | CZ6: =CZ5+D6 -> 0 | DA6: =DA5+E6 -> 0 | DB6: =DB5+F6 -> 0 | DC6: =DC5+G6 -> 0 | DD6: =DD5+H6 -> 0 | DE6: =DE5+I6 -> 0 | ... DP6: =DP5+T6 -> 0 | DR6: =DR5+V6 -> 0 | DS6: =DS5+W6 -> 0 | DT6: =DT5+X6 -> 0 | DU6: =DU5+Y6 -> 5 | DV6: =DV5+Z6 -> 2 | DW6: =DW5+AA6 -> 35 | DX6: =DX5+AB6 -> 0 | DY6: =DY5+AC6 -> 0 | ... EQ6: =EQ5+AU6 -> 0 | ER6: =AVERAGE(EH6:EQ6) -> 0 | ES6: =AVERAGE(DB6:EQ6) -> 1.0243902 | EV6: 165 | EW6: =CX6/CX$102 -> 0 | EX6: =CY6/CY$102 -> 0 | EY6: =CZ6/CZ$102 -> 0 | EZ6: =DA6/DA$102 -> 0 | FA6: =DB6/DB$102 -> 0 | FB6: =DC6/DC$102 -> 0 | FC6: =DD6/DD$102 -> 0 | FD6: =DE6/DE$102 -> 0 | ... FO6: =DP6/DP$102 -> 0 | FQ6: =DR6/DR$102 -> 0 | FR6: =DS6/DS$102 -> 0 | FS6: =DT6/DT$102 -> 0 | FT6: =DU6/DU$102 -> 0.00020899124 | FU6: =DV6/DV$102 -> 2.8629096e-05 | FV6: =DW6/DW$102 -> 0.00045425638 | FW6: =DX6/DX$102 -> 0 | FX6: =DY6/DY$102 -> 0 | ... GP6: =EQ6/EQ$102 -> 0 | GQ6: =AVERAGE(GG6:GP6) -> 0 | GR6: =AVERAGE(FA6:GP6) -> 1.6875042e-05
A7: 166 | P7: 0 | S7: 0 | W7: 0 | Y7: 1 | Z7: 2 | AA7: 18 | AB7: 0 | AE7: 0 | AQ7: 0 | AT7: 0 | AU7: 0 | AW7: =AW6+AV7 -> 0 | AY7: 166 | AZ7: =B7/B$104 -> 0 | BA7: =C7/C$104 -> 0 | BB7: =D7/D$104 -> 0 | BC7: =E7/E$104 -> 0 | BD7: =F7/F$104 -> 0 | BE7: =G7/G$104 -> 0 | BF7: =H7/H$104 -> 0 | BG7: =I7/I$104 -> 0 | ... BR7: =T7/T$104 -> 0 | BT7: =V7/V$104 -> 0 | BU7: =W7/W$104 -> 0 | BV7: =X7/X$104 -> 0 | BW7: =Y7/Y$104 -> 4.1798249e-05 | BX7: =Z7/Z$104 -> 2.8629096e-05 | BY7: =AA7/AA$104 -> 0.00023361757 | BZ7: =AB7/AB$104 -> 0 | CA7: =AC7/AC$104 -> 0 | ... CS7: =AU7/AU$104 -> 0 | CT7: =CT6+AVERAGE(CJ7:CS7) -> 0 | CU7: =CU6+AVERAGE(BD7:CS7) -> 2.4290772e-05 | CW7: 166 | CX7: =CX6+B7 -> 0 | CY7: =CY6+C7 -> 0 | CZ7: =CZ6+D7 -> 0 | DA7: =DA6+E7 -> 0 | DB7: =DB6+F7 -> 0 | DC7: =DC6+G7 -> 0 | DD7: =DD6+H7 -> 0 | DE7: =DE6+I7 -> 0 | ... DP7: =DP6+T7 -> 0 | DR7: =DR6+V7 -> 0 | DS7: =DS6+W7 -> 0 | DT7: =DT6+X7 -> 0 | DU7: =DU6+Y7 -> 6 | DV7: =DV6+Z7 -> 4 | DW7: =DW6+AA7 -> 53 | DX7: =DX6+AB7 -> 0 | DY7: =DY6+AC7 -> 0 | ... EQ7: =EQ6+AU7 -> 0 | ER7: =AVERAGE(EH7:EQ7) -> 0 | ES7: =AVERAGE(DB7:EQ7) -> 1.5365854 | EV7: 166 | EW7: =CX7/CX$102 -> 0 | EX7: =CY7/CY$102 -> 0 | EY7: =CZ7/CZ$102 -> 0 | EZ7: =DA7/DA$102 -> 0 | FA7: =DB7/DB$102 -> 0 | FB7: =DC7/DC$102 -> 0 | FC7: =DD7/DD$102 -> 0 | FD7: =DE7/DE$102 -> 0 | ... FO7: =DP7/DP$102 -> 0 | FQ7: =DR7/DR$102 -> 0 | FR7: =DS7/DS$102 -> 0 | FS7: =DT7/DT$102 -> 0 | FT7: =DU7/DU$102 -> 0.00025078949 | FU7: =DV7/DV$102 -> 5.7258192e-05 | FV7: =DW7/DW$102 -> 0.00068787395 | FW7: =DX7/DX$102 -> 0 | FX7: =DY7/DY$102 -> 0 | ... GP7: =EQ7/EQ$102 -> 0 | GQ7: =AVERAGE(GG7:GP7) -> 0 | GR7: =AVERAGE(FA7:GP7) -> 2.4290772e-05
A8: 167 | P8: 0 | Q8: 0 | S8: 9 | W8: 1 | X8: 11 | Y8: 4 | Z8: 3 | AA8: 29 | AB8: 0 | AE8: 1 | AM8: 1 | AP8: 26 | AQ8: 0 | AR8: 3 | AS8: 1 | AT8: 12 | AU8: 7 | AV8: =AVERAGE(AL8:AU8) -> 7.1428571 | AW8: =AW7+AV8 -> 7.1428571 | AY8: 167 | AZ8: =B8/B$104 -> 0 | BA8: =C8/C$104 -> 0 | BB8: =D8/D$104 -> 0 | BC8: =E8/E$104 -> 0 | BD8: =F8/F$104 -> 0 | BE8: =G8/G$104 -> 0 | BF8: =H8/H$104 -> 0 | BG8: =I8/I$104 -> 0 | ... BR8: =T8/T$104 -> 0 | BT8: =V8/V$104 -> 0 | BU8: =W8/W$104 -> 0.00033921303 | BV8: =X8/X$104 -> 0.0030046435 | BW8: =Y8/Y$104 -> 0.00016719299 | BX8: =Z8/Z$104 -> 4.2943644e-05 | BY8: =AA8/AA$104 -> 0.00037638386 | BZ8: =AB8/AB$104 -> 0 | CA8: =AC8/AC$104 -> 0 | ... CS8: =AU8/AU$104 -> 3.3285307e-05 | CT8: =CT7+AVERAGE(CJ8:CS8) -> 6.5739048e-05 | CU8: =CU7+AVERAGE(BD8:CS8) -> 0.0001503444 | CW8: 167 | CX8: =CX7+B8 -> 0 | CY8: =CY7+C8 -> 0 | CZ8: =CZ7+D8 -> 0 | DA8: =DA7+E8 -> 0 | DB8: =DB7+F8 -> 0 | DC8: =DC7+G8 -> 0 | DD8: =DD7+H8 -> 0 | DE8: =DE7+I8 -> 0 | ... DP8: =DP7+T8 -> 0 | DR8: =DR7+V8 -> 0 | DS8: =DS7+W8 -> 1 | DT8: =DT7+X8 -> 11 | DU8: =DU7+Y8 -> 10 | DV8: =DV7+Z8 -> 7 | DW8: =DW7+AA8 -> 82 | DX8: =DX7+AB8 -> 0 | DY8: =DY7+AC8 -> 0 | ... EQ8: =EQ7+AU8 -> 7 | ER8: =AVERAGE(EH8:EQ8) -> 5 | ES8: =AVERAGE(DB8:EQ8) -> 4.1707317 | EV8: 167 | EW8: =CX8/CX$102 -> 0 | EX8: =CY8/CY$102 -> 0 | EY8: =CZ8/CZ$102 -> 0 | EZ8: =DA8/DA$102 -> 0 | FA8: =DB8/DB$102 -> 0 | FB8: =DC8/DC$102 -> 0 | FC8: =DD8/DD$102 -> 0 | FD8: =DE8/DE$102 -> 0 | ... FO8: =DP8/DP$102 -> 0 | FQ8: =DR8/DR$102 -> 0 | FR8: =DS8/DS$102 -> 0.00033921303 | FS8: =DT8/DT$102 -> 0.0030046435 | FT8: =DU8/DU$102 -> 0.00041798249 | FU8: =DV8/DV$102 -> 0.00010020184 | FV8: =DW8/DW$102 -> 0.0010642578 | FW8: =DX8/DX$102 -> 0 | FX8: =DY8/DY$102 -> 0 | ... GP8: =EQ8/EQ$102 -> 3.3285307e-05 | GQ8: =AVERAGE(GG8:GP8) -> 6.5739048e-05 | GR8: =AVERAGE(FA8:GP8) -> 0.0001503444
A9: 168 | P9: 0 | Q9: 0 | R9: 6 | S9: 3 | W9: 0 | X9: 6 | Y9: 24 | Z9: 3 | AA9: 24 | AB9: 5 | AE9: 0 | AJ9: 41 | AM9: 3 | AP9: 7 | AQ9: 1 | AR9: 4 | AS9: 2 | AT9: 100 | AU9: 0 | AV9: =AVERAGE(AL9:AU9) -> 16.714286 | AW9: =AW8+AV9 -> 23.857143 | AY9: 168 | AZ9: =B9/B$104 -> 0 | BA9: =C9/C$104 -> 0 | BB9: =D9/D$104 -> 0 | BC9: =E9/E$104 -> 0 | BD9: =F9/F$104 -> 0 | BE9: =G9/G$104 -> 0 | BF9: =H9/H$104 -> 0 | BG9: =I9/I$104 -> 0 | ... BR9: =T9/T$104 -> 0 | BT9: =V9/V$104 -> 0 | BU9: =W9/W$104 -> 0 | BV9: =X9/X$104 -> 0.0016388965 | BW9: =Y9/Y$104 -> 0.001003158 | BX9: =Z9/Z$104 -> 4.2943644e-05 | BY9: =AA9/AA$104 -> 0.00031149009 | BZ9: =AB9/AB$104 -> 7.6282306e-05 | CA9: =AC9/AC$104 -> 0 | ... CS9: =AU9/AU$104 -> 0 | CT9: =CT8+AVERAGE(CJ9:CS9) -> 0.00016749026 | CU9: =CU8+AVERAGE(BD9:CS9) -> 0.00027897242 | CW9: 168 | CX9: =CX8+B9 -> 0 | CY9: =CY8+C9 -> 0 | CZ9: =CZ8+D9 -> 0 | DA9: =DA8+E9 -> 0 | DB9: =DB8+F9 -> 0 | DC9: =DC8+G9 -> 0 | DD9: =DD8+H9 -> 0 | DE9: =DE8+I9 -> 0 | ... DP9: =DP8+T9 -> 0 | DR9: =DR8+V9 -> 0 | DS9: =DS8+W9 -> 1 | DT9: =DT8+X9 -> 17 | DU9: =DU8+Y9 -> 34 | DV9: =DV8+Z9 -> 10 | DW9: =DW8+AA9 -> 106 | DX9: =DX8+AB9 -> 5 | DY9: =DY8+AC9 -> 0 | ... EQ9: =EQ8+AU9 -> 7 | ER9: =AVERAGE(EH9:EQ9) -> 16.7 | ES9: =AVERAGE(DB9:EQ9) -> 9.7560976 | EV9: 168 | EW9: =CX9/CX$102 -> 0 | EX9: =CY9/CY$102 -> 0 | EY9: =CZ9/CZ$102 -> 0 | EZ9: =DA9/DA$102 -> 0 | FA9: =DB9/DB$102 -> 0 | FB9: =DC9/DC$102 -> 0 | FC9: =DD9/DD$102 -> 0 | FD9: =DE9/DE$102 -> 0 | ... FO9: =DP9/DP$102 -> 0 | FQ9: =DR9/DR$102 -> 0 | FR9: =DS9/DS$102 -> 0.00033921303 | FS9: =DT9/DT$102 -> 0.00464354 | FT9: =DU9/DU$102 -> 0.0014211405 | FU9: =DV9/DV$102 -> 0.00014314548 | FV9: =DW9/DW$102 -> 0.0013757479 | FW9: =DX9/DX$102 -> 7.6282306e-05 | FX9: =DY9/DY$102 -> 0 | ... GP9: =EQ9/EQ$102 -> 3.3285307e-05 | GQ9: =AVERAGE(GG9:GP9) -> 0.00016749026 | GR9: =AVERAGE(FA9:GP9) -> 0.00027897242
A10: 169 | P10: 0 | Q10: 6 | R10: 2 | S10: 4 | W10: 2 | X10: 3 | Y10: 21 | Z10: 2 | AA10: 22 | AB10: 0 | AE10: 7 | AJ10: 33 | AL10: 0 | AM10: 3 | AP10: 57 | AQ10: 1 | AR10: 1 | AS10: 0 | AT10: 160 | AU10: 3 | AV10: =AVERAGE(AL10:AU10) -> 28.125 | AW10: =AW9+AV10 -> 51.982143 | AY10: 169 | AZ10: =B10/B$104 -> 0 | BA10: =C10/C$104 -> 0 | BB10: =D10/D$104 -> 0 | BC10: =E10/E$104 -> 0 | BD10: =F10/F$104 -> 0 | BE10: =G10/G$104 -> 0 | BF10: =H10/H$104 -> 0 | BG10: =I10/I$104 -> 0 | ... BR10: =T10/T$104 -> 0 | BT10: =V10/V$104 -> 0 | BU10: =W10/W$104 -> 0.00067842605 | BV10: =X10/X$104 -> 0.00081944824 | BW10: =Y10/Y$104 -> 0.00087776322 | BX10: =Z10/Z$104 -> 2.8629096e-05 | BY10: =AA10/AA$104 -> 0.00028553258 | BZ10: =AB10/AB$104 -> 0 | CA10: =AC10/AC$104 -> 0 | ... CS10: =AU10/AU$104 -> 1.4265132e-05 | CT10: =CT9+AVERAGE(CJ10:CS10) -> 0.00038704259 | CU10: =CU9+AVERAGE(BD10:CS10) -> 0.00044217674 | CW10: 169 | CX10: =CX9+B10 -> 0 | CY10: =CY9+C10 -> 0 | CZ10: =CZ9+D10 -> 0 | DA10: =DA9+E10 -> 0 | DB10: =DB9+F10 -> 0 | DC10: =DC9+G10 -> 0 | DD10: =DD9+H10 -> 0 | DE10: =DE9+I10 -> 0 | ... DP10: =DP9+T10 -> 0 | DR10: =DR9+V10 -> 0 | DS10: =DS9+W10 -> 3 | DT10: =DT9+X10 -> 20 | DU10: =DU9+Y10 -> 55 | DV10: =DV9+Z10 -> 12 | DW10: =DW9+AA10 -> 128 | DX10: =DX9+AB10 -> 5 | DY10: =DY9+AC10 -> 0 | ... EQ10: =EQ9+AU10 -> 10 | ER10: =AVERAGE(EH10:EQ10) -> 39.2 | ES10: =AVERAGE(DB10:EQ10) -> 17.731707 | EV10: 169 | EW10: =CX10/CX$102 -> 0 | EX10: =CY10/CY$102 -> 0 | EY10: =CZ10/CZ$102 -> 0 | EZ10: =DA10/DA$102 -> 0 | FA10: =DB10/DB$102 -> 0 | FB10: =DC10/DC$102 -> 0 | FC10: =DD10/DD$102 -> 0 | FD10: =DE10/DE$102 -> 0 | ... FO10: =DP10/DP$102 -> 0 | FQ10: =DR10/DR$102 -> 0 | FR10: =DS10/DS$102 -> 0.0010176391 | FS10: =DT10/DT$102 -> 0.0054629883 | FT10: =DU10/DU$102 -> 0.0022989037 | FU10: =DV10/DV$102 -> 0.00017177457 | FV10: =DW10/DW$102 -> 0.0016612805 | FW10: =DX10/DX$102 -> 7.6282306e-05 | FX10: =DY10/DY$102 -> 0 | ... GP10: =EQ10/EQ$102 -> 4.7550439e-05 | GQ10: =AVERAGE(GG10:GP10) -> 0.00038704259 | GR10: =AVERAGE(FA10:GP10) -> 0.00044217674
A11: 170 | B11: 0 | N11: 1 | P11: 14 | Q11: 19 | R11: 51 | S11: 0 | W11: 0 | X11: 5 | Y11: 60 | Z11: 11 | AA11: 43 | AB11: 0 | AE11: 12 | AJ11: 220 | AK11: 19 | AL11: 0 | AM11: 9 | AO11: 2 | AP11: 74 | AQ11: 0 | AR11: 22 | AS11: 1 | AT11: 351 | AU11: 325 | AV11: =AVERAGE(AL11:AU11) -> 87.111111 | AW11: =AW10+AV11 -> 139.09325 | AY11: 170 | AZ11: =B11/B$104 -> 0 | BA11: =C11/C$104 -> 0 | BB11: =D11/D$104 -> 0 | BC11: =E11/E$104 -> 0 | BD11: =F11/F$104 -> 0 | BE11: =G11/G$104 -> 0 | BF11: =H11/H$104 -> 0 | BG11: =I11/I$104 -> 0 | ... BR11: =T11/T$104 -> 0 | BT11: =V11/V$104 -> 0 | BU11: =W11/W$104 -> 0 | BV11: =X11/X$104 -> 0.0013657471 | BW11: =Y11/Y$104 -> 0.0025078949 | BX11: =Z11/Z$104 -> 0.00015746003 | BY11: =AA11/AA$104 -> 0.00055808641 | BZ11: =AB11/AB$104 -> 0 | CA11: =AC11/AC$104 -> 0 | ... CS11: =AU11/AU$104 -> 0.0015453893 | CT11: =CT10+AVERAGE(CJ11:CS11) -> 0.00097608294 | CU11: =CU10+AVERAGE(BD11:CS11) -> 0.0009242675 | CW11: 170 | CX11: =CX10+B11 -> 0 | CY11: =CY10+C11 -> 0 | CZ11: =CZ10+D11 -> 0 | DA11: =DA10+E11 -> 0 | DB11: =DB10+F11 -> 0 | DC11: =DC10+G11 -> 0 | DD11: =DD10+H11 -> 0 | DE11: =DE10+I11 -> 0 | ... DP11: =DP10+T11 -> 0 | DR11: =DR10+V11 -> 0 | DS11: =DS10+W11 -> 3 | DT11: =DT10+X11 -> 25 | DU11: =DU10+Y11 -> 115 | DV11: =DV10+Z11 -> 23 | DW11: =DW10+AA11 -> 171 | DX11: =DX10+AB11 -> 5 | DY11: =DY10+AC11 -> 0 | ... EQ11: =EQ10+AU11 -> 335 | ER11: =AVERAGE(EH11:EQ11) -> 117.6 | ES11: =AVERAGE(DB11:EQ11) -> 47.95122 | EV11: 170 | EW11: =CX11/CX$102 -> 0 | EX11: =CY11/CY$102 -> 0 | EY11: =CZ11/CZ$102 -> 0 | EZ11: =DA11/DA$102 -> 0 | FA11: =DB11/DB$102 -> 0 | FB11: =DC11/DC$102 -> 0 | FC11: =DD11/DD$102 -> 0 | FD11: =DE11/DE$102 -> 0 | ... FO11: =DP11/DP$102 -> 0 | FQ11: =DR11/DR$102 -> 0 | FR11: =DS11/DS$102 -> 0.0010176391 | FS11: =DT11/DT$102 -> 0.0068287353 | FT11: =DU11/DU$102 -> 0.0048067986 | FU11: =DV11/DV$102 -> 0.0003292346 | FV11: =DW11/DW$102 -> 0.0022193669 | FW11: =DX11/DX$102 -> 7.6282306e-05 | FX11: =DY11/DY$102 -> 0 | ... GP11: =EQ11/EQ$102 -> 0.0015929397 | GQ11: =AVERAGE(GG11:GP11) -> 0.00097608294 | GR11: =AVERAGE(FA11:GP11) -> 0.0009242675
A12: 171 | B12: 0 | L12: 4 | N12: 0 | O12: 0 | P12: 0 | Q12: 20 | R12: 27 | S12: 12 | W12: 4 | X12: 10 | Y12: 76 | Z12: 0 | AA12: 23 | AB12: 3 | AD12: 86 | AE12: 5 | AF12: 0 | AH12: 0 | AI12: 0 | AJ12: 276 | AK12: 4 | AL12: 1 | AM12: 8 | AN12: 3 | AO12: 42 | AP12: 88 | AQ12: 0 | AR12: 11 | AS12: 52 | AT12: 20 | AU12: 1419 | AV12: =AVERAGE(AL12:AU12) -> 164.4 | AW12: =AW11+AV12 -> 303.49325 | AY12: 171 | AZ12: =B12/B$104 -> 0 | BA12: =C12/C$104 -> 0 | BB12: =D12/D$104 -> 0 | BC12: =E12/E$104 -> 0 | BD12: =F12/F$104 -> 0 | BE12: =G12/G$104 -> 0 | BF12: =H12/H$104 -> 0 | BG12: =I12/I$104 -> 0 | ... BR12: =T12/T$104 -> 0 | BT12: =V12/V$104 -> 0 | BU12: =W12/W$104 -> 0.0013568521 | BV12: =X12/X$104 -> 0.0027314941 | BW12: =Y12/Y$104 -> 0.0031766669 | BX12: =Z12/Z$104 -> 0 | BY12: =AA12/AA$104 -> 0.00029851134 | BZ12: =AB12/AB$104 -> 4.5769383e-05 | CA12: =AC12/AC$104 -> 0 | ... CS12: =AU12/AU$104 -> 0.0067474073 | CT12: =CT11+AVERAGE(CJ12:CS12) -> 0.0019979719 | CU12: =CU11+AVERAGE(BD12:CS12) -> 0.0015976549 | CW12: 171 | CX12: =CX11+B12 -> 0 | CY12: =CY11+C12 -> 0 | CZ12: =CZ11+D12 -> 0 | DA12: =DA11+E12 -> 0 | DB12: =DB11+F12 -> 0 | DC12: =DC11+G12 -> 0 | DD12: =DD11+H12 -> 0 | DE12: =DE11+I12 -> 0 | ... DP12: =DP11+T12 -> 0 | DR12: =DR11+V12 -> 0 | DS12: =DS11+W12 -> 7 | DT12: =DT11+X12 -> 35 | DU12: =DU11+Y12 -> 191 | DV12: =DV11+Z12 -> 23 | DW12: =DW11+AA12 -> 194 | DX12: =DX11+AB12 -> 8 | DY12: =DY11+AC12 -> 0 | ... EQ12: =EQ11+AU12 -> 1754 | ER12: =AVERAGE(EH12:EQ12) -> 282 | ES12: =AVERAGE(DB12:EQ12) -> 101.46341 | EV12: 171 | EW12: =CX12/CX$102 -> 0 | EX12: =CY12/CY$102 -> 0 | EY12: =CZ12/CZ$102 -> 0 | EZ12: =DA12/DA$102 -> 0 | FA12: =DB12/DB$102 -> 0 | FB12: =DC12/DC$102 -> 0 | FC12: =DD12/DD$102 -> 0 | FD12: =DE12/DE$102 -> 0 | ... FO12: =DP12/DP$102 -> 0 | FQ12: =DR12/DR$102 -> 0 | FR12: =DS12/DS$102 -> 0.0023744912 | FS12: =DT12/DT$102 -> 0.0095602294 | FT12: =DU12/DU$102 -> 0.0079834655 | FU12: =DV12/DV$102 -> 0.0003292346 | FV12: =DW12/DW$102 -> 0.0025178782 | FW12: =DX12/DX$102 -> 0.00012205169 | FX12: =DY12/DY$102 -> 0 | ... GP12: =EQ12/EQ$102 -> 0.008340347 | GQ12: =AVERAGE(GG12:GP12) -> 0.0019979719 | GR12: =AVERAGE(FA12:GP12) -> 0.0015976549
A13: 172 | B13: 0 | L13: 23 | N13: 0 | O13: 0 | P13: 3 | Q13: 32 | R13: 41 | S13: 8 | W13: 1 | X13: 0 | Y13: 39 | Z13: 1 | AA13: 53 | AB13: 119 | AD13: 220 | AE13: 0 | AF13: 0 | AH13: 0 | AI13: 0 | AJ13: 341 | AK13: 241 | AL13: 1 | AM13: 4 | AN13: 1 | AO13: 2 | AP13: 31 | AQ13: 12 | AR13: 77 | AS13: 0 | AT13: 108 | AU13: 37 | AV13: =AVERAGE(AL13:AU13) -> 27.3 | AW13: =AW12+AV13 -> 330.79325 | AY13: 172 | AZ13: =B13/B$104 -> 0 | BA13: =C13/C$104 -> 0 | BB13: =D13/D$104 -> 0 | BC13: =E13/E$104 -> 0 | BD13: =F13/F$104 -> 0 | BE13: =G13/G$104 -> 0 | BF13: =H13/H$104 -> 0 | BG13: =I13/I$104 -> 0 | ... BR13: =T13/T$104 -> 0 | BT13: =V13/V$104 -> 0 | BU13: =W13/W$104 -> 0.00033921303 | BV13: =X13/X$104 -> 0 | BW13: =Y13/Y$104 -> 0.0016301317 | BX13: =Z13/Z$104 -> 1.4314548e-05 | BY13: =AA13/AA$104 -> 0.00068787395 | BZ13: =AB13/AB$104 -> 0.0018155189 | CA13: =AC13/AC$104 -> 0 | ... CS13: =AU13/AU$104 -> 0.00017593662 | CT13: =CT12+AVERAGE(CJ13:CS13) -> 0.0023254925 | CU13: =CU12+AVERAGE(BD13:CS13) -> 0.0024231582 | CW13: 172 | CX13: =CX12+B13 -> 0 | CY13: =CY12+C13 -> 0 | CZ13: =CZ12+D13 -> 0 | DA13: =DA12+E13 -> 0 | DB13: =DB12+F13 -> 0 | DC13: =DC12+G13 -> 0 | DD13: =DD12+H13 -> 0 | DE13: =DE12+I13 -> 0 | ... DP13: =DP12+T13 -> 0 | DR13: =DR12+V13 -> 0 | DS13: =DS12+W13 -> 8 | DT13: =DT12+X13 -> 35 | DU13: =DU12+Y13 -> 230 | DV13: =DV12+Z13 -> 24 | DW13: =DW12+AA13 -> 247 | DX13: =DX12+AB13 -> 127 | DY13: =DY12+AC13 -> 0 | ... EQ13: =EQ12+AU13 -> 1791 | ER13: =AVERAGE(EH13:EQ13) -> 309.3 | ES13: =AVERAGE(DB13:EQ13) -> 135.4878 | EV13: 172 | EW13: =CX13/CX$102 -> 0 | EX13: =CY13/CY$102 -> 0 | EY13: =CZ13/CZ$102 -> 0 | EZ13: =DA13/DA$102 -> 0 | FA13: =DB13/DB$102 -> 0 | FB13: =DC13/DC$102 -> 0 | FC13: =DD13/DD$102 -> 0 | FD13: =DE13/DE$102 -> 0 | ... FO13: =DP13/DP$102 -> 0 | FQ13: =DR13/DR$102 -> 0 | FR13: =DS13/DS$102 -> 0.0027137042 | FS13: =DT13/DT$102 -> 0.0095602294 | FT13: =DU13/DU$102 -> 0.0096135972 | FU13: =DV13/DV$102 -> 0.00034354915 | FV13: =DW13/DW$102 -> 0.0032057522 | FW13: =DX13/DX$102 -> 0.0019375706 | FX13: =DY13/DY$102 -> 0 | ... GP13: =EQ13/EQ$102 -> 0.0085162836 | GQ13: =AVERAGE(GG13:GP13) -> 0.0023254925 | GR13: =AVERAGE(FA13:GP13) -> 0.0024231582
A14: 173 | B14: 0 | L14: 25 | N14: 0 | O14: 1 | P14: 0 | Q14: 70 | R14: 34 | S14: 14 | T14: 19 | W14: 0 | X14: 6 | Y14: 17 | Z14: 0 | AA14: 61 | AB14: 8 | AD14: 447 | AE14: 11 | AF14: 9 | AG14: 0 | AH14: 12 | AI14: 0 | AJ14: 397 | AK14: 42 | AL14: 0 | AM14: 12 | AN14: 48 | AO14: 2 | AP14: 26 | AQ14: 11 | AR14: 60 | AS14: 33 | AT14: 29 | AU14: 1067 | AV14: =AVERAGE(AL14:AU14) -> 128.8 | AW14: =AW13+AV14 -> 459.59325 | AY14: 173 | AZ14: =B14/B$104 -> 0 | BA14: =C14/C$104 -> 0 | BB14: =D14/D$104 -> 0 | BC14: =E14/E$104 -> 0 | BD14: =F14/F$104 -> 0 | BE14: =G14/G$104 -> 0 | BF14: =H14/H$104 -> 0 | BG14: =I14/I$104 -> 0 | ... BR14: =T14/T$104 -> 0.00067550752 | BT14: =V14/V$104 -> 0 | BU14: =W14/W$104 -> 0 | BV14: =X14/X$104 -> 0.0016388965 | BW14: =Y14/Y$104 -> 0.00071057023 | BX14: =Z14/Z$104 -> 0 | BY14: =AA14/AA$104 -> 0.00079170398 | BZ14: =AB14/AB$104 -> 0.00012205169 | CA14: =AC14/AC$104 -> 0 | ... CS14: =AU14/AU$104 -> 0.0050736319 | CT14: =CT13+AVERAGE(CJ14:CS14) -> 0.0032034689 | CU14: =CU13+AVERAGE(BD14:CS14) -> 0.0033166015 | CW14: 173 | CX14: =CX13+B14 -> 0 | CY14: =CY13+C14 -> 0 | CZ14: =CZ13+D14 -> 0 | DA14: =DA13+E14 -> 0 | DB14: =DB13+F14 -> 0 | DC14: =DC13+G14 -> 0 | DD14: =DD13+H14 -> 0 | DE14: =DE13+I14 -> 0 | ... DP14: =DP13+T14 -> 19 | DR14: =DR13+V14 -> 0 | DS14: =DS13+W14 -> 8 | DT14: =DT13+X14 -> 41 | DU14: =DU13+Y14 -> 247 | DV14: =DV13+Z14 -> 24 | DW14: =DW13+AA14 -> 308 | DX14: =DX13+AB14 -> 135 | DY14: =DY13+AC14 -> 0 | ... EQ14: =EQ13+AU14 -> 2858 | ER14: =AVERAGE(EH14:EQ14) -> 438.1 | ES14: =AVERAGE(DB14:EQ14) -> 195.5122 | EV14: 173 | EW14: =CX14/CX$102 -> 0 | EX14: =CY14/CY$102 -> 0 | EY14: =CZ14/CZ$102 -> 0 | EZ14: =DA14/DA$102 -> 0 | FA14: =DB14/DB$102 -> 0 | FB14: =DC14/DC$102 -> 0 | FC14: =DD14/DD$102 -> 0 | FD14: =DE14/DE$102 -> 0 | ... FO14: =DP14/DP$102 -> 0.00067550752 | FQ14: =DR14/DR$102 -> 0 | FR14: =DS14/DS$102 -> 0.0027137042 | FS14: =DT14/DT$102 -> 0.011199126 | FT14: =DU14/DU$102 -> 0.010324167 | FU14: =DV14/DV$102 -> 0.00034354915 | FV14: =DW14/DW$102 -> 0.0039974562 | FW14: =DX14/DX$102 -> 0.0020596223 | FX14: =DY14/DY$102 -> 0 | ... GP14: =EQ14/EQ$102 -> 0.013589916 | GQ14: =AVERAGE(GG14:GP14) -> 0.0032034689 | GR14: =AVERAGE(FA14:GP14) -> 0.0033166015
A15: 174 | B15: 7 | C15: 11 | L15: 11 | N15: 1 | O15: 0 | P15: 39 | Q15: 47 | R15: 68 | S15: 18 | T15: 78 | V15: 8 | W15: 1 | X15: 10 | Y15: 20 | Z15: 1 | AA15: 136 | AB15: 49 | AD15: 97 | AE15: 4 | AF15: 7 | AG15: 0 | AH15: 0 | AI15: 0 | AJ15: 93 | AK15: 66 | AL15: 0 | AM15: 2 | AN15: 52 | AO15: 0 | AP15: 31 | AQ15: 0 | AR15: 96 | AS15: 3 | AT15: 765 | AU15: 1527 | AV15: =AVERAGE(AL15:AU15) -> 247.6 | AW15: =AW14+AV15 -> 707.19325 | AY15: 174 | AZ15: =B15/B$104 -> 0.00030513055 | BA15: =C15/C$104 -> 0.00057447253 | BB15: =D15/D$104 -> 0 | BC15: =E15/E$104 -> 0 | BD15: =F15/F$104 -> 0 | BE15: =G15/G$104 -> 0 | BF15: =H15/H$104 -> 0 | BG15: =I15/I$104 -> 0 | ... BR15: =T15/T$104 -> 0.0027731361 | BT15: =V15/V$104 -> 0.00013920548 | BU15: =W15/W$104 -> 0.00033921303 | BV15: =X15/X$104 -> 0.0027314941 | BW15: =Y15/Y$104 -> 0.00083596497 | BX15: =Z15/Z$104 -> 1.4314548e-05 | BY15: =AA15/AA$104 -> 0.0017651105 | BZ15: =AB15/AB$104 -> 0.00074756659 | CA15: =AC15/AC$104 -> 0 | ... CS15: =AU15/AU$104 -> 0.0072609521 | CT15: =CT14+AVERAGE(CJ15:CS15) -> 0.0047469114 | CU15: =CU14+AVERAGE(BD15:CS15) -> 0.0042589313 | CW15: 174 | CX15: =CX14+B15 -> 7 | CY15: =CY14+C15 -> 11 | CZ15: =CZ14+D15 -> 0 | DA15: =DA14+E15 -> 0 | DB15: =DB14+F15 -> 0 | DC15: =DC14+G15 -> 0 | DD15: =DD14+H15 -> 0 | DE15: =DE14+I15 -> 0 | ... DP15: =DP14+T15 -> 97 | DR15: =DR14+V15 -> 8 | DS15: =DS14+W15 -> 9 | DT15: =DT14+X15 -> 51 | DU15: =DU14+Y15 -> 267 | DV15: =DV14+Z15 -> 25 | DW15: =DW14+AA15 -> 444 | DX15: =DX14+AB15 -> 184 | DY15: =DY14+AC15 -> 0 | ... EQ15: =EQ14+AU15 -> 4385 | ER15: =AVERAGE(EH15:EQ15) -> 685.7 | ES15: =AVERAGE(DB15:EQ15) -> 274.29268 | EV15: 174 | EW15: =CX15/CX$102 -> 0.00030513055 | EX15: =CY15/CY$102 -> 0.00057447253 | EY15: =CZ15/CZ$102 -> 0 | EZ15: =DA15/DA$102 -> 0 | FA15: =DB15/DB$102 -> 0 | FB15: =DC15/DC$102 -> 0 | FC15: =DD15/DD$102 -> 0 | FD15: =DE15/DE$102 -> 0 | ... FO15: =DP15/DP$102 -> 0.0034486437 | FQ15: =DR15/DR$102 -> 0.00013920548 | FR15: =DS15/DS$102 -> 0.0030529172 | FS15: =DT15/DT$102 -> 0.01393062 | FT15: =DU15/DU$102 -> 0.011160132 | FU15: =DV15/DV$102 -> 0.0003578637 | FV15: =DW15/DW$102 -> 0.0057625667 | FW15: =DX15/DX$102 -> 0.0028071888 | FX15: =DY15/DY$102 -> 0 | ... GP15: =EQ15/EQ$102 -> 0.020850868 | GQ15: =AVERAGE(GG15:GP15) -> 0.0047469114 | GR15: =AVERAGE(FA15:GP15) -> 0.0042589313
A16: 175 | B16: 33 | C16: 12 | D16: 15 | G16: 0 | L16: 11 | N16: 0 | O16: 0 | P16: 35 | Q16: 54 | R16: 134 | S16: 21 | T16: 32 | V16: 76 | W16: 3 | X16: 9 | Y16: 36 | Z16: 0 | AA16: 36 | AB16: 58 | AD16: 61 | AE16: 7 | AF16: 0 | AG16: 0 | AH16: 0 | AI16: 2 | AJ16: 667 | AK16: 349 | AL16: 1 | AM16: 6 | AN16: 170 | AO16: 0 | AP16: 30 | AQ16: 0 | AR16: 104 | AS16: 3 | AT16: 2060 | AU16: 45 | AV16: =AVERAGE(AL16:AU16) -> 241.9 | AW16: =AW15+AV16 -> 949.09325 | AY16: 175 | AZ16: =B16/B$104 -> 0.0014384726 | BA16: =C16/C$104 -> 0.00062669731 | BB16: =D16/D$104 -> 0.00065568038 | BC16: =E16/E$104 -> 0 | BD16: =F16/F$104 -> 0 | BE16: =G16/G$104 -> 0 | BF16: =H16/H$104 -> 0 | BG16: =I16/I$104 -> 0 | ... BR16: =T16/T$104 -> 0.0011376969 | BT16: =V16/V$104 -> 0.0013224521 | BU16: =W16/W$104 -> 0.0010176391 | BV16: =X16/X$104 -> 0.0024583447 | BW16: =Y16/Y$104 -> 0.0015047369 | BX16: =Z16/Z$104 -> 0 | BY16: =AA16/AA$104 -> 0.00046723514 | BZ16: =AB16/AB$104 -> 0.00088487474 | CA16: =AC16/AC$104 -> 0 | ... CS16: =AU16/AU$104 -> 0.00021397698 | CT16: =CT15+AVERAGE(CJ16:CS16) -> 0.0066795918 | CU16: =CU15+AVERAGE(BD16:CS16) -> 0.0059589835 | CW16: 175 | CX16: =CX15+B16 -> 40 | CY16: =CY15+C16 -> 23 | CZ16: =CZ15+D16 -> 15 | DA16: =DA15+E16 -> 0 | DB16: =DB15+F16 -> 0 | DC16: =DC15+G16 -> 0 | DD16: =DD15+H16 -> 0 | DE16: =DE15+I16 -> 0 | ... DP16: =DP15+T16 -> 129 | DR16: =DR15+V16 -> 84 | DS16: =DS15+W16 -> 12 | DT16: =DT15+X16 -> 60 | DU16: =DU15+Y16 -> 303 | DV16: =DV15+Z16 -> 25 | DW16: =DW15+AA16 -> 480 | DX16: =DX15+AB16 -> 242 | DY16: =DY15+AC16 -> 0 | ... EQ16: =EQ15+AU16 -> 4430 | ER16: =AVERAGE(EH16:EQ16) -> 927.6 | ES16: =AVERAGE(DB16:EQ16) -> 372.09756 | EV16: 175 | EW16: =CX16/CX$102 -> 0.0017436032 | EX16: =CY16/CY$102 -> 0.0012011698 | EY16: =CZ16/CZ$102 -> 0.00065568038 | EZ16: =DA16/DA$102 -> 0 | FA16: =DB16/DB$102 -> 0 | FB16: =DC16/DC$102 -> 0 | FC16: =DD16/DD$102 -> 0 | FD16: =DE16/DE$102 -> 0 | ... FO16: =DP16/DP$102 -> 0.0045863405 | FQ16: =DR16/DR$102 -> 0.0014616576 | FR16: =DS16/DS$102 -> 0.0040705563 | FS16: =DT16/DT$102 -> 0.016388965 | FT16: =DU16/DU$102 -> 0.012664869 | FU16: =DV16/DV$102 -> 0.0003578637 | FV16: =DW16/DW$102 -> 0.0062298018 | FW16: =DX16/DX$102 -> 0.0036920636 | FX16: =DY16/DY$102 -> 0 | ... GP16: =EQ16/EQ$102 -> 0.021064845 | GQ16: =AVERAGE(GG16:GP16) -> 0.0066795918 | GR16: =AVERAGE(FA16:GP16) -> 0.0059589835
A17: 176 | B17: 11 | C17: 4 | D17: 40 | G17: 0 | H17: 1 | L17: 11 | N17: 0 | O17: 0 | P17: 10 | Q17: 277 | R17: 67 | S17: 10 | T17: 51 | V17: 135 | W17: 1 | X17: 4 | Y17: 23 | Z17: 0 | AA17: 33 | AB17: 47 | AC17: 246 | AD17: 63 | AE17: 1 | AF17: 12 | AG17: 18 | AH17: 0 | AI17: 120 | AJ17: 535 | AK17: 155 | AL17: 2 | AM17: 1 | AN17: 334 | AO17: 6 | AP17: 10 | AQ17: 1 | AR17: 118 | AS17: 14 | AT17: 48 | AU17: 75 | AV17: =AVERAGE(AL17:AU17) -> 60.9 | AW17: =AW16+AV17 -> 1009.9933 | AY17: 176 | AZ17: =B17/B$104 -> 0.00047949087 | BA17: =C17/C$104 -> 0.0002088991 | BB17: =D17/D$104 -> 0.001748481 | BC17: =E17/E$104 -> 0 | BD17: =F17/F$104 -> 0 | BE17: =G17/G$104 -> 0 | BF17: =H17/H$104 -> 9.3729497e-05 | BG17: =I17/I$104 -> 0 | ... BR17: =T17/T$104 -> 0.0018132044 | BT17: =V17/V$104 -> 0.0023490926 | BU17: =W17/W$104 -> 0.00033921303 | BV17: =X17/X$104 -> 0.0010925977 | BW17: =Y17/Y$104 -> 0.00096135972 | BX17: =Z17/Z$104 -> 0 | BY17: =AA17/AA$104 -> 0.00042829887 | BZ17: =AB17/AB$104 -> 0.00071705367 | CA17: =AC17/AC$104 -> 0.0024340289 | ... CS17: =AU17/AU$104 -> 0.00035662829 | CT17: =CT16+AVERAGE(CJ17:CS17) -> 0.0076092709 | CU17: =CU16+AVERAGE(BD17:CS17) -> 0.00729871 | CW17: 176 | CX17: =CX16+B17 -> 51 | CY17: =CY16+C17 -> 27 | CZ17: =CZ16+D17 -> 55 | DA17: =DA16+E17 -> 0 | DB17: =DB16+F17 -> 0 | DC17: =DC16+G17 -> 0 | DD17: =DD16+H17 -> 1 | DE17: =DE16+I17 -> 0 | ... DP17: =DP16+T17 -> 180 | DR17: =DR16+V17 -> 219 | DS17: =DS16+W17 -> 13 | DT17: =DT16+X17 -> 64 | DU17: =DU16+Y17 -> 326 | DV17: =DV16+Z17 -> 25 | DW17: =DW16+AA17 -> 513 | DX17: =DX16+AB17 -> 289 | DY17: =DY16+AC17 -> 246 | ... EQ17: =EQ16+AU17 -> 4505 | ER17: =AVERAGE(EH17:EQ17) -> 988.5 | ES17: =AVERAGE(DB17:EQ17) -> 431.34146 | EV17: 176 | EW17: =CX17/CX$102 -> 0.002223094 | EX17: =CY17/CY$102 -> 0.0014100689 | EY17: =CZ17/CZ$102 -> 0.0024041614 | EZ17: =DA17/DA$102 -> 0 | FA17: =DB17/DB$102 -> 0 | FB17: =DC17/DC$102 -> 0 | FC17: =DD17/DD$102 -> 9.3729497e-05 | FD17: =DE17/DE$102 -> 0 | ... FO17: =DP17/DP$102 -> 0.0063995449 | FQ17: =DR17/DR$102 -> 0.0038107501 | FR17: =DS17/DS$102 -> 0.0044097693 | FS17: =DT17/DT$102 -> 0.017481562 | FT17: =DU17/DU$102 -> 0.013626229 | FU17: =DV17/DV$102 -> 0.0003578637 | FV17: =DW17/DW$102 -> 0.0066581007 | FW17: =DX17/DX$102 -> 0.0044091173 | FX17: =DY17/DY$102 -> 0.0024340289 | ... GP17: =EQ17/EQ$102 -> 0.021421473 | GQ17: =AVERAGE(GG17:GP17) -> 0.0076092709 | GR17: =AVERAGE(FA17:GP17) -> 0.00729871
A18: 177 | B18: 93 | C18: 3 | D18: 40 | E18: 8 | F18: 13 | G18: 0 | H18: 0 | L18: 18 | N18: 0 | O18: 3 | P18: 7 | Q18: 30 | R18: 125 | S18: 7 | T18: 156 | V18: 524 | W18: 8 | X18: 10 | Y18: 74 | Z18: 2 | AA18: 103 | AB18: 71 | AC18: 160 | AD18: 44 | AE18: 13 | AF18: 52 | AG18: 0 | AH18: 0 | AI18: 65 | AJ18: 92 | AK18: 143 | AL18: 3 | AM18: 81 | AN18: 108 | AO18: 358 | AP18: 6 | AQ18: 1 | AR18: 304 | AS18: 34 | AT18: 319 | AU18: 842 | AV18: =AVERAGE(AL18:AU18) -> 205.6 | AW18: =AW17+AV18 -> 1215.5933 | AY18: 177 | AZ18: =B18/B$104 -> 0.0040538773 | BA18: =C18/C$104 -> 0.00015667433 | BB18: =D18/D$104 -> 0.001748481 | BC18: =E18/E$104 -> 0.018604651 | BD18: =F18/F$104 -> 0.0051485149 | BE18: =G18/G$104 -> 0 | BF18: =H18/H$104 -> 0 | BG18: =I18/I$104 -> 0 | ... BR18: =T18/T$104 -> 0.0055462723 | BT18: =V18/V$104 -> 0.0091179592 | BU18: =W18/W$104 -> 0.0027137042 | BV18: =X18/X$104 -> 0.0027314941 | BW18: =Y18/Y$104 -> 0.0030930704 | BX18: =Z18/Z$104 -> 2.8629096e-05 | BY18: =AA18/AA$104 -> 0.0013368116 | BZ18: =AB18/AB$104 -> 0.0010832087 | CA18: =AC18/AC$104 -> 0.0015831082 | ... CS18: =AU18/AU$104 -> 0.004003747 | CT18: =CT17+AVERAGE(CJ18:CS18) -> 0.0098471123 | CU18: =CU17+AVERAGE(BD18:CS18) -> 0.009194539 | CW18: 177 | CX18: =CX17+B18 -> 144 | CY18: =CY17+C18 -> 30 | CZ18: =CZ17+D18 -> 95 | DA18: =DA17+E18 -> 8 | DB18: =DB17+F18 -> 13 | DC18: =DC17+G18 -> 0 | DD18: =DD17+H18 -> 1 | DE18: =DE17+I18 -> 0 | ... DP18: =DP17+T18 -> 336 | DR18: =DR17+V18 -> 743 | DS18: =DS17+W18 -> 21 | DT18: =DT17+X18 -> 74 | DU18: =DU17+Y18 -> 400 | DV18: =DV17+Z18 -> 27 | DW18: =DW17+AA18 -> 616 | DX18: =DX17+AB18 -> 360 | DY18: =DY17+AC18 -> 406 | ... EQ18: =EQ17+AU18 -> 5347 | ER18: =AVERAGE(EH18:EQ18) -> 1194.1 | ES18: =AVERAGE(DB18:EQ18) -> 523.43902 | EV18: 177 | EW18: =CX18/CX$102 -> 0.0062769714 | EX18: =CY18/CY$102 -> 0.0015667433 | EY18: =CZ18/CZ$102 -> 0.0041526424 | EZ18: =DA18/DA$102 -> 0.018604651 | FA18: =DB18/DB$102 -> 0.0051485149 | FB18: =DC18/DC$102 -> 0 | FC18: =DD18/DD$102 -> 9.3729497e-05 | FD18: =DE18/DE$102 -> 0 | ... FO18: =DP18/DP$102 -> 0.011945817 | FQ18: =DR18/DR$102 -> 0.012928709 | FR18: =DS18/DS$102 -> 0.0071234735 | FS18: =DT18/DT$102 -> 0.020213057 | FT18: =DU18/DU$102 -> 0.016719299 | FU18: =DV18/DV$102 -> 0.00038649279 | FV18: =DW18/DW$102 -> 0.0079949123 | FW18: =DX18/DX$102 -> 0.005492326 | FX18: =DY18/DY$102 -> 0.0040171371 | ... GP18: =EQ18/EQ$102 -> 0.02542522 | GQ18: =AVERAGE(GG18:GP18) -> 0.0098471123 | GR18: =AVERAGE(FA18:GP18) -> 0.009194539
A19: 178 | B19: 38 | C19: 3 | D19: 67 | E19: 1 | F19: 11 | G19: 1 | H19: 0 | L19: 24 | M19: 28 | N19: 0 | O19: 3 | P19: 285 | Q19: 105 | R19: 149 | S19: 2 | T19: 155 | V19: 411 | W19: 16 | X19: 31 | Y19: 54 | Z19: 7 | AA19: 561 | AB19: 89 | AC19: 143 | AD19: 15 | AE19: 2 | AF19: 14 | AG19: 4 | AH19: 0 | AI19: 66 | AJ19: 311 | AK19: 50 | AL19: 0 | AM19: 260 | AN19: 1055 | AO19: 535 | AP19: 12 | AQ19: 3 | AR19: 35 | AS19: 157 | AT19: 1496 | AU19: 207 | AV19: =AVERAGE(AL19:AU19) -> 376 | AW19: =AW18+AV19 -> 1591.5933 | AY19: 178 | AZ19: =B19/B$104 -> 0.001656423 | BA19: =C19/C$104 -> 0.00015667433 | BB19: =D19/D$104 -> 0.0029287057 | BC19: =E19/E$104 -> 0.0023255814 | BD19: =F19/F$104 -> 0.0043564356 | BE19: =G19/G$104 -> 8.6730269e-05 | BF19: =H19/H$104 -> 0 | BG19: =I19/I$104 -> 0 | ... BR19: =T19/T$104 -> 0.0055107192 | BT19: =V19/V$104 -> 0.0071516818 | BU19: =W19/W$104 -> 0.0054274084 | BV19: =X19/X$104 -> 0.0084676318 | BW19: =Y19/Y$104 -> 0.0022571054 | BX19: =Z19/Z$104 -> 0.00010020184 | BY19: =AA19/AA$104 -> 0.0072810809 | BZ19: =AB19/AB$104 -> 0.001357825 | CA19: =AC19/AC$104 -> 0.001414903 | ... CS19: =AU19/AU$104 -> 0.00098429409 | CT19: =CT18+AVERAGE(CJ19:CS19) -> 0.014985779 | CU19: =CU18+AVERAGE(BD19:CS19) -> 0.012301968 | CW19: 178 | CX19: =CX18+B19 -> 182 | CY19: =CY18+C19 -> 33 | CZ19: =CZ18+D19 -> 162 | DA19: =DA18+E19 -> 9 | DB19: =DB18+F19 -> 24 | DC19: =DC18+G19 -> 1 | DD19: =DD18+H19 -> 1 | DE19: =DE18+I19 -> 0 | ... DP19: =DP18+T19 -> 491 | DR19: =DR18+V19 -> 1154 | DS19: =DS18+W19 -> 37 | DT19: =DT18+X19 -> 105 | DU19: =DU18+Y19 -> 454 | DV19: =DV18+Z19 -> 34 | DW19: =DW18+AA19 -> 1177 | DX19: =DX18+AB19 -> 449 | DY19: =DY18+AC19 -> 549 | ... EQ19: =EQ18+AU19 -> 5554 | ER19: =AVERAGE(EH19:EQ19) -> 1570.1 | ES19: =AVERAGE(DB19:EQ19) -> 677.02439 | EV19: 178 | EW19: =CX19/CX$102 -> 0.0079333944 | EX19: =CY19/CY$102 -> 0.0017234176 | EY19: =CZ19/CZ$102 -> 0.0070813481 | EZ19: =DA19/DA$102 -> 0.020930233 | FA19: =DB19/DB$102 -> 0.0095049505 | FB19: =DC19/DC$102 -> 8.6730269e-05 | FC19: =DD19/DD$102 -> 9.3729497e-05 | FD19: =DE19/DE$102 -> 0 | ... FO19: =DP19/DP$102 -> 0.017456536 | FQ19: =DR19/DR$102 -> 0.020080391 | FR19: =DS19/DS$102 -> 0.012550882 | FS19: =DT19/DT$102 -> 0.028680688 | FT19: =DU19/DU$102 -> 0.018976405 | FU19: =DV19/DV$102 -> 0.00048669463 | FV19: =DW19/DW$102 -> 0.015275993 | FW19: =DX19/DX$102 -> 0.006850151 | FX19: =DY19/DY$102 -> 0.0054320401 | ... GP19: =EQ19/EQ$102 -> 0.026409514 | GQ19: =AVERAGE(GG19:GP19) -> 0.014985779 | GR19: =AVERAGE(FA19:GP19) -> 0.012301968
A20: 179 | B20: 47 | C20: 47 | D20: 464 | E20: 0 | F20: 12 | G20: 0 | H20: 0 | L20: 4 | M20: 32 | N20: 0 | O20: 1 | P20: 228 | Q20: 234 | R20: 31 | S20: 16 | T20: 92 | V20: 61 | W20: 9 | X20: 39 | Y20: 42 | Z20: 11 | AA20: 343 | AB20: 9 | AC20: 71 | AD20: 63 | AE20: 0 | AF20: 0 | AG20: 2 | AH20: 19 | AI20: 41 | AJ20: 205 | AK20: 927 | AL20: 13 | AM20: 69 | AN20: 193 | AO20: 0 | AP20: 1062 | AQ20: 0 | AR20: 490 | AS20: 0 | AT20: 3360 | AU20: 1109 | AV20: =AVERAGE(AL20:AU20) -> 629.6 | AW20: =AW19+AV20 -> 2221.1933 | AY20: 179 | AZ20: =B20/B$104 -> 0.0020487337 | BA20: =C20/C$104 -> 0.0024545644 | BB20: =D20/D$104 -> 0.02028238 | BC20: =E20/E$104 -> 0 | BD20: =F20/F$104 -> 0.0047524752 | BE20: =G20/G$104 -> 0 | BF20: =H20/H$104 -> 0 | BG20: =I20/I$104 -> 0 | ... BR20: =T20/T$104 -> 0.0032708785 | BT20: =V20/V$104 -> 0.0010614418 | BU20: =W20/W$104 -> 0.0030529172 | BV20: =X20/X$104 -> 0.010652827 | BW20: =Y20/Y$104 -> 0.0017555264 | BX20: =Z20/Z$104 -> 0.00015746003 | BY20: =AA20/AA$104 -> 0.0044517125 | BZ20: =AB20/AB$104 -> 0.00013730815 | CA20: =AC20/AC$104 -> 0.00070250428 | ... CS20: =AU20/AU$104 -> 0.0052733437 | CT20: =CT19+AVERAGE(CJ20:CS20) -> 0.02106712 | CU20: =CU19+AVERAGE(BD20:CS20) -> 0.016281953 | CW20: 179 | CX20: =CX19+B20 -> 229 | CY20: =CY19+C20 -> 80 | CZ20: =CZ19+D20 -> 626 | DA20: =DA19+E20 -> 9 | DB20: =DB19+F20 -> 36 | DC20: =DC19+G20 -> 1 | DD20: =DD19+H20 -> 1 | DE20: =DE19+I20 -> 0 | ... DP20: =DP19+T20 -> 583 | DR20: =DR19+V20 -> 1215 | DS20: =DS19+W20 -> 46 | DT20: =DT19+X20 -> 144 | DU20: =DU19+Y20 -> 496 | DV20: =DV19+Z20 -> 45 | DW20: =DW19+AA20 -> 1520 | DX20: =DX19+AB20 -> 458 | DY20: =DY19+AC20 -> 620 | ... EQ20: =EQ19+AU20 -> 6663 | ER20: =AVERAGE(EH20:EQ20) -> 2199.7 | ES20: =AVERAGE(DB20:EQ20) -> 891.36585 | EV20: 179 | EW20: =CX20/CX$102 -> 0.0099821281 | EX20: =CY20/CY$102 -> 0.004177982 | EY20: =CZ20/CZ$102 -> 0.027363728 | EZ20: =DA20/DA$102 -> 0.020930233 | FA20: =DB20/DB$102 -> 0.014257426 | FB20: =DC20/DC$102 -> 8.6730269e-05 | FC20: =DD20/DD$102 -> 9.3729497e-05 | FD20: =DE20/DE$102 -> 0 | ... FO20: =DP20/DP$102 -> 0.020727415 | FQ20: =DR20/DR$102 -> 0.021141833 | FR20: =DS20/DS$102 -> 0.015603799 | FS20: =DT20/DT$102 -> 0.039333515 | FT20: =DU20/DU$102 -> 0.020731931 | FU20: =DV20/DV$102 -> 0.00064415465 | FV20: =DW20/DW$102 -> 0.019727706 | FW20: =DX20/DX$102 -> 0.0069874592 | FX20: =DY20/DY$102 -> 0.0061345444 | ... GP20: =EQ20/EQ$102 -> 0.031682858 | GQ20: =AVERAGE(GG20:GP20) -> 0.02106712 | GR20: =AVERAGE(FA20:GP20) -> 0.016281953
A21: 180 | B21: 42 | C21: 36 | D21: 274 | E21: 2 | F21: 12 | G21: 37 | H21: 0 | I21: 0 | L21: 2 | M21: 147 | N21: 180 | O21: 2 | P21: 28 | Q21: 167 | R21: 18 | S21: 7 | T21: 89 | V21: 46 | W21: 15 | X21: 54 | Y21: 1 | Z21: 48 | AA21: 201 | AB21: 514 | AC21: 44 | AD21: 401 | AE21: 2 | AF21: 2 | AG21: 3 | AH21: 36 | AI21: 59 | AJ21: 537 | AK21: 124 | AL21: 12 | AM21: 160 | AN21: 32 | AO21: 799 | AP21: 1022 | AQ21: 0 | AR21: 261 | AS21: 113 | AT21: 924 | AU21: 1345 | AV21: =AVERAGE(AL21:AU21) -> 466.8 | AW21: =AW20+AV21 -> 2687.9933 | AY21: 180 | AZ21: =B21/B$104 -> 0.0018307833 | BA21: =C21/C$104 -> 0.0018800919 | BB21: =D21/D$104 -> 0.011977095 | BC21: =E21/E$104 -> 0.0046511628 | BD21: =F21/F$104 -> 0.0047524752 | BE21: =G21/G$104 -> 0.0032090199 | BF21: =H21/H$104 -> 0 | BG21: =I21/I$104 -> 0 | ... BR21: =T21/T$104 -> 0.0031642194 | BT21: =V21/V$104 -> 0.00080043154 | BU21: =W21/W$104 -> 0.0050881954 | BV21: =X21/X$104 -> 0.014750068 | BW21: =Y21/Y$104 -> 4.1798249e-05 | BX21: =Z21/Z$104 -> 0.0006870983 | BY21: =AA21/AA$104 -> 0.0026087295 | BZ21: =AB21/AB$104 -> 0.007841821 | CA21: =AC21/AC$104 -> 0.00043535476 | ... CS21: =AU21/AU$104 -> 0.0063955341 | CT21: =CT20+AVERAGE(CJ21:CS21) -> 0.026564078 | CU21: =CU20+AVERAGE(BD21:CS21) -> 0.019648011 | CW21: 180 | CX21: =CX20+B21 -> 271 | CY21: =CY20+C21 -> 116 | CZ21: =CZ20+D21 -> 900 | DA21: =DA20+E21 -> 11 | DB21: =DB20+F21 -> 48 | DC21: =DC20+G21 -> 38 | DD21: =DD20+H21 -> 1 | DE21: =DE20+I21 -> 0 | ... DP21: =DP20+T21 -> 672 | DR21: =DR20+V21 -> 1261 | DS21: =DS20+W21 -> 61 | DT21: =DT20+X21 -> 198 | DU21: =DU20+Y21 -> 497 | DV21: =DV20+Z21 -> 93 | DW21: =DW20+AA21 -> 1721 | DX21: =DX20+AB21 -> 972 | DY21: =DY20+AC21 -> 664 | ... EQ21: =EQ20+AU21 -> 8008 | ER21: =AVERAGE(EH21:EQ21) -> 2666.5 | ES21: =AVERAGE(DB21:EQ21) -> 1072.9268 | EV21: 180 | EW21: =CX21/CX$102 -> 0.011812911 | EX21: =CY21/CY$102 -> 0.006058074 | EY21: =CZ21/CZ$102 -> 0.039340823 | EZ21: =DA21/DA$102 -> 0.025581395 | FA21: =DB21/DB$102 -> 0.019009901 | FB21: =DC21/DC$102 -> 0.0032957502 | FC21: =DD21/DD$102 -> 9.3729497e-05 | FD21: =DE21/DE$102 -> 0 | ... FO21: =DP21/DP$102 -> 0.023891634 | FQ21: =DR21/DR$102 -> 0.021942265 | FR21: =DS21/DS$102 -> 0.020691995 | FS21: =DT21/DT$102 -> 0.054083584 | FT21: =DU21/DU$102 -> 0.02077373 | FU21: =DV21/DV$102 -> 0.001331253 | FV21: =DW21/DW$102 -> 0.022336435 | FW21: =DX21/DX$102 -> 0.01482928 | FX21: =DY21/DY$102 -> 0.0065698992 | ... GP21: =EQ21/EQ$102 -> 0.038078392 | GQ21: =AVERAGE(GG21:GP21) -> 0.026564078 | GR21: =AVERAGE(FA21:GP21) -> 0.019648011
A22: 181 | B22: 118 | C22: 4 | D22: 144 | E22: 2 | F22: 0 | G22: 8 | H22: 0 | I22: 0 | J22: 0 | L22: 17 | M22: 85 | N22: 54 | O22: 6 | P22: 42 | Q22: 253 | R22: 187 | S22: 7 | T22: 438 | V22: 820 | W22: 21 | X22: 77 | Y22: 38 | Z22: 24 | AA22: 930 | AB22: 368 | AC22: 28 | AD22: 183 | AE22: 3 | AF22: 1 | AG22: 9 | AH22: 0 | AI22: 522 | AJ22: 425 | AK22: 146 | AL22: 93 | AM22: 176 | AN22: 3 | AO22: 502 | AP22: 1982 | AQ22: 0 | AR22: 282 | AS22: 1655 | AT22: 298 | AU22: 1390 | AV22: =AVERAGE(AL22:AU22) -> 638.1 | AW22: =AW21+AV22 -> 3326.0933 | AY22: 181 | AZ22: =B22/B$104 -> 0.0051436293 | BA22: =C22/C$104 -> 0.0002088991 | BB22: =D22/D$104 -> 0.0062945316 | BC22: =E22/E$104 -> 0.0046511628 | BD22: =F22/F$104 -> 0 | BE22: =G22/G$104 -> 0.00069384215 | BF22: =H22/H$104 -> 0 | BG22: =I22/I$104 -> 0 | ... BR22: =T22/T$104 -> 0.015572226 | BT22: =V22/V$104 -> 0.014268562 | BU22: =W22/W$104 -> 0.0071234735 | BV22: =X22/X$104 -> 0.021032505 | BW22: =Y22/Y$104 -> 0.0015883334 | BX22: =Z22/Z$104 -> 0.00034354915 | BY22: =AA22/AA$104 -> 0.012070241 | BZ22: =AB22/AB$104 -> 0.0056143777 | CA22: =AC22/AC$104 -> 0.00027704394 | ... CS22: =AU22/AU$104 -> 0.006609511 | CT22: =CT21+AVERAGE(CJ22:CS22) -> 0.03533776 | CU22: =CU21+AVERAGE(BD22:CS22) -> 0.024934765 | CW22: 181 | CX22: =CX21+B22 -> 389 | CY22: =CY21+C22 -> 120 | CZ22: =CZ21+D22 -> 1044 | DA22: =DA21+E22 -> 13 | DB22: =DB21+F22 -> 48 | DC22: =DC21+G22 -> 46 | DD22: =DD21+H22 -> 1 | DE22: =DE21+I22 -> 0 | ... DP22: =DP21+T22 -> 1110 | DR22: =DR21+V22 -> 2081 | DS22: =DS21+W22 -> 82 | DT22: =DT21+X22 -> 275 | DU22: =DU21+Y22 -> 535 | DV22: =DV21+Z22 -> 117 | DW22: =DW21+AA22 -> 2651 | DX22: =DX21+AB22 -> 1340 | DY22: =DY21+AC22 -> 692 | ... EQ22: =EQ21+AU22 -> 9398 | ER22: =AVERAGE(EH22:EQ22) -> 3304.6 | ES22: =AVERAGE(DB22:EQ22) -> 1343 | EV22: 181 | EW22: =CX22/CX$102 -> 0.016956541 | EX22: =CY22/CY$102 -> 0.0062669731 | EY22: =CZ22/CZ$102 -> 0.045635354 | EZ22: =DA22/DA$102 -> 0.030232558 | FA22: =DB22/DB$102 -> 0.019009901 | FB22: =DC22/DC$102 -> 0.0039895924 | FC22: =DD22/DD$102 -> 9.3729497e-05 | FD22: =DE22/DE$102 -> 0 | ... FO22: =DP22/DP$102 -> 0.03946386 | FQ22: =DR22/DR$102 -> 0.036210827 | FR22: =DS22/DS$102 -> 0.027815468 | FS22: =DT22/DT$102 -> 0.075116089 | FT22: =DU22/DU$102 -> 0.022362063 | FU22: =DV22/DV$102 -> 0.0016748021 | FV22: =DW22/DW$102 -> 0.034406676 | FW22: =DX22/DX$102 -> 0.020443658 | FX22: =DY22/DY$102 -> 0.0068469431 | ... GP22: =EQ22/EQ$102 -> 0.044687903 | GQ22: =AVERAGE(GG22:GP22) -> 0.03533776 | GR22: =AVERAGE(FA22:GP22) -> 0.024934765
A23: 182 | B23: 171 | C23: 53 | D23: 148 | E23: 7 | F23: 8 | G23: 3 | H23: 0 | I23: 0 | J23: 0 | L23: 29 | M23: 109 | N23: 92 | O23: 3 | P23: 195 | Q23: 210 | R23: 180 | S23: 7 | T23: 267 | V23: 410 | W23: 24 | X23: 91 | Y23: 8 | Z23: 74 | AA23: 197 | AB23: 433 | AC23: 142 | AD23: 71 | AE23: 3 | AF23: 17 | AG23: 1 | AH23: 0 | AI23: 201 | AJ23: 1030 | AK23: 304 | AL23: 2 | AM23: 437 | AN23: 457 | AO23: 869 | AP23: 766 | AQ23: 9 | AR23: 150 | AS23: 344 | AT23: 1141 | AU23: 1340 | AV23: =AVERAGE(AL23:AU23) -> 551.5 | AW23: =AW22+AV23 -> 3877.5933 | AY23: 182 | AZ23: =B23/B$104 -> 0.0074539035 | BA23: =C23/C$104 -> 0.0027679131 | BB23: =D23/D$104 -> 0.0064693797 | BC23: =E23/E$104 -> 0.01627907 | BD23: =F23/F$104 -> 0.0031683168 | BE23: =G23/G$104 -> 0.00026019081 | BF23: =H23/H$104 -> 0 | BG23: =I23/I$104 -> 0 | ... BR23: =T23/T$104 -> 0.0094926583 | BT23: =V23/V$104 -> 0.0071342811 | BU23: =W23/W$104 -> 0.0081411126 | BV23: =X23/X$104 -> 0.024856597 | BW23: =Y23/Y$104 -> 0.00033438599 | BX23: =Z23/Z$104 -> 0.0010592765 | BY23: =AA23/AA$104 -> 0.0025568145 | BZ23: =AB23/AB$104 -> 0.0066060477 | CA23: =AC23/AC$104 -> 0.0014050086 | ... CS23: =AU23/AU$104 -> 0.0063717588 | CT23: =CT22+AVERAGE(CJ23:CS23) -> 0.042664985 | CU23: =CU22+AVERAGE(BD23:CS23) -> 0.029976103 | CW23: 182 | CX23: =CX22+B23 -> 560 | CY23: =CY22+C23 -> 173 | CZ23: =CZ22+D23 -> 1192 | DA23: =DA22+E23 -> 20 | DB23: =DB22+F23 -> 56 | DC23: =DC22+G23 -> 49 | DD23: =DD22+H23 -> 1 | DE23: =DE22+I23 -> 0 | ... DP23: =DP22+T23 -> 1377 | DR23: =DR22+V23 -> 2491 | DS23: =DS22+W23 -> 106 | DT23: =DT22+X23 -> 366 | DU23: =DU22+Y23 -> 543 | DV23: =DV22+Z23 -> 191 | DW23: =DW22+AA23 -> 2848 | DX23: =DX22+AB23 -> 1773 | DY23: =DY22+AC23 -> 834 | ... EQ23: =EQ22+AU23 -> 10738 | ER23: =AVERAGE(EH23:EQ23) -> 3856.1 | ES23: =AVERAGE(DB23:EQ23) -> 1577.7317 | EV23: 182 | EW23: =CX23/CX$102 -> 0.024410444 | EX23: =CY23/CY$102 -> 0.0090348861 | EY23: =CZ23/CZ$102 -> 0.052104734 | EZ23: =DA23/DA$102 -> 0.046511628 | FA23: =DB23/DB$102 -> 0.022178218 | FB23: =DC23/DC$102 -> 0.0042497832 | FC23: =DD23/DD$102 -> 9.3729497e-05 | FD23: =DE23/DE$102 -> 0 | ... FO23: =DP23/DP$102 -> 0.048956519 | FQ23: =DR23/DR$102 -> 0.043345108 | FR23: =DS23/DS$102 -> 0.035956581 | FS23: =DT23/DT$102 -> 0.099972685 | FT23: =DU23/DU$102 -> 0.022696449 | FU23: =DV23/DV$102 -> 0.0027340786 | FV23: =DW23/DW$102 -> 0.036963491 | FW23: =DX23/DX$102 -> 0.027049706 | FX23: =DY23/DY$102 -> 0.0082519517 | ... GP23: =EQ23/EQ$102 -> 0.051059662 | GQ23: =AVERAGE(GG23:GP23) -> 0.042664985 | GR23: =AVERAGE(FA23:GP23) -> 0.029976103
